Workbook

Sheet README
B3: Important notes on the use of this Excel file
B6: 1. How to fill in the Excel Form
B8: • Visit the Service Portal:
B9: https://www.kindermissionswerk.org/en/partners/service
B88: 2. Important note (Personnel Expenses):
B90: The entry of Personell Expenses (e.g. salaries, social contributions) is not made directly in the “Budget” sheet, but exclusively in the “Payroll structure” sheet. Please click the “Payroll structure” tab at the bottom left and enter all relevant information regarding the project staff there. The data entered there will then be automatically and in summarized form transferred to the “Personnel Expenses” section of the Budget sheet. This area is deliberately locked and cannot be edited manually in the “Budget” sheet.

Sheet Budget
A1: =IF($I$3="","",VLOOKUP($I$3,Sprachversionen!$B:$EA,2,FALSE)) -> C O S T A N D F I N A N C I A L P L A N
A2: _V2_en | C2: Hier kommt ein langer Titel rein | G2: =IF($I$3="","",VLOOKUP($I$3,Sprachversionen!$B:$EA,84,FALSE)) -> Project number | I2: 2026_0001_001 | P2: =IF($I$3="","",VLOOKUP($I$3,Sprachversionen!$B:$EA,90,FALSE)) -> Tip:
A3: =IF($I$3="","",VLOOKUP($I$3,Sprachversionen!$B:$EA,3,FALSE)) -> Project Title | G3: =IF($I$3="","Chose your language",VLOOKUP($I$3,Sprachversionen!$B:$EA,7,FALSE)) -> Language | I3: english | P3: =IF($I$3="","",VLOOKUP($I$3,Sprachversionen!$B:$EA,91,FALSE)) -> These short notes do not replace the full instructions – for details, see: "Completion aid to the cost and financing plan.pdf" on our website.
A4: =IF($I$3="","",VLOOKUP($I$3,Sprachversionen!$B:$EA,52,FALSE)) -> Project Partner | C4: Testträger | G4: =IF($I$3="","Chose your currency",VLOOKUP($I$3,Sprachversionen!$B:$EA,8,FALSE)) -> Local Currency | I4: USD
A5: =IF($I$3="","",VLOOKUP($I$3,Sprachversionen!$B:$EA,4,FALSE)) -> Planned Project Duration (in Months) | C5: 36 | G5: =IF($I$3="","",VLOOKUP($I$3,Sprachversionen!$B:$EA,9,FALSE))&IF($I$4="",""," € / "&I4) -> Exchange Rate € / USD | I5: 2
A6: =IF($I$3="","",VLOOKUP($I$3,Sprachversionen!$B:$EA,5,FALSE)) -> Planned Project Start | C6: 46023 | G6: =IF($I$3="","",VLOOKUP($I$3,Sprachversionen!$B:$EA,6,FALSE)) -> Date Of Last update | I6: 46023
D8: =IF($I$3="","",VLOOKUP($I$3,Sprachversionen!$B:$EA,24,FALSE)) -> Costs Calculation | J8: =IF($I$3="","",VLOOKUP($I$3,Sprachversionen!$B:$EA,25,FALSE)) -> Costs Per Year/Phase
B9: =VLOOKUP($I$3, Sprachversionen!$B:$EA, 98, FALSE) -> Fillable fields are in the colours on the left | C9: =IF($I$3="","",VLOOKUP($I$3,Sprachversionen!$B:$EA,26,FALSE)) -> Details | D9: =IF($I$3="","",VLOOKUP($I$3,Sprachversionen!$B:$EA,27,FALSE)) -> Unit | E9: =IF($I$3="","",VLOOKUP($I$3,Sprachversionen!$B:$EA,28,FALSE)) -> Quantity | F9: =IF($I$3="","",VLOOKUP($I$3,Sprachversionen!$B:$EA,29,FALSE)) -> % | G9: =IF($I$3="","",VLOOKUP($I$3,Sprachversionen!$B:$EA,30,FALSE)) -> Frequency | H9: =IF($I$3="","",VLOOKUP($I$3,Sprachversionen!$B:$EA,31,FALSE)) -> Cost Per Unit | I9: =IF($I$3="","",VLOOKUP($I$3,Sprachversionen!$B:$EA,32,FALSE)) -> Total Costs | J9: =IF($I$3="","",VLOOKUP($I$3,Sprachversionen!$B:$EA,33,FALSE)) -> 1. Year/Phase | K9: =IF($I$3="","",VLOOKUP($I$3,Sprachversionen!$B:$EA,34,FALSE)) -> 2. Year/Phase | L9: =IF($I$3="","",VLOOKUP($I$3,Sprachversionen!$B:$EA,35,FALSE)) -> 3. Year/Phase | N9: =IF($I$3="","",I9) -> Total Costs
D10: =IF($I$3="","",VLOOKUP($I$3,Sprachversionen!$B:$EA,36,FALSE)) -> Text only | I10: =IF($I$3="","",VLOOKUP($I$3,Sprachversionen!$B:$EA,37,FALSE)) -> in Local Currency | J10: =IF($I$3="","",VLOOKUP($I$3,Sprachversionen!$B:$EA,37,FALSE)) -> in Local Currency | K10: =IF($I$3="","",VLOOKUP($I$3,Sprachversionen!$B:$EA,37,FALSE)) -> in Local Currency | L10: =IF($I$3="","",VLOOKUP($I$3,Sprachversionen!$B:$EA,37,FALSE)) -> in Local Currency | N10: =IF($I$3="","",VLOOKUP($I$3,Sprachversionen!$B:$EA,59,FALSE)) -> in €
A11: =IF(ROW()<ROW($A$11),"",IF(ROW()=ROW($A$11),"1.","1."&(ROW()-ROW($A$11)))) -> 1. | B11: =VLOOKUP($I$3, Sprachversionen!$B:$EA, 10, FALSE) -> Building Expenses
A12: =IF(ROW()<ROW($A$11),"",IF(ROW()=ROW($A$11),"1.","1."&(ROW()-ROW($A$11)))) -> 1.1 | B12: Test 1 | E12: 1 | F12: 1 | G12: 3 | H12: 1000 | I12: =E12*F12*G12*H12 -> 3000 | J12: =I12/2 -> 1500 | K12: =I12/3 -> 1000 | L12: =I12-(J12+K12) -> 500 | N12: =ROUND(IFERROR(I12/$I$5,0), 2) -> 1500
A13: =IF(ROW()<ROW($A$11),"",IF(ROW()=ROW($A$11),"1.","1."&(ROW()-ROW($A$11)))) -> 1.2 | B13: Test 2 | E13: 1 | F13: 1 | G13: 3 | H13: 1000 | I13: =E13*F13*G13*H13 -> 3000 | J13: =I13/2 -> 1500 | K13: =I13/3 -> 1000 | L13: =I13-(J13+K13) -> 500 | N13: =ROUND(IFERROR(I13/$I$5,0), 2) -> 1500
A14: =IF(ROW()<ROW($A$11),"",IF(ROW()=ROW($A$11),"1.","1."&(ROW()-ROW($A$11)))) -> 1.3 | B14: Test 3 | E14: 1 | F14: 1 | G14: 3 | H14: 1000 | I14: =E14*F14*G14*H14 -> 3000 | J14: =I14/2 -> 1500 | K14: =I14/3 -> 1000 | L14: =I14-(J14+K14) -> 500 | N14: =ROUND(IFERROR(I14/$I$5,0), 2) -> 1500
A15: =IF(ROW()<ROW($A$11),"",IF(ROW()=ROW($A$11),"1.","1."&(ROW()-ROW($A$11)))) -> 1.4 | B15: Test 4 | E15: 1 | F15: 1 | G15: 3 | H15: 1000 | I15: =E15*F15*G15*H15 -> 3000 | J15: =I15/2 -> 1500 | K15: =I15/3 -> 1000 | L15: =I15-(J15+K15) -> 500 | N15: =ROUND(IFERROR(I15/$I$5,0), 2) -> 1500
A16: =IF(ROW()<ROW($A$11),"",IF(ROW()=ROW($A$11),"1.","1."&(ROW()-ROW($A$11)))) -> 1.5 | B16: Test 5 | E16: 1 | F16: 1 | G16: 3 | H16: 1000 | I16: =E16*F16*G16*H16 -> 3000 | J16: =I16/2 -> 1500 | K16: =I16/3 -> 1000 | L16: =I16-(J16+K16) -> 500 | N16: =ROUND(IFERROR(I16/$I$5,0), 2) -> 1500
A17: =IF(ROW()<ROW($A$11),"",IF(ROW()=ROW($A$11),"1.","1."&(ROW()-ROW($A$11)))) -> 1.6 | B17: Test 6 | E17: 1 | F17: 1 | G17: 3 | H17: 1000 | I17: =E17*F17*G17*H17 -> 3000 | J17: =I17/2 -> 1500 | K17: =I17/3 -> 1000 | L17: =I17-(J17+K17) -> 500 | N17: =ROUND(IFERROR(I17/$I$5,0), 2) -> 1500
A18: =IF(ROW()<ROW($A$11),"",IF(ROW()=ROW($A$11),"1.","1."&(ROW()-ROW($A$11)))) -> 1.7 | B18: Test 7 | E18: 1 | F18: 1 | G18: 3 | H18: 1000 | I18: =E18*F18*G18*H18 -> 3000 | J18: =I18/2 -> 1500 | K18: =I18/3 -> 1000 | L18: =I18-(J18+K18) -> 500 | N18: =ROUND(IFERROR(I18/$I$5,0), 2) -> 1500
A19: =IF(ROW()<ROW($A$11),"",IF(ROW()=ROW($A$11),"1.","1."&(ROW()-ROW($A$11)))) -> 1.8 | B19: Test 8 | E19: 1 | F19: 1 | G19: 3 | H19: 1000 | I19: =E19*F19*G19*H19 -> 3000 | J19: =I19/2 -> 1500 | K19: =I19/3 -> 1000 | L19: =I19-(J19+K19) -> 500 | N19: =ROUND(IFERROR(I19/$I$5,0), 2) -> 1500
A20: =IF(ROW()<ROW($A$11),"",IF(ROW()=ROW($A$11),"1.","1."&(ROW()-ROW($A$11)))) -> 1.9 | B20: Test 9 | E20: 1 | F20: 1 | G20: 3 | H20: 1000 | I20: =E20*F20*G20*H20 -> 3000 | J20: =I20/2 -> 1500 | K20: =I20/3 -> 1000 | L20: =I20-(J20+K20) -> 500 | N20: =ROUND(IFERROR(I20/$I$5,0), 2) -> 1500
A21: =IF(ROW()<ROW($A$11),"",IF(ROW()=ROW($A$11),"1.","1."&(ROW()-ROW($A$11)))) -> 1.10 | B21: Test 10 | E21: 1 | F21: 1 | G21: 3 | H21: 1000 | I21: =E21*F21*G21*H21 -> 3000 | J21: =I21/2 -> 1500 | K21: =I21/3 -> 1000 | L21: =I21-(J21+K21) -> 500 | N21: =ROUND(IFERROR(I21/$I$5,0), 2) -> 1500
A22: =IF(ROW()<ROW($A$11),"",IF(ROW()=ROW($A$11),"1.","1."&(ROW()-ROW($A$11)))) -> 1.11 | B22: Test 11 | E22: 1 | F22: 1 | G22: 3 | H22: 1000 | I22: =E22*F22*G22*H22 -> 3000 | J22: =I22/2 -> 1500 | K22: =I22/3 -> 1000 | L22: =I22-(J22+K22) -> 500 | N22: =ROUND(IFERROR(I22/$I$5,0), 2) -> 1500
A23: =IF(ROW()<ROW($A$11),"",IF(ROW()=ROW($A$11),"1.","1."&(ROW()-ROW($A$11)))) -> 1.12 | B23: Test 12 | E23: 1 | F23: 1 | G23: 3 | H23: 1000 | I23: =E23*F23*G23*H23 -> 3000 | J23: =I23/2 -> 1500 | K23: =I23/3 -> 1000 | L23: =I23-(J23+K23) -> 500 | N23: =ROUND(IFERROR(I23/$I$5,0), 2) -> 1500
... A31: =IF(ROW()<ROW($A$11),"",IF(ROW()=ROW($A$11),"1.","1."&(ROW()-ROW($A$11)))) -> 1.20 | B31: Test 20 | E31: 1 | F31: 1 | G31: 3 | H31: 1000 | I31: =E31*F31*G31*H31 -> 3000 | J31: =I31/2 -> 1500 | K31: =I31/3 -> 1000 | L31: =I31-(J31+K31) -> 500 | N31: =ROUND(IFERROR(I31/$I$5,0), 2) -> 1500
A32: =IF($I$3="","",VLOOKUP($I$3,Sprachversionen!$B:$DZ,11,FALSE)) -> Subtotal Building Expenses | I32: =SUM(I11:I31) -> 60000 | J32: =SUM(J11:J31) -> 30000 | K32: =SUM(K11:K31) -> 20000 | L32: =SUM(L11:L31) -> 10000 | M32: =I32=SUM(J32:L32) -> TRUE | N32: =SUM(N11:N31) -> 30000
A33: =IF(ROW()<ROW($A$33),"",IF(ROW()=ROW($A$33),"2.","2."&(ROW()-ROW($A$33)))) -> 2. | B33: =VLOOKUP($I$3, Sprachversionen!$B:$EA, 12, FALSE) -> Non-Recurring Expenses (Investments)
A34: =IF(ROW()<ROW($A$33),"",IF(ROW()=ROW($A$33),"2.","2."&(ROW()-ROW($A$33)))) -> 2.1 | B34: Test 1 | E34: 1 | F34: 1 | G34: 3 | H34: 1000 | I34: =E34*F34*G34*H34 -> 3000 | J34: =I34/2 -> 1500 | K34: =I34/3 -> 1000 | L34: =I34-(J34+K34) -> 500 | N34: =ROUND(IFERROR(I34/$I$5,0), 2) -> 1500
A35: =IF(ROW()<ROW($A$33),"",IF(ROW()=ROW($A$33),"2.","2."&(ROW()-ROW($A$33)))) -> 2.2 | B35: Test 2 | E35: 1 | F35: 1 | G35: 3 | H35: 1000 | I35: =E35*F35*G35*H35 -> 3000 | J35: =I35/2 -> 1500 | K35: =I35/3 -> 1000 | L35: =I35-(J35+K35) -> 500 | N35: =ROUND(IFERROR(I35/$I$5,0), 2) -> 1500
A36: =IF(ROW()<ROW($A$33),"",IF(ROW()=ROW($A$33),"2.","2."&(ROW()-ROW($A$33)))) -> 2.3 | B36: Test 3 | E36: 1 | F36: 1 | G36: 3 | H36: 1000 | I36: =E36*F36*G36*H36 -> 3000 | J36: =I36/2 -> 1500 | K36: =I36/3 -> 1000 | L36: =I36-(J36+K36) -> 500 | N36: =ROUND(IFERROR(I36/$I$5,0), 2) -> 1500
A37: =IF(ROW()<ROW($A$33),"",IF(ROW()=ROW($A$33),"2.","2."&(ROW()-ROW($A$33)))) -> 2.4 | B37: Test 4 | E37: 1 | F37: 1 | G37: 3 | H37: 1000 | I37: =E37*F37*G37*H37 -> 3000 | J37: =I37/2 -> 1500 | K37: =I37/3 -> 1000 | L37: =I37-(J37+K37) -> 500 | N37: =ROUND(IFERROR(I37/$I$5,0), 2) -> 1500
A38: =IF(ROW()<ROW($A$33),"",IF(ROW()=ROW($A$33),"2.","2."&(ROW()-ROW($A$33)))) -> 2.5 | B38: Test 5 | E38: 1 | F38: 1 | G38: 3 | H38: 1000 | I38: =E38*F38*G38*H38 -> 3000 | J38: =I38/2 -> 1500 | K38: =I38/3 -> 1000 | L38: =I38-(J38+K38) -> 500 | N38: =ROUND(IFERROR(I38/$I$5,0), 2) -> 1500
A39: =IF(ROW()<ROW($A$33),"",IF(ROW()=ROW($A$33),"2.","2."&(ROW()-ROW($A$33)))) -> 2.6 | B39: Test 6 | E39: 1 | F39: 1 | G39: 3 | H39: 1000 | I39: =E39*F39*G39*H39 -> 3000 | J39: =I39/2 -> 1500 | K39: =I39/3 -> 1000 | L39: =I39-(J39+K39) -> 500 | N39: =ROUND(IFERROR(I39/$I$5,0), 2) -> 1500
A40: =IF(ROW()<ROW($A$33),"",IF(ROW()=ROW($A$33),"2.","2."&(ROW()-ROW($A$33)))) -> 2.7 | B40: Test 7 | E40: 1 | F40: 1 | G40: 3 | H40: 1000 | I40: =E40*F40*G40*H40 -> 3000 | J40: =I40/2 -> 1500 | K40: =I40/3 -> 1000 | L40: =I40-(J40+K40) -> 500 | N40: =ROUND(IFERROR(I40/$I$5,0), 2) -> 1500
A41: =IF(ROW()<ROW($A$33),"",IF(ROW()=ROW($A$33),"2.","2."&(ROW()-ROW($A$33)))) -> 2.8 | B41: Test 8 | E41: 1 | F41: 1 | G41: 3 | H41: 1000 | I41: =E41*F41*G41*H41 -> 3000 | J41: =I41/2 -> 1500 | K41: =I41/3 -> 1000 | L41: =I41-(J41+K41) -> 500 | N41: =ROUND(IFERROR(I41/$I$5,0), 2) -> 1500
A42: =IF(ROW()<ROW($A$33),"",IF(ROW()=ROW($A$33),"2.","2."&(ROW()-ROW($A$33)))) -> 2.9 | B42: Test 9 | E42: 1 | F42: 1 | G42: 3 | H42: 1000 | I42: =E42*F42*G42*H42 -> 3000 | J42: =I42/2 -> 1500 | K42: =I42/3 -> 1000 | L42: =I42-(J42+K42) -> 500 | N42: =ROUND(IFERROR(I42/$I$5,0), 2) -> 1500
A43: =IF(ROW()<ROW($A$33),"",IF(ROW()=ROW($A$33),"2.","2."&(ROW()-ROW($A$33)))) -> 2.10 | B43: Test 10 | E43: 1 | F43: 1 | G43: 3 | H43: 1000 | I43: =E43*F43*G43*H43 -> 3000 | J43: =I43/2 -> 1500 | K43: =I43/3 -> 1000 | L43: =I43-(J43+K43) -> 500 | N43: =ROUND(IFERROR(I43/$I$5,0), 2) -> 1500
A44: =IF(ROW()<ROW($A$33),"",IF(ROW()=ROW($A$33),"2.","2."&(ROW()-ROW($A$33)))) -> 2.11 | B44: Test 11 | E44: 1 | F44: 1 | G44: 3 | H44: 1000 | I44: =E44*F44*G44*H44 -> 3000 | J44: =I44/2 -> 1500 | K44: =I44/3 -> 1000 | L44: =I44-(J44+K44) -> 500 | N44: =ROUND(IFERROR(I44/$I$5,0), 2) -> 1500
A45: =IF(ROW()<ROW($A$33),"",IF(ROW()=ROW($A$33),"2.","2."&(ROW()-ROW($A$33)))) -> 2.12 | B45: Test 12 | E45: 1 | F45: 1 | G45: 3 | H45: 1000 | I45: =E45*F45*G45*H45 -> 3000 | J45: =I45/2 -> 1500 | K45: =I45/3 -> 1000 | L45: =I45-(J45+K45) -> 500 | N45: =ROUND(IFERROR(I45/$I$5,0), 2) -> 1500
... A53: =IF(ROW()<ROW($A$33),"",IF(ROW()=ROW($A$33),"2.","2."&(ROW()-ROW($A$33)))) -> 2.20 | B53: Test 20 | E53: 1 | F53: 1 | G53: 3 | H53: 1000 | I53: =E53*F53*G53*H53 -> 3000 | J53: =I53/2 -> 1500 | K53: =I53/3 -> 1000 | L53: =I53-(J53+K53) -> 500 | N53: =ROUND(IFERROR(I53/$I$5,0), 2) -> 1500
A54: =IF($I$3="","",VLOOKUP($I$3,Sprachversionen!$B:$DZ,13,FALSE)) -> Subtotal Non Recurring Expenses (Investments) | I54: =SUM(I33:I53) -> 60000 | J54: =SUM(J33:J53) -> 30000 | K54: =SUM(K33:K53) -> 20000 | L54: =SUM(L33:L53) -> 10000 | M54: =I54=SUM(J54:L54) -> TRUE | N54: =SUM(N33:N53) -> 30000
A55: =IF(ROW()<ROW($A$55),"",IF(ROW()=ROW($A$55),"3.","3."&(ROW()-ROW($A$55)))) -> 3. | B55: =VLOOKUP($I$3,Sprachversionen!$B:$EA, 14, FALSE) -> Personnel Expenses | C55: {=IF( SUMPRODUCT(('Payroll structure'!C9:C158<>"")/ COUNTIF('Payroll structure'!C9:C158,'Payroll structure'!C9:C158&"")) >ROWS(A55:A86)-2, VLOOKUP($I$3,Sprachversionen!B:EA,85,FALSE), "" )} | P55: =IF($I$3="","",VLOOKUP($I$3,Sprachversionen!$B:$EA,92,FALSE)) -> 🚫 Personnel Expenses: Please do not enter anything here
...

Sheet Budget details
A1: =IF(Budget!$I$3="","",VLOOKUP(Budget!$I$3,Sprachversionen!$B:$EA,55,FALSE)) -> BUDGET DETAILS
A3: =Budget!A3&": "&Budget!C3 -> Project Title:
A4: =Budget!A4&": "&Budget!C4 -> Project Partner: Testträger
A5: =Budget!A5&": "&Budget!C5&" "&IF(Budget!$I$3="","",VLOOKUP(Budget!$I$3,Sprachversionen!$B:$EA,54,FALSE)) -> Planned Project Duration (in Months): 36 Months

Sheet Payroll structure
A1: =IF(Budget!$I$3="","",VLOOKUP(Budget!$I$3,Sprachversionen!$B:$EA,53,FALSE)) -> P A Y R O L L S T R U C T U R E
A3: =Budget!A3&": "&Budget!C3 -> Project Title:
A4: =Budget!A4&": "&Budget!C4 -> Project Partner: Testträger
A5: =Budget!A5&": "&Budget!C5&" "&IF(Budget!$I$3="","",VLOOKUP(Budget!$I$3,Sprachversionen!$B:$EA,54,FALSE)) -> Planned Project Duration (in Months): 36 Months
B7: =IF(Budget!$I$3="","",VLOOKUP(Budget!$I$3,Sprachversionen!$B:$EA,79,FALSE)) -> Information from the employment contract | H7: =IF(Budget!$I$3="","",VLOOKUP(Budget!$I$3,Sprachversionen!$B:$EA,80,FALSE)) -> Monthly salary for a full-time position (annual average) | K7: =IF(Budget!$I$3="","",VLOOKUP(Budget!$I$3,Sprachversionen!$B:$EA,81,FALSE)) -> Annual budget of the organisation | M7: =IF(Budget!$I$3="","",VLOOKUP(Budget!$I$3,Sprachversionen!$B:$EA,82,FALSE)) -> Project Budget
A8: =IF(Budget!$I$3="","",VLOOKUP(Budget!$I$3,Sprachversionen!$B:$EA,63,FALSE)) -> Number | B8: =IF(Budget!$I$3="","",VLOOKUP(Budget!$I$3,Sprachversionen!$B:$EA,64,FALSE)) -> Surname, First/Given Name | C8: =IF(Budget!$I$3="","",VLOOKUP(Budget!$I$3,Sprachversionen!$B:$EA,65,FALSE)) -> Position | D8: =IF(Budget!$I$3="","",VLOOKUP(Budget!$I$3,Sprachversionen!$B:$EA,66,FALSE)) -> Detailed description of cost calculation (for traceability of the components of the gross amount paid by employer) | E8: =IF(Budget!$I$3="","",VLOOKUP(Budget!$I$3,Sprachversionen!$B:$EA,67,FALSE)) -> Employment level (% of a full-time position) | F8: =IF(Budget!$I$3="","",VLOOKUP(Budget!$I$3,Sprachversionen!$B:$EA,68,FALSE)) -> Deployment location | G8: =IF(Budget!$I$3="","",VLOOKUP(Budget!$I$3,Sprachversionen!$B:$EA,69,FALSE)) -> Number of Monthly Salaries/year | H8: =IF(Budget!$I$3="","",VLOOKUP(Budget!$I$3,Sprachversionen!$B:$EA,70,FALSE)) -> Gross Basic Salary | I8: =IF(Budget!$I$3="","",VLOOKUP(Budget!$I$3,Sprachversionen!$B:$EA,71,FALSE)) -> Voluntary elements of the gross salary | J8: =IF(Budget!$I$3="","",VLOOKUP(Budget!$I$3,Sprachversionen!$B:$EA,72,FALSE)) -> Statutory employer contributions to social security and other statutory salary components | K8: =IF(Budget!$I$3="","",VLOOKUP(Budget!$I$3,Sprachversionen!$B:$EA,73,FALSE)) -> Fixed yearly payments | L8: =IF(Budget!$I$3="","",VLOOKUP(Budget!$I$3,Sprachversionen!$B:$EA,74,FALSE)) -> Annual gross Salary (Employer) | M8: =IF(Budget!$I$3="","",VLOOKUP(Budget!$I$3,Sprachversionen!$B:$EA,75,FALSE)) -> % Engagement to the Project | N8: =IF(Budget!$I$3="","",VLOOKUP(Budget!$I$3,Sprachversionen!$B:$EA,86,FALSE)) -> Duration of assignment (months) | O8: =IF(Budget!$I$3="","",VLOOKUP(Budget!$I$3,Sprachversionen!$B:$EA,82,FALSE)) -> Project Budget | P8: =IF(Budget!$I$3="","",VLOOKUP(Budget!$I$3,Sprachversionen!$B:$EA,76,FALSE)) -> Budget Year 1 | Q8: =IF(Budget!$I$3="","",VLOOKUP(Budget!$I$3,Sprachversionen!$B:$EA,77,FALSE)) -> Budget Year 2 | R8: =IF(Budget!$I$3="","",VLOOKUP(Budget!$I$3,Sprachversionen!$B:$EA,78,FALSE)) -> Budget Year 3 | S8: =IF(Budget!$I$3="","",VLOOKUP(Budget!$I$3,Sprachversionen!$B:$EA,59,FALSE)) -> in €
A9: =IF(ROW()<ROW($A$9),"",(ROW()-ROW($A$9)+1)) -> 1 | L9: =IF($C9="",0,SUM($H9:$J9)*$G9*$E9+$K9) -> 0 | N9: =Budget!$C$5 -> 36 | O9: =IF($C9=0,0,$L9/12*$N9*$M9) -> 0 | S9: =ROUND(IFERROR($O9/Budget!$I$5,0),2) -> 0 | T9: =$O9=(SUM($P9:$R9)) -> TRUE
A10: =IF(ROW()<ROW($A$9),"",(ROW()-ROW($A$9)+1)) -> 2 | L10: =IF($C10="",0,SUM($H10:$J10)*$G10*$E10+$K10) -> 0 | N10: =Budget!$C$5 -> 36 | O10: =IF($C10=0,0,$L10/12*$N10*$M10) -> 0 | S10: =ROUND(IFERROR($O10/Budget!$I$5,0),2) -> 0 | T10: =$O10=(SUM($P10:$R10)) -> TRUE
A11: =IF(ROW()<ROW($A$9),"",(ROW()-ROW($A$9)+1)) -> 3 | L11: =IF($C11="",0,SUM($H11:$J11)*$G11*$E11+$K11) -> 0 | N11: =Budget!$C$5 -> 36 | O11: =IF($C11=0,0,$L11/12*$N11*$M11) -> 0 | S11: =ROUND(IFERROR($O11/Budget!$I$5,0),2) -> 0 | T11: =$O11=(SUM($P11:$R11)) -> TRUE
A12: =IF(ROW()<ROW($A$9),"",(ROW()-ROW($A$9)+1)) -> 4 | L12: =IF($C12="",0,SUM($H12:$J12)*$G12*$E12+$K12) -> 0 | N12: =Budget!$C$5 -> 36 | O12: =IF($C12=0,0,$L12/12*$N12*$M12) -> 0 | S12: =ROUND(IFERROR($O12/Budget!$I$5,0),2) -> 0 | T12: =$O12=(SUM($P12:$R12)) -> TRUE
A13: =IF(ROW()<ROW($A$9),"",(ROW()-ROW($A$9)+1)) -> 5 | L13: =IF($C13="",0,SUM($H13:$J13)*$G13*$E13+$K13) -> 0 | N13: =Budget!$C$5 -> 36 | O13: =IF($C13=0,0,$L13/12*$N13*$M13) -> 0 | S13: =ROUND(IFERROR($O13/Budget!$I$5,0),2) -> 0 | T13: =$O13=(SUM($P13:$R13)) -> TRUE
A14: =IF(ROW()<ROW($A$9),"",(ROW()-ROW($A$9)+1)) -> 6 | L14: =IF($C14="",0,SUM($H14:$J14)*$G14*$E14+$K14) -> 0 | N14: =Budget!$C$5 -> 36 | O14: =IF($C14=0,0,$L14/12*$N14*$M14) -> 0 | S14: =ROUND(IFERROR($O14/Budget!$I$5,0),2) -> 0 | T14: =$O14=(SUM($P14:$R14)) -> TRUE
A15: =IF(ROW()<ROW($A$9),"",(ROW()-ROW($A$9)+1)) -> 7 | L15: =IF($C15="",0,SUM($H15:$J15)*$G15*$E15+$K15) -> 0 | N15: =Budget!$C$5 -> 36 | O15: =IF($C15=0,0,$L15/12*$N15*$M15) -> 0 | S15: =ROUND(IFERROR($O15/Budget!$I$5,0),2) -> 0 | T15: =$O15=(SUM($P15:$R15)) -> TRUE
A16: =IF(ROW()<ROW($A$9),"",(ROW()-ROW($A$9)+1)) -> 8 | L16: =IF($C16="",0,SUM($H16:$J16)*$G16*$E16+$K16) -> 0 | N16: =Budget!$C$5 -> 36 | O16: =IF($C16=0,0,$L16/12*$N16*$M16) -> 0 | S16: =ROUND(IFERROR($O16/Budget!$I$5,0),2) -> 0 | T16: =$O16=(SUM($P16:$R16)) -> TRUE
A17: =IF(ROW()<ROW($A$9),"",(ROW()-ROW($A$9)+1)) -> 9 | L17: =IF($C17="",0,SUM($H17:$J17)*$G17*$E17+$K17) -> 0 | N17: =Budget!$C$5 -> 36 | O17: =IF($C17=0,0,$L17/12*$N17*$M17) -> 0 | S17: =ROUND(IFERROR($O17/Budget!$I$5,0),2) -> 0 | T17: =$O17=(SUM($P17:$R17)) -> TRUE
A18: =IF(ROW()<ROW($A$9),"",(ROW()-ROW($A$9)+1)) -> 10 | L18: =IF($C18="",0,SUM($H18:$J18)*$G18*$E18+$K18) -> 0 | N18: =Budget!$C$5 -> 36 | O18: =IF($C18=0,0,$L18/12*$N18*$M18) -> 0 | S18: =ROUND(IFERROR($O18/Budget!$I$5,0),2) -> 0 | T18: =$O18=(SUM($P18:$R18)) -> TRUE
A19: =IF(ROW()<ROW($A$9),"",(ROW()-ROW($A$9)+1)) -> 11 | L19: =IF($C19="",0,SUM($H19:$J19)*$G19*$E19+$K19) -> 0 | N19: =Budget!$C$5 -> 36 | O19: =IF($C19=0,0,$L19/12*$N19*$M19) -> 0 | S19: =ROUND(IFERROR($O19/Budget!$I$5,0),2) -> 0 | T19: =$O19=(SUM($P19:$R19)) -> TRUE
A20: =IF(ROW()<ROW($A$9),"",(ROW()-ROW($A$9)+1)) -> 12 | L20: =IF($C20="",0,SUM($H20:$J20)*$G20*$E20+$K20) -> 0 | N20: =Budget!$C$5 -> 36 | O20: =IF($C20=0,0,$L20/12*$N20*$M20) -> 0 | S20: =ROUND(IFERROR($O20/Budget!$I$5,0),2) -> 0 | T20: =$O20=(SUM($P20:$R20)) -> TRUE
... A158: =IF(ROW()<ROW($A$9),"",(ROW()-ROW($A$9)+1)) -> 150 | L158: =IF($C158="",0,SUM($H158:$J158)*$G158*$E158+$K158) -> 0 | N158: =Budget!$C$5 -> 36 | O158: =IF($C158=0,0,$L158/12*$N158*$M158) -> 0 | S158: =ROUND(IFERROR($O158/Budget!$I$5,0),2) -> 0 | T158: =$O158=(SUM($P158:$R158)) -> TRUE

Sheet Sprachversionen
A1: AED | B1: deutsch | C1: K O S T E N - U N D F I N A N Z I E R U N G S P L A N | D1: Projekttitel | E1: Geplante Projektdauer (in Monaten) | F1: Geplanter Projektbeginn | G1: Letzter Stand | H1: Sprache | I1: Lokalwährung | J1: Wechselkurs | K1: Bauausgaben | L1: Zwischensumme Bauausgaben | M1: Einmalige Ausgaben (Investitionen) | N1: Zwischensumme Einmalige Ausgaben (Investitionen) | O1: Personalkosten | P1: Zwischensumme Personalkosten | Q1: Laufende Ausgaben für Projektaktivitäten | R1: Zwischensumme Laufende Ausgaben für Projektaktivitäten | S1: Projektverwaltung | T1: Zwischensumme Projektverwaltung | U1: Evaluierung | V1: Audit | W1: Reserve - nur nach Genehmigung | X1: Summe | Y1: Kostenberechnung | Z1: Kosten pro Jahr/ Phase | AA1: Beschreibung | AB1: Einheit | AC1: Menge | AD1: % | AE1: Häufigkeit | AF1: Kosten pro Einheit | AG1: Gesamtkosten | AH1: 1. Jahr/ Phase | AI1: 2. Jahr/ Phase | AJ1: 3. Jahr/ Phase | AK1: nur Text | AL1: in Lokalwährung | AM1: Lokale Eigenleistung | AN1: Drittmittel | AO1: Beim KMW beantragt | AP1: Erläuterungen: | AQ1: Der Kosten- und Finanzierungsplan sowie die Finanzberichte werden in Lokalwährung angefertigt. Bei zwei gängigen Lokalwährungen empfehlen wir, die am meisten genutzte oder die stabilste Währung (“functional currency”) dem Projekt als Lokalwährung zugrunde zu legen. Budgetiert werden können nur Kosten mit einhergehendem Geldfluss (keine kalkulierten Kosten) und direktem Projektbezug. Abgerechnet werden können nur Ausgaben mit gebuchten und gestempelten Belegen ("finanziert durch das KMW-Projekt Nr."). Das KMW behält sich das Recht vor, stichprobenmäßig Beleglisten anzufordern und Belege zu prüfen. XXX zur Finanzierung? | AR1: Erklärungen der Kostenkategorien: | AS1: - Planmäßige Baumaßnahmen wie Neubau – oder Umbauarbeiten, Renovierungen oder Sanierungen - Kosten für Fachplanung wie Architekt, Statik, Bodengutachter, Brandschutz etc. – es muss mindestens ein Kostenvoranschlag des Architekten vorliegen - Außerkostenplanmäßige Eigenleistung: Grundstück oder bereits vorhandenes Gebäude und Genehmigungskosten der Baumaßnahme - der (Eigentums-) Nachweis hierzu muss geliefert werden - Jede größere Baumaßnahme unterliegt zwei externer Prüfungen: 1) Abnahme durch einen Bauprüfer: die externe Bauprüfung inkl. Bauüberwachung, Abrechnung und Berichtswesen erfolgt durch einen Architekten oder Bauingenieur - es ist mindestens ein Vergleichsangebot für die Baukosten und benötigten Fachplaner vorzulegen (liegt kein weiteres Vergleichsangebot vor, ist eine schriftliche Erklärung notwendig) 2) Audit durch einen Buchprüfer - Instandhaltungskosten (z.B. kleine Reparaturen, Wartungen, Inspektionen, Malerarbeiten) werden in der Kostenkategorie Projektverwaltung budgetiert - Kostenaufschlüsselung nach Gewerken in einer Massenaufstellung | AT1: - Anschaffungen über 500€ - Fahrzeuge, die ausschließlich im Projekt gebraucht werden und innerhalb von 5 bzw. 10 Jahren beim Projektträger verbleiben - Ausrüstungen und Maschinen - Einrichtungen - Sonstige Investitionen (z.B. Kauf von Lizenzen) Es bedarf mindestens 3 Kostenvoranschläge mit Vergabevermerk, die als Teil der Belege archiviert werden müssen zur evtl. Prüfung durch einen externen Buchprüfer. Die im Projekt angeschafften Investitionen unterliegen der - Zweckbindung: 5 Jahre für Anschaffungen unter 50T€, darüber hinaus 10 Jahre - Eigentumsübergang: Bei Nutzung innerhalb des Projekts geht die Anschaffung in das Eigentum des Projektpartners über | AU1: 1) Personal mit Festanstellung (nach Funktionen): - Gehälter inkl. Sozialabgaben pro Person (% Sozialabgaben & Bruttolohn) - Bei Teilzeitpersonal Angabe des prozentualen Arbeitszeitumfangs in der Spalte „%“) und des Bruttogehalts auf Vollzeitbasis - Bei nicht in Vollzeit für das Projekt engagiertem Personal Angabe des prozentualen Beschäftigungsumfangs in der Spalte „%“ Detaillierte Aufschlüsselung dieser Personalkosten pro Person - Bruttogehalt: monatliches Grundgehalt - Andere Elemente des Bruttogehalts: eventuelle vermögenswirksame Leistungen, Zuschläge und Zulagen, pauschal versteuerte Lohnbestandteile oder geldwerte Vorteile aus Sachbezügen (nur anerkennbar, wenn objektive Bewertungskriterien angewandt und im Projektkontext sinnvoll eingesetzt werden) – wird i.d.R. als % vom Bruttogehalt oder als Pauschale berechnet - Gesetzliche Arbeitgebersozialabgaben: jeder festangestellte Mitarbeiter muss gesetzlich versichert sein (z.B. Kranken-, Renten-, Pflege- und Arbeitslosenversicherung) - wird i.d.R. als % vom Bruttogehalt oder als Pauschale berechnet 2) Honorarkräfte (Personal ohne Festanstellung, Honorare ohne Sozialabgaben) - Ausgaben für Personalweiterbildung (Kosten pro Weiterbildungstag pro Person, separate Aufschlüsselung von evtl. Transport- und Verpflegungskosten) - Honorarkräfte, die nur in vereinzelten Projektmaßnahmen tätig sind, werden in der Kostenkategorie „Laufende Kosten für Projektaktivitäten“ budgetiert | AV1: - 1 Budgetlinie pro Projektmaßnahme (siehe Logframe) (bei institutioneller Förderung: XXX - Kosten für Veranstaltungen können wie folgt budgetiert werden: 1) Einheit: Kosten pro Teilnehmer (Begünstigte) pro Veranstaltung 2) Die detaillierte Aufschlüsselung von Kosten für Material, Verpflegung, Beherbergung, Transport, Honorarkräfte, externe Raummiete, Printmedien etc. geschieht im Reiter „Budgeterläuterungen“ | AW1: - Kontinuierliche Instandhaltung (z.B. kleine Reparaturen, Wartungen, Inspektionen, Malerarbeiten) – Instandhaltungskosten ohne direkten Projektzusammenhang müssen besonders begründet werden - Team- und Monitoringtreffen (falls es sich um interne Auswertungen ohne Evaluierungs-ToRs und Evaluierungsbericht handelt) - Büromaterial - Miete, Strom, Gas und Wasser des Projektbüros - Bankgebühren, die bei Erhalt der KMW-Auszahlung bei der Empfängerbank anfallen | AX1: - Interne oder externe Evaluierung mit verfügbaren ToRs und Evaluierungsbericht - Es müssen folgende Informationen vorliegen: 1) Bei Antragstellung: - Grobe Kostenplanung und Angabe einer Pauschale mit Hinweis der Berechnungsgrundlage - Angabe, wozu die Evaluierung dienen soll und wann sie geplant ist 2) Ca. 6 Monate vor geplanter Evalulierung: - Das Evaluierungsbudget muss präzisiert werden - Mit den konkreten Vorbereitungen beginnen: detaillierter Kostenplan, ToR, Evaluatorsuche und –auswahl etc. | AY1: - Externe Buchprüfung (Jahresaudit bei großvolumigen und langjährigen Projekten – Gesamtaudit bei langjährigen Projekten im kleineren Segment – institutionelles Audit bei langjährigen Partnern mit mehreren Projekten) - Aufschlüsselung von evtl. Transport- und Verpflegungskosten im Reiter „Budgeterläuterungen“ Hinweise für den Buchprüfer: - Durchführung der Buchprüfung nach dem KMW Standard Auditvertrag - Die Buchprüfungsgesellschaft bzw. der Auditor müssen alle 5-6 Jahre gewechselt werden - Es müssen mindestens 3 Kostenvoranschläge vorliegen und nach Projektbewilligung eine Begründung der Buchprüferauswahl eingereicht – das KMW behält sich das Recht vor, der Empfehlung je nach Bewertung im internen Auditorenpool zu widersprechen | AZ1: - Wird i.d.R durch das KMW finanziert - Die Reserve kann unter bestimmten Bedingungen beim KMW beantragt werden (z.B. bei Währungsverlusten, nachgewiesenen Kostensteigerungen ) | BA1: Projektträger | BB1: G E H A L T S S T R U K T U R | BC1: Monate | BD1: Budgeterläuterungen | BE1: Name Drittmittelgeber | BF1: Förderstatus | BG1: Bewilligt/ Beantragt | BH1: in € | BI1: Förderzeitraum | BJ1: von | BK1: bis | BL1: Nr. | BM1: Name, Vorname | BN1: Position | BO1: Detaillierte Beschreibung der Kosten (zur Nachvollziehbarkeit der Bestandteile des Arbeitgeberbruttos) | BP1: Beschäftigungsumfang (% einer Vollzeitstelle) | BQ1: Einsatzort | BR1: Anzahl Monatsgehälter/ Jahr | BS1: Bruttobasisgehalt | BT1: Freiwillige Elemente des Bruttogehalts | BU1: Gesetzliche Arbeitgebersozialabgaben und andere gesetzlich festgeschriebene Gehaltselemente | BV1: Jährliche Einmalzahlungen | BW1: Jährliches Arbeitgeberbrutto | BX1: % engagierte Arbeitszeit im Projekt | BY1: Budget Jahr 1 | BZ1: Budget Jahr 2 | CA1: Budget Jahr 3 | CB1: Informationen aus dem Arbeitsvertrag | CC1: Monatslohn einer Vollzeitstelle (Jahresdurchschnitt) | CD1: Jahresbudget der Organisation | CE1: Projektbudget | CF1: MA/ Monat | CG1: Projektnummer | CH1: Weitere Zeilen hinzufügen! | CI1: Einsatzdauer (in Monaten) | CJ1: Bewilligt | CK1: Beantragt | CL1: Info: Wenn Sie mehr Zeilen (Kostenpositionen) benötigen, kontaktieren Sie uns bitte. | CM1: Tipp: | CN1: Diese Kurzinfos ersetzen nicht die vollständige Anleitung – für Details siehe: „Ausfüllhilfe zum Kosten- und Finanzierungsplan“ auf unserer Webseite. | CO1: 🚫 Personalkosten: Bitte hier nichts eintragen | CP1: ="Die Personalkosten (z. B. Gehälter) sind nicht auf diesem Blatt einzutragen." & CHAR(10) & "Bitte klicken Sie unten links auf den Reiter """ & CT10 & """." & CHAR(10) & "Dort erfassen Sie alle Daten zu den Mitarbeitenden im Projekt." -> Die Personalkosten (z. B. Gehälter) sind nicht auf diesem Blatt einzutragen. Bitte klicken Sie unten links auf den Reiter "Payroll structure". Dort erfassen Sie alle Daten zu den Mitarbeitenden im Projekt. | CQ1: =CP1 & CHAR(10) & CHAR(10) & "Diese Angaben werden automatisch in den Abschnitt „Personalkosten“ dieses Blatts übernommen." & CHAR(10) & "Die Zellen in diesem Bereich sind deshalb gesperrt und können nicht bearbeitet werden." -> Die Personalkosten (z. B. Gehälter) sind nicht auf diesem Blatt einzutragen. Bitte klicken Sie unten links auf den Reiter "Payroll structure". Dort erfassen Sie alle Daten zu den Mitarbeitenden im Projekt. Diese Angaben werden automatisch in den Abschnitt „Personalkosten“ dieses Blatts übernommen. Die Zellen in diesem Bereich sind deshalb gesperrt und können nicht bearbeitet werden. | CR1: Budget | CS1: Budgeterläuterungen | CT1: Gehaltsstruktur | CU1: Ausfüllbare Felder sind in den Farben links
A2: AFN | B2: english | C2: C O S T A N D F I N A N C I A L P L A N | D2: Project Title | E2: Planned Project Duration (in Months) | F2: Planned Project Start | G2: Date Of Last update | H2: Language | I2: Local Currency | J2: Exchange Rate | K2: Building Expenses | L2: Subtotal Building Expenses | M2: Non-Recurring Expenses (Investments) | N2: Subtotal Non Recurring Expenses (Investments) | O2: Personnel Expenses | P2: Subtotal Personnel Expenses | Q2: Ongoing Expenses for Project Activities | R2: Subtotal Ongoing Expenses for Project Activities | S2: Project Administration | T2: Subtotal Project Administration | U2: Evaluation | V2: Audit | W2: Contingency reserve - after authorisation only | X2: Total | Y2: Costs Calculation | Z2: Costs Per Year/Phase | AA2: Details | AB2: Unit | AC2: Quantity | AD2: % | AE2: Frequency | AF2: Cost Per Unit | AG2: Total Costs | AH2: 1. Year/Phase | AI2: 2. Year/Phase | AJ2: 3. Year/Phase | AK2: Text only | AL2: in Local Currency | AM2: Local Contribution | AN2: Third party contribution | AO2: Requested from KMW | BA2: Project Partner | BB2: P A Y R O L L S T R U C T U R E | BC2: Months | BD2: BUDGET DETAILS | BE2: Name of the Third Party Donor | BF2: Funding Status | BG2: Approved/Requested | BH2: in € | BI2: Funding Period | BJ2: From | BK2: To | BL2: Number | BM2: Surname, First/Given Name | BN2: Position | BO2: Detailed description of cost calculation (for traceability of the components of the gross amount paid by employer) | BP2: Employment level (% of a full-time position) | BQ2: Deployment location | BR2: Number of Monthly Salaries/year | BS2: Gross Basic Salary | BT2: Voluntary elements of the gross salary | BU2: Statutory employer contributions to social security and other statutory salary components | BV2: Fixed yearly payments | BW2: Annual gross Salary (Employer) | BX2: % Engagement to the Project | BY2: Budget Year 1 | BZ2: Budget Year 2 | CA2: Budget Year 3 | CB2: Information from the employment contract | CC2: Monthly salary for a full-time position (annual average) | CD2: Annual budget of the organisation | CE2: Project Budget | CF2: employee/ month | CG2: Project number | CH2: Add more lines! | CI2: Duration of assignment (months) | CJ2: Approved | CK2: Requested | CL2: Info: If you need more lines (cost items), please contact us. | CM2: Tip: | CN2: These short notes do not replace the full instructions – for details, see: "Completion aid to the cost and financing plan.pdf" on our website. | CO2: 🚫 Personnel Expenses: Please do not enter anything here | CP2: ="Personnel costs (e.g. salaries) should not be entered on this sheet." & CHAR(10) & "Please click on the """ & CT10 & """ tab at the bottom left." & CHAR(10) & "There you can enter all data regarding project staff." -> Personnel costs (e.g. salaries) should not be entered on this sheet. Please click on the "Payroll structure" tab at the bottom left. There you can enter all data regarding project staff. | CQ2: =CP2 & CHAR(10) & CHAR(10) & "This information is automatically transferred to the “Personnel Expenses” section of this sheet." & CHAR(10) & "As a result, the cells in this section are locked and cannot be modified." -> Personnel costs (e.g. salaries) should not be entered on this sheet. Please click on the "Payroll structure" tab at the bottom left. There you can enter all data regarding project staff. This information is automatically transferred to the “Personnel Expenses” section of this sheet. As a result, the cells in this section are locked and cannot be modified. | CR2: Budget | CS2: Budget explanations | CT2: Payroll structure | CU2: Fillable fields are in the colours on the left
A3: ALL | B3: français | C3: B U D G E T D U P R O J E T E T P L A N D E F I N A N C E M E N T | D3: Titre du projet | E3: Durée prévue du projet (nombre de mois) | F3: Début prévu du projet | G3: Date dernière modification | H3: Langue | I3: Monnaie locale | J3: Taux d'échange | K3: Dépenses de construction | L3: Sous-total dépenses de construction | M3: Dépenses uniques (investissements) | N3: Sous-total dépenses uniques (investissements) | O3: Personnel | P3: Sous-total personnel | Q3: Dépenses courantes pour activités de projet | R3: Sous-total dépenses courantes pour activités de projet | S3: Gestion de projet | T3: Sous-total gestion de projet | U3: Evaluation | V3: Audit | W3: Réserve - uniquement après accord | X3: TOTAL | Y3: Calcul des coûts | Z3: Coûts par année/phase (le cas échéant) | AA3: Détail calcul des coûts | AB3: Unité | AC3: Quantité | AD3: % | AE3: Fréquence | AF3: Coûts par unité | AG3: Coût total | AH3: 1ère année/phase | AI3: 2e année/phase | AJ3: 3e année/phase | AK3: texte uniquement | AL3: en monnaie locale | AM3: Contribution locale | AN3: Contributions de tiers | AO3: Montant demandé à Kindermissionswerk | AP3: Remarques : | AQ3: La subdivision indiquée est purement illustrative et peut être adaptée selon le cas. Pour ajouter des éléments de coûts supplémentaires, veuillez compléter le tableau en insérant des lignes supplémentaires. Pour les frais de personnel, veuillez indiquer séparément toutes les personnes rémunérées par des fonds de projet ainsi que le pourcentage de leur activité pour le projet. Les rémunérations et les charges sociales doivent être indiquées séparément. Pour les collaborateurs à temps partiel, veuillez indiquer le pourcentage du temps de travail et du salaire brut par rapport à un poste à plein temps. Pour le plan de financement, veuillez considérer que seules les contributions monétaires peuvent être prises en compte pour les prestations propres. | AR3: Explications quant aux éléments de coûts : | AS3: l’achat du terrain à bâtir (coût non assumé par KMW), aux coûts d’aménagement du terrain, coûts liés à la construction (gros œuvre, aménagement intérieur), à l’équipement, l’appareillage, la technique opératoire, aux installations extérieures, aux frais accessoires (honoraires d’architecte, etc.) | AT3: véhicules, équipements, machines et appareils, autres dispositifs (indépendamment des dépenses de construction), autres investissements (par ex. l’achat de licences, …) | AU3: salariés permanents (selon leur fonction), rémunérations et charges sociales par personne, collaborateurs indépendants percevant des honoraires, coûts pour la formation continue du personnel | AV3: la mise en place de groupes de base, la formation et le conseil sur place, les cours de formation dans des centres (par ex. x jours pour y participant(e)s), au matériel de cours, etc., à l’observation des effets (collecte de données de base, collecte de résultats intermédiaires à l’aide d’indicateurs, ateliers spécif. sur l’observation des effets, etc.) | AW3: audit, frais de locaux (loyer, énergie, entretien du bâtiment), à la communication (téléphone, Internet, etc.), frais de déplacement pour le personnel, à la mobilité (entretien des véhicules, coûts de fonctionnement des véhicules), produits consommables pour le fonctionnement, l’administration, la logistique, etc., à l’évaluation, etc. | BA3: Porteur de projet | BB3: S T R U C T U R E S A L A R I A L E | BC3: mois | BD3: B U D G E T D É T A I L L É | BE3: Nom contribution de tiers | BF3: Statut de la donation | BG3: Accordé/ Demandé | BH3: en € | BI3: Période de financement | BJ3: de | BK3: à | BL3: N° | BM3: Nom, prénom | BN3: Position | BO3: Description détaillée des coûts (afin de mieux comprendre les éléments du salaire brut chargé) | BP3: Taux d'emploi (% du temps plein) | BQ3: Lieu d'affectation | BR3: Nombre de salaires mensuels/ an | BS3: Salaire de base | BT3: Éléments volontaires du salaire brut | BU3: Charges sociales employeur obligatoires ou d'autres éléments (obligatoires) du salaire brut | BV3: Paiements forfaitaires annuels | BW3: Coût annuel du salarié | BX3: % du temps de travail engagé dans le projet | BY3: Budget année 1 | BZ3: Budget année 2 | CA3: Budget année 3 | CB3: Informations issues du contrat de travail | CC3: Salaire mensuel temps plein (moyenne annuelle) | CD3: Budget annuel de l'organisation | CE3: Budget du projet | CF3: employé/ mois | CG3: Numéro de projet | CH3: Ajouter d'autres lignes ! | CI3: Durée de l’affectation (mois) | CJ3: Accordé | CK3: Demandé | CL3: Info : Si vous avez besoin de plus de lignes (postes de coûts), veuillez nous contacter. | CM3: Astuce : | CN3: Ces brèves informations ne remplacent pas les instructions complètes – pour plus de détails, voir : « Guide_pour_le_remplissage_du_plan_de_couts_et_financement.pdf » sur notre site internet. | CO3: 🚫 Personnel : Veuillez ne rien saisir ici | CP3: ="Les coûts du personnel (par ex. les salaires) ne doivent pas être saisis dans cette feuille." & CHAR(10) & "Veuillez cliquer sur l’onglet « " & CT10 & " » en bas à gauche." & CHAR(10) & "Vous y saisirez toutes les données concernant le personnel du projet." -> Les coûts du personnel (par ex. les salaires) ne doivent pas être saisis dans cette feuille. Veuillez cliquer sur l’onglet « Payroll structure » en bas à gauche. Vous y saisirez toutes les données concernant le personnel du projet. | CQ3: =CP3 & CHAR(10) & CHAR(10) & "Ces informations sont automatiquement transférées dans la section « Personnel » de cette feuille." & CHAR(10) & "Par conséquent, les cellules de cette section sont verrouillées et ne peuvent pas être modifiées." -> Les coûts du personnel (par ex. les salaires) ne doivent pas être saisis dans cette feuille. Veuillez cliquer sur l’onglet « Payroll structure » en bas à gauche. Vous y saisirez toutes les données concernant le personnel du projet. Ces informations sont automatiquement transférées dans la section « Personnel » de cette feuille. Par conséquent, les cellules de cette section sont verrouillées et ne peuvent pas être modifiées. | CR3: Budget | CS3: Budget détaillé | CT3: Structure salariale | CU3: Les champs remplissables sont dans les couleurs à gauche
A4: AMD | B4: español | C4: P R E S U P U E S T O Y P L A N D E F I N A N C I A M I E N TO | D4: Título del proyecto | E4: Duración planeada | F4: Fecha planeada de início | G4: Documento actualizado el … | H4: Español | I4: Moneda local | J4: Tipo de cambio estimado / € | K4: Gastos de construcción | L4: Subtotal gastos de construcción | M4: Gastos extraordinarios (inversiones) | N4: Subtotal gastos extraorinarios (inversiones) | O4: Gastos de personal | P4: Subtotal gastos de personal | Q4: Gastos corrientes para actividades del proyecto | R4: Subtotal gastos corrientes para actividades | S4: Gastos administrativos del proyecto / Gestión del proyecto | T4: Subtotal gastos administrativos del proyecto | U4: Evaluación | V4: Auditoría externa | W4: Reserva - solo previa autorización | X4: Total | Y4: Cálculo de gastos | Z4: Gastos por año / fase | AA4: Partida de costos | AB4: Unidad | AC4: Cantidad | AD4: % | AE4: Frecuencia | AF4: Gastos por unidad | AG4: Gastos total | AH4: 1er. Año/fase | AI4: 2do. Año/fase | AJ4: 3er. Año/fase | AK4: narrativo | AL4: en moneda local | AM4: Aporte propio | AN4: Aportes de terceros | AO4: Importe solicitado KMW | BA4: Entidad responsable | BB4: Composición salarial | BC4: meses | BD4: Aclaraciones al presupuesto | BE4: Nombre de los terceros aportantes | BF4: Status de la financiación | BG4: Aprobado/Solicitado | BH4: en euros | BI4: período de financiación | BJ4: de | BK4: hasta | BL4: N° | BM4: Apellido, nombre | BN4: posición/puesto | BO4: Descripcion detallado de costos (que explicite los componentes del salário bruto) | BP4: Tipo de contrato: a tiempo completo / parcial (en %) | BQ4: Lugar de trabajo | BR4: Cantidad de salarios mensuales por año | BS4: Sueldo base (bruto) | BT4: Conceptos voluntarios del salário bruto | BU4: Cargas sociales obligatorias del empleador y demás conceptos salariales obligatorios | BV4: Pagos únicos anuales | BW4: Salário bruto anual pagado por el empleador | BX4: Dedicación al proyecto (en %) | BY4: Presupuesto año 1 | BZ4: Presupuesto año 2 | CA4: Presupuesto año 3 | CB4: Informaciones del contrato de trabajo | CC4: Salario mensual (a tiempo completo) | CD4: Gastos anuales de la entidad | CE4: Presupuesto del proyecto | CF4: empleado / mes | CG4: Número de proyecto | CH4: ¡Añade más líneas! | CI4: Duración de la asignación (meses) | CJ4: Aprobado | CK4: Solicitado | CL4: Información: Si necesita más líneas (partidas de gastos), póngase en contacto con nosotros. | CM4: Consejo: | CN4: Estas notas breves no sustituyen las instrucciones completas; para más detalles, consulta: « Ayuda_para_la_elaboracion_del_plan_de_costos_e_financiamiento.pdf » en nuestro sitio web. | CO4: 🚫 Gastos de personal: Por favor, no introduzca nada aquí | CP4: ="Los costes de personal (p. ej., sueldos) no deben ingresarse en esta hoja." & CHAR(10) & "Haga clic en la pestaña « " & CT10 & " » en la parte inferior izquierda." & CHAR(10) & "Allí puede introducir todos los datos sobre el personal del proyecto." -> Los costes de personal (p. ej., sueldos) no deben ingresarse en esta hoja. Haga clic en la pestaña « Payroll structure » en la parte inferior izquierda. Allí puede introducir todos los datos sobre el personal del proyecto. | CQ4: =CP4 & CHAR(10) & CHAR(10) & "Esta información se transfiere automáticamente a la sección « Gastos de personal » de esta hoja." & CHAR(10) & "Por lo tanto, las celdas de esta sección están bloqueadas y no se pueden modificar." -> Los costes de personal (p. ej., sueldos) no deben ingresarse en esta hoja. Haga clic en la pestaña « Payroll structure » en la parte inferior izquierda. Allí puede introducir todos los datos sobre el personal del proyecto. Esta información se transfiere automáticamente a la sección « Gastos de personal » de esta hoja. Por lo tanto, las celdas de esta sección están bloqueadas y no se pueden modificar. | CR4: Presupuesto | CS4: Aclaraciones al presupuesto | CT4: Composición salarial | CU4: Los campos rellenables aparecen en los colores de la izquierda
A5: ANG | B5: português | C5: P L A N O D E C U S T O S E F I N A N C I A M E N T O | D5: Título do projeto | E5: Duração prevista (em meses) | F5: Previsão de início | G5: Documento atualizada em | H5: Português | I5: Moeda local | J5: Proposta de cambio / € | K5: Despesas de construção (civil) | L5: Subtotal despesas de construção (civil) | M5: Despesas únicas (investimentos) | N5: Subtotal Despesas únicas (investimentos) | O5: Despesas com pessoal / recursos humanos | P5: Subtotal Despesas com pessoal / recursos humanos | Q5: Custos de atividades de projeto | R5: Subtotal Custos de atividades de projeto | S5: Administração do projeto | T5: Subtotal Administração do projeto | U5: Avaliação | V5: Auditoria externa | W5: Reserva - somente após autorização | X5: Total | Y5: Cálculo de custos | Z5: Custos por ano / fase | AA5: Item de custos | AB5: Unidade | AC5: Quantidade | AD5: % | AE5: Freqüencia | AF5: Custo unitário | AG5: Custos total | AH5: 1° ano/fase | AI5: 2° ano/fase | AJ5: 3° ano/fase | AK5: Somente texto | AL5: em moeda local | AM5: Contribuição própria | AN5: Contribucões de terceiros | AO5: Subsídio solicitado KMW | BA5: Entidade responsável | BB5: Composição salarial | BC5: meses | BD5: Esclarecimentos orçamentários | BE5: Outras entidades financiadores (terceiros) | BF5: status do financiamento | BG5: Aprovado/Solicitado | BH5: em euros | BI5: período de financiamento | BJ5: de | BK5: até | BL5: N° | BM5: Sobrenome, nome | BN5: Cargo | BO5: Explicações detalhados de custos (que descrimine os componentes do salário bruto) | BP5: Modelo de contrato: tempo integral / parcial (em %) | BQ5: Local de trabalho | BR5: Quantidade de salários mensais por ano | BS5: Salário base (bruto) | BT5: Componentes voluntários do salário bruto | BU5: Encargos sociais obrigatórios do empregador e outros elementos salariais obrigatórios | BV5: Beneficios únicos anuais | BW5: Salário bruto anual pago pelo empregador | BX5: Vinculação ao projeto (em %) | BY5: Orçamento ano 1 | BZ5: Orçamento ano 2 | CA5: Orçamento ano 3 | CB5: Informações do contrato de trabalho | CC5: Salário mensal (de tempo integral) | CD5: Custos anuais da entidade | CE5: Orçamento do projeto | CF5: funcionário / mês | CG5: Número do projeto | CH5: Adicione mais linhas! | CI5: Duração da atuação (meses) | CJ5: Aprovado | CK5: Solicitado | CL5: Informações: Se você precisar de mais linhas (itens de custo), entre em contato conosco. | CM5: Dica: | CN5: Essas informações resumidas não substituem as instruções completas – para mais detalhes, veja: "Guia_para_preenchimento_do_plano_de_custos_e_financiamento.pdf" em nosso site. | CO5: 🚫 Despesas com pessoal: Por favor, não preencha nada aqui | CP5: ="Os custos com pessoal (por exemplo, salários) não devem ser inseridos nesta planilha." & CHAR(10) & "Clique na aba """ & CT10 & """ no canto inferior esquerdo." & CHAR(10) & "Lá você poderá inserir todos os dados sobre os colaboradores do projeto." -> Os custos com pessoal (por exemplo, salários) não devem ser inseridos nesta planilha. Clique na aba "Payroll structure" no canto inferior esquerdo. Lá você poderá inserir todos os dados sobre os colaboradores do projeto. | CQ5: =CP5 & CHAR(10) & CHAR(10) & "Essas informações são transferidas automaticamente para a seção “Despesas com pessoal” desta planilha." & CHAR(10) & "Portanto, as células desta seção estão protegidas contra edição." -> Os custos com pessoal (por exemplo, salários) não devem ser inseridos nesta planilha. Clique na aba "Payroll structure" no canto inferior esquerdo. Lá você poderá inserir todos os dados sobre os colaboradores do projeto. Essas informações são transferidas automaticamente para a seção “Despesas com pessoal” desta planilha. Portanto, as células desta seção estão protegidas contra edição. | CR5: Plano de custos e financiamento | CS5: Esclarecimentos orçamentários | CT5: Composición salarial | CU5: Os campos preenchíveis estão nas cores à esquerda
A6: AOA | B6: 1 | C6: 2 | D6: 3 | E6: 4 | F6: 5 | G6: 6 | H6: 7 | I6: 8 | J6: 9 | K6: 10 | L6: 11 | M6: 12 | N6: 13 | O6: 14 | P6: 15 | Q6: 16 | R6: 17 | S6: 18 | T6: 19 | U6: 20 | V6: 21 | W6: 22 | X6: 23 | Y6: 24 | Z6: 25 | AA6: 26 | AB6: 27 | AC6: 28 | AD6: 29 | AE6: 30 | AF6: 31 | AG6: 32 | AH6: 33 | AI6: 34 | AJ6: 35 | AK6: 36 | AL6: 37 | AM6: 38 | AN6: 39 | AO6: 40 | AP6: 41 | AQ6: 42 | AR6: 43 | AS6: 44 | AT6: 45 | AU6: 46 | AV6: 47 | AW6: 48 | AX6: 49 | AY6: 50 | AZ6: 51 | BA6: 52 | BB6: 53 | BC6: 54 | BD6: 55 | BE6: 56 | BF6: 57 | BG6: 58 | BH6: 59 | BI6: 60 | BJ6: 61 | BK6: 62 | BL6: 63 | BM6: 64 | BN6: 65 | BO6: 66 | BP6: 67 | BQ6: 68 | BR6: 69 | BS6: 70 | BT6: 71 | BU6: 72 | BV6: 73 | BW6: 74 | BX6: 75 | BY6: 76 | BZ6: 77 | CA6: 78 | CB6: 79 | CC6: 80 | CD6: 81 | CE6: 82 | CF6: 83 | CG6: 84 | CH6: 85 | CI6: 86 | CJ6: 87 | CK6: 88 | CL6: 89 | CM6: 90 | CN6: 91 | CO6: 92 | CP6: 93 | CQ6: 94 | CR6: 95 | CS6: 96 | CT6: 97 | CU6: 98
A7: ARS | C7: =COUNTA(C1:C5) -> 5 | D7: =COUNTA(D1:D5) -> 5 | E7: =COUNTA(E1:E5) -> 5 | F7: =COUNTA(F1:F5) -> 5 | G7: =COUNTA(G1:G5) -> 5 | H7: =COUNTA(H1:H5) -> 5 | I7: =COUNTA(I1:I5) -> 5 | J7: =COUNTA(J1:J5) -> 5 | ... CU7: =COUNTA(CU1:CU5) -> 5
A8: AUD
A9: AWG | CJ9: =IF(Budget!$I$3="","",VLOOKUP(Budget!$I$3,Sprachversionen!$B:$EA,87,FALSE)) -> Approved | CK9: =IF(Budget!$I$3="","",VLOOKUP(Budget!$I$3,Sprachversionen!$B:$EA,88,FALSE)) -> Requested | CS9: =IF(RIGHT(Budget!A2,2)="de","deutsch", IF(RIGHT(Budget!A2,2)="en","english", IF(RIGHT(Budget!A2,2)="fr","français", IF(RIGHT(Budget!A2,2)="es","español", IF(RIGHT(Budget!A2,2)="po","português", ""))))) -> english
A10: AZN | CR10: =IF(Budget!I3="","",VLOOKUP($CS$9,Sprachversionen!$B:$EA,95,FALSE)) -> Budget | CS10: =IF($I$3="","",VLOOKUP($CS$9,Sprachversionen!$B:$EA,96,FALSE)) -> Budget explanations | CT10: =IF($I$3="","",VLOOKUP(CS9,Sprachversionen!$B:$EA,97,FALSE)) -> Payroll structure
A11: BAM
A12: BBD
A13: BDT
A14: BGN
A15: BHD
A16: BIF
A17: BMD
A18: BND
A19: BOB
A20: BRL
A21: BSD
A22: BTN
... A153: ZWL

Sheet Sprachversion FB
A1: deutsch | B1: F I N A N Z B E R I C H T | C1: ÜBERSICHT ÜBER EINNAHMEN UND AUSGABEN | D1: Projektnummer | E1: Projektlaufzeit | F1: Aktueller Berichtszeitraum | G1: von (TT MM JJJJ): | H1: bis (TT MM JJJJ): | I1: EINNAHMEN | J1: (in lokaler Währung) | K1: Bewilligtes Budget | L1: Einnahmen im Berichtszeitraum | M1: Kumulierte Gesamtabrechnung | N1: Abweichung | O1: Begründung Abweichung im Berichtszeitraum | P1: Saldovortrag (aus vorherigem Berichtszeitraum) | Q1: Lokale Eigenleistung | R1: Beiträge von dritter Seite | S1: KMW Mittel* | T1: Zinserträge | U1: GESAMT | V1: Datum | W1: Rate (Datum / Betrag der Gutschrift) | X1: AUSGABEN | Y1: Ausgaben im Berichtszeitraum
A2: english
A3: français
A4: español
A5: português
I141: 0
I142: 0
I143: 0
A144: Please" chose your language | I144: 0
