Workbook
Name Saldovortrag_LW: 'Dashboard'!$C$14
Name Saldovortrag_EUR: 'Dashboard'!$E$14
Name Budget_Kurs: 'I. Budget'!$H$4
Name Eigenmittel_LW: 'I. Budget'!$E$7
Name Eigenmittel_EUR: 'I. Budget'!$I$7
Name Drittmittel_LW: 'I. Budget'!$E$10
Name Drittmittel_EUR: 'I. Budget'!$I$10
Name KMW_Mittel_LW: 'I. Budget'!$E$13
Name KMW_Mittel_EUR: 'I. Budget'!$I$13
Name Gesamtprojektmittel_LW: 'I. Budget'!$E$15
Name Gesamtprojektmittel_EUR: 'I. Budget'!$I$15
Name Kosten_Bauausgaben_LW: 'I. Budget'!$O$4
Name Kosten_Bauausgaben_EUR: 'I. Budget'!$P$4
Name Kosten_Investitionen_LW: 'I. Budget'!$O$5
Name Kosten_Investitionen_EUR: 'I. Budget'!$P$5
Name Kosten_Personalkosten_LW: 'I. Budget'!$O$6
Name Kosten_Personalkosten_EUR: 'I. Budget'!$P$6
Name Kosten_Projektaktivitaeten_LW: 'I. Budget'!$O$7
Name Kosten_Projektaktivitaeten_EUR: 'I. Budget'!$P$7
Name Kosten_Projektverwaltung_LW: 'I. Budget'!$O$8
Name Kosten_Projektverwaltung_EUR: 'I. Budget'!$P$8
Name Kosten_Evaluierung_LW: 'I. Budget'!$O$9
Name Kosten_Evaluierung_EUR: 'I. Budget'!$P$9
Name Kosten_Audit_LW: 'I. Budget'!$O$10
Name Kosten_Audit_EUR: 'I. Budget'!$P$10
Name Kosten_Reserve_LW: 'I. Budget'!$O$11
Name Kosten_Reserve_EUR: 'I. Budget'!$P$11
Name Gesamtausgaben_LW: 'I. Budget'!$O$12
Name Gesamtausgaben_EUR: 'I. Budget'!$P$12
Name Budget_ID_Liste: OFFSET('I. Budget'!$S$1, 0, 0, COUNTA('I. Budget'!S:S), 1)
Name Geber_Liste: OFFSET('I. Budget'!$K$19,0,0,MAX(1,COUNTA('I. Budget'!$K$19:$K$19)),1)
Name Reserve_Freigabe: 'I. Budget'!$K$5
Name FB_Kurs_1: 'III. Finanzberichte'!$C$8
Name FB_SaldoLC_1: 'III. Finanzberichte'!$C$144
Name FB_SaldoEUR_1: 'III. Finanzberichte'!$D$144
Name FB_Kurs_2: 'III. Finanzberichte'!$J$8
Name FB_SaldoLC_2: 'III. Finanzberichte'!$J$144
Name FB_SaldoEUR_2: 'III. Finanzberichte'!$K$144
Name FB_Kurs_3: 'III. Finanzberichte'!$Q$8
Name FB_SaldoLC_3: 'III. Finanzberichte'!$Q$144
Name FB_SaldoEUR_3: 'III. Finanzberichte'!$R$144
Name FB_Kurs_4: 'III. Finanzberichte'!$X$8
Name FB_SaldoLC_4: 'III. Finanzberichte'!$X$144
Name FB_SaldoEUR_4: 'III. Finanzberichte'!$Y$144
Name FB_Kurs_5: 'III. Finanzberichte'!$AE$8
Name FB_SaldoLC_5: 'III. Finanzberichte'!$AE$144
Name FB_SaldoEUR_5: 'III. Finanzberichte'!$AF$144
Name FB_Kurs_6: 'III. Finanzberichte'!$AL$8
Name FB_SaldoLC_6: 'III. Finanzberichte'!$AL$144
Name FB_SaldoEUR_6: 'III. Finanzberichte'!$AM$144
Name FB_Kurs_7: 'III. Finanzberichte'!$AS$8
Name FB_SaldoLC_7: 'III. Finanzberichte'!$AS$144
Name FB_SaldoEUR_7: 'III. Finanzberichte'!$AT$144
Name FB_Kurs_8: 'III. Finanzberichte'!$AZ$8
Name FB_SaldoLC_8: 'III. Finanzberichte'!$AZ$144
Name FB_SaldoEUR_8: 'III. Finanzberichte'!$BA$144
Name FB_Kurs_9: 'III. Finanzberichte'!$BG$8
Name FB_SaldoLC_9: 'III. Finanzberichte'!$BG$144
Name FB_SaldoEUR_9: 'III. Finanzberichte'!$BH$144
Name FB_Kurs_10: 'III. Finanzberichte'!$BN$8

Sheet Dashboard
AA1: AED
B2: DASHBOARD (v1.0) | AA2: AFN
AA3: ALL
B4: Statische Projektinformationen | AA4: AMD
B5: Projektnummer | D5: Vorprojekt vorhanden | E5: Ja | AA5: AOA
B6: Projekttitel | AA6: ARS
B7: Projekttraeger | D7: Berichtswaehrung | AA7: AUD
B8: Projektstart | D8: Projektende | AA8: AWG
B9: Projektlaufzeit (geplant) | C9: ==IF(AND(ISNUMBER($C$8),ISNUMBER($E$8)),TEXT(DAY($C$8),"00")&"."&TEXT(MONTH($C$8),"00")&"."&TEXT(YEAR($C$8),"0000")&" - "&TEXT(DAY($E$8),"00")&"."&TEXT(MONTH($E$8),"00")&"."&TEXT(YEAR($E$8),"0000"),"") | D9: In Monate | E9: ==IF(AND(ISNUMBER($C$8),ISNUMBER($E$8)),DATEDIF($C$8,$E$8+1,"M"),"") | AA9: AZN
B10: Vorprojektnummer | D10: VP-Berichtswaehrung | AA10: BAM
B11: Vorprojektende | D11: Wechselkurs | AA11: BBD
B12: Saldo (LW) | D12: Saldo (EUR) | E12: ==IFERROR(ROUND($C$12/$E$11,2),0) | AA12: BDT
B13: Folgeprojektstart | D13: Wechselkurs | AA13: BHD
B14: Saldovortrag (LW) | D14: Saldovortrag (EUR) | E14: ==IFERROR(ROUND($C$14/$E$13,2),0) | AA14: BIF
AA15: BMD
B16: Folgende Dokumente liegen vor: | D16: Nein | E16: Vorprojektsaldo (Nachweis) | AA16: BND
D17: Nein | E17: Vertrag | AA17: BOB
D18: Nein | E18: Budget | AA18: BRL
D19: Nein | E19: Bankbelege | AA19: BSD
D20: Nein | E20: Finanzbericht(e) | AA20: BTN
D21: Nein | E21: Einzelbelege und Beleglisten | AA21: BWP
D22: Nein | E22: Narrativer Bericht | AA22: BYN
AA23: BZD
AA24: CAD
AA25: CDF
AA26: CHF
AA27: CLP
AA28: CNY
AA29: COP
AA30: CRC
AA31: CUP
AA32: CVE
AA33: CZK
AA34: DJF
... AA155: ZWG

Sheet I. Budget
S1: {=IFERROR(_xlfn._xlws.FILTER(TblBudgetAusgaben[ID],TblBudgetAusgaben[ID]<>""),"")} -> 0
B2: I. KERNDATEN BUDGET | K2: Reserve Freigabe
K3: ==$P$11
B4: 1. GEPLANTE EINNAHMEN / FINANZIERUNG | G4: € Budget-Kurs: | H4: ==IFERROR($E$15/$I$15,0) | K4: Reserve freigeben: | O4: ==SUMIFS(TblBudgetAusgaben[Betrag (LC)],TblBudgetAusgaben[Kostenkategorie],"Bauausgaben") | P4: ==SUMIFS(TblBudgetAusgaben[Betrag (EUR)],TblBudgetAusgaben[Kostenkategorie],"Bauausgaben")
B5: Finanzierungsquelle | E5: Betrag (LC) | F5: Jahr 1 | G5: Jahr 2 | H5: Jahr 3 | I5: Betrag (EUR) | K5: Nein | O5: ==SUMIFS(TblBudgetAusgaben[Betrag (LC)],TblBudgetAusgaben[Kostenkategorie],"Investitionen") | P5: ==SUMIFS(TblBudgetAusgaben[Betrag (EUR)],TblBudgetAusgaben[Kostenkategorie],"Investitionen")
B6: 1.1 Eigenmittel | K6: ==IF($K$5="Ja","FREIGEGEBEN","NICHT FREIGEGEBEN") | O6: ==SUMIFS(TblBudgetAusgaben[Betrag (LC)],TblBudgetAusgaben[Kostenkategorie],"Personalkosten") | P6: ==SUMIFS(TblBudgetAusgaben[Betrag (EUR)],TblBudgetAusgaben[Kostenkategorie],"Personalkosten")
B7: Eigenmittel | E7: 120000 | F7: 50000 | G7: 30000 | H7: 40000 | I7: 60000 | O7: ==SUMIFS(TblBudgetAusgaben[Betrag (LC)],TblBudgetAusgaben[Kostenkategorie],"Projektaktivitaeten") | P7: ==SUMIFS(TblBudgetAusgaben[Betrag (EUR)],TblBudgetAusgaben[Kostenkategorie],"Projektaktivitaeten")
K8: Begruendung | O8: ==SUMIFS(TblBudgetAusgaben[Betrag (LC)],TblBudgetAusgaben[Kostenkategorie],"Projektverwaltung") | P8: ==SUMIFS(TblBudgetAusgaben[Betrag (EUR)],TblBudgetAusgaben[Kostenkategorie],"Projektverwaltung")
B9: 1.2 Drittmittel | O9: ==SUMIFS(TblBudgetAusgaben[Betrag (LC)],TblBudgetAusgaben[Kostenkategorie],"Evaluierung") | P9: ==SUMIFS(TblBudgetAusgaben[Betrag (EUR)],TblBudgetAusgaben[Kostenkategorie],"Evaluierung")
B10: Drittmittel (Summe): | D10: Aufstellung je Geber → Tabelle rechts | E10: ==SUM(TblDrittmittel[Betrag (LC)]) | F10: 3000 | G10: 2000 | H10: 1000 | I10: ==SUM(TblDrittmittel[Betrag (EUR)]) | O10: ==SUMIFS(TblBudgetAusgaben[Betrag (LC)],TblBudgetAusgaben[Kostenkategorie],"Audit") | P10: ==SUMIFS(TblBudgetAusgaben[Betrag (EUR)],TblBudgetAusgaben[Kostenkategorie],"Audit")
O11: ==SUMIFS(TblBudgetAusgaben[Betrag (LC)],TblBudgetAusgaben[Kostenkategorie],"Reserve") | P11: ==SUMIFS(TblBudgetAusgaben[Betrag (EUR)],TblBudgetAusgaben[Kostenkategorie],"Reserve")
B12: 1.3 KMW-Mittel | O12: ==SUBTOTAL(109,TblBudgetAusgaben[Betrag (LC)]) | P12: ==SUBTOTAL(109,TblBudgetAusgaben[Betrag (EUR)])
B13: KMW-Mittel | E13: 140700 | F13: 80350 | G13: 56900 | H13: 3450 | I13: 70350
B15: GESAMTPROJEKTMITTEL | E15: ==E7+E10+E13 | F15: ==F7+F10+F13 | G15: ==G7+G10+G13 | H15: ==H7+H10+H13 | I15: ==I7+I10+I13
B17: 2. GEPLANTE AUSGABEN | K17: Drittmittel – Aufstellung je Geber
B18: Kostenkategorie | C18: ID | D18: Kostenposition | E18: Betrag (LC) | F18: Jahr 1 | G18: Jahr 2 | H18: Jahr 3 | I18: Betrag (EUR) | K18: Name des Gebers | L18: Betrag (LC) | M18: Betrag (EUR)
B19: Bauausgaben | C19: 1.1 | D19: Test 1 | E19: 3000 | F19: 1500 | G19: 1000 | H19: 500 | I19: 1500 | K19: Sonstige | L19: 6000 | M19: 3000
B20: Bauausgaben | C20: 1.2 | D20: Test 2 | E20: 3000 | F20: 1500 | G20: 1000 | H20: 500 | I20: 1500
B21: Bauausgaben | C21: 1.3 | D21: Test 3 | E21: 3000 | F21: 1500 | G21: 1000 | H21: 500 | I21: 1500
B22: Bauausgaben | C22: 1.4 | D22: Test 4 | E22: 3000 | F22: 1500 | G22: 1000 | H22: 500 | I22: 1500
B23: Bauausgaben | C23: 1.5 | D23: Test 5 | E23: 3000 | F23: 1500 | G23: 1000 | H23: 500 | I23: 1500
B24: Bauausgaben | C24: 1.6 | D24: Test 6 | E24: 3000 | F24: 1500 | G24: 1000 | H24: 500 | I24: 1500
B25: Bauausgaben | C25: 1.7 | D25: Test 7 | E25: 3000 | F25: 1500 | G25: 1000 | H25: 500 | I25: 1500
B26: Bauausgaben | C26: 1.8 | D26: Test 8 | E26: 3000 | F26: 1500 | G26: 1000 | H26: 500 | I26: 1500
B27: Bauausgaben | C27: 1.9 | D27: Test 9 | E27: 3000 | F27: 1500 | G27: 1000 | H27: 500 | I27: 1500
B28: Bauausgaben | C28: 1.10 | D28: Test 10 | E28: 3000 | F28: 1500 | G28: 1000 | H28: 500 | I28: 1500
B29: Bauausgaben | C29: 1.11 | D29: Test 11 | E29: 3000 | F29: 1500 | G29: 1000 | H29: 500 | I29: 1500
B30: Bauausgaben | C30: 1.12 | D30: Test 12 | E30: 3000 | F30: 1500 | G30: 1000 | H30: 500 | I30: 1500
B31: Bauausgaben | C31: 1.13 | D31: Test 13 | E31: 3000 | F31: 1500 | G31: 1000 | H31: 500 | I31: 1500
... B58: Investitionen | C58: 2.20 | D58: Test 20 | E58: 3000 | F58: 1500 | G58: 1000 | H58: 500 | I58: 1500
B59: Personalkosten | C59: 3.1 | D59: Personalkosten | E59: 0 | I59: 0
B60: Personalkosten | C60: 3.2 | D60: Personalkosten | E60: 0 | I60: 0
B61: Personalkosten | C61: 3.3 | D61: Personalkosten | E61: 0 | I61: 0
B62: Personalkosten | C62: 3.4 | D62: Personalkosten | E62: 0 | I62: 0
B63: Personalkosten | C63: 3.5 | D63: Personalkosten | E63: 0 | I63: 0
B64: Personalkosten | C64: 3.6 | D64: Personalkosten | E64: 0 | I64: 0
B65: Personalkosten | C65: 3.7 | D65: Personalkosten | E65: 0 | I65: 0
B66: Personalkosten | C66: 3.8 | D66: Personalkosten | E66: 0 | I66: 0
B67: Personalkosten | C67: 3.9 | D67: Personalkosten | E67: 0 | I67: 0
B68: Personalkosten | C68: 3.10 | D68: Personalkosten | E68: 0 | I68: 0
...

Sheet II. KMW-Mittel
Z1: Periode 1
B2: II. KMW-MITTEL BEREITGESTELLT | Z2: Periode 2
Z3: Periode 3
B4: Periode | C4: Waehrung | D4: Betrag | E4: Datum | Z4: Periode 4
Z5: Periode 5
Z6: Periode 6
Z7: Periode 7
Z8: Periode 8
Z9: Periode 9
Z10: Periode 10
Z11: Periode 11
Z12: Periode 12
Z13: Periode 13
Z14: Periode 14
Z15: Periode 15
Z16: Periode 16
... Z22: Periode 22
B23: GESAMT | D23: ==SUBTOTAL(109,TblKMWMittel[Betrag]) | Z23: Periode 23
Z24: Periode 24
Z25: Periode 25
Z26: Periode 26
Z27: Periode 27
Z28: Periode 28
Z29: Periode 29
Z30: Periode 30
Z31: Periode 31
Z32: Periode 32
Z33: Periode 33
Z34: Periode 34
Z35: Periode 35
Z36: Periode 36

Sheet III. Finanzberichte
H3: ➤ | O3: ➤ | V3: ➤ | AC3: ➤ | AJ3: ➤ | AQ3: ➤ | AX3: ➤ | BE3: ➤ | BL3: ➤ | BS3: ➤ | BZ3: ➤ | CG3: ➤ | CN3: ➤ | CU3: ➤ | DB3: ➤ | DI3: ➤ | DP3: ➤
B4: Periode: | C4: Periode 1 | I4: Periode: | J4: Periode 2 | P4: Periode: | Q4: Periode 3 | W4: Periode: | X4: Periode 4 | AD4: Periode: | AE4: Periode 5 | AK4: Periode: | AL4: Periode 6 | AR4: Periode: | AS4: Periode 7 | AY4: Periode: | AZ4: Periode 8 | BF4: Periode: | BG4: Periode 9 | BM4: Periode: | BN4: Periode 10 | BT4: Periode: | BU4: Periode 11 | CA4: Periode: | CB4: Periode 12 | CH4: Periode: | CI4: Periode 13 | CO4: Periode: | CP4: Periode 14 | CV4: Periode: | CW4: Periode 15 | DC4: Periode: | DD4: Periode 16 | DJ4: Periode: | DK4: Periode 17 | DQ4: Periode: | DR4: Periode 18
B5: Von: | I5: Von: | P5: Von: | W5: Von: | AD5: Von: | AK5: Von: | AR5: Von: | AY5: Von: | BF5: Von: | BM5: Von: | BT5: Von: | CA5: Von: | CH5: Von: | CO5: Von: | CV5: Von: | DC5: Von: | DJ5: Von: | DQ5: Von:
B6: Bis: | I6: Bis: | P6: Bis: | W6: Bis: | AD6: Bis: | AK6: Bis: | AR6: Bis: | AY6: Bis: | BF6: Bis: | BM6: Bis: | BT6: Bis: | CA6: Bis: | CH6: Bis: | CO6: Bis: | CV6: Bis: | DC6: Bis: | DJ6: Bis: | DQ6: Bis:
B7: Zeitraum: | C7: ==IF(OR(C5="",C6=""),"",DATEDIF(C5,C6,"m")+1) -> 158 | I7: Zeitraum: | J7: ==IF(OR(J5="",J6=""),"",DATEDIF(J5,J6,"m")+1) -> 158 | P7: Zeitraum: | Q7: ==IF(OR(Q5="",Q6=""),"",DATEDIF(Q5,Q6,"m")+1) -> 158 | W7: Zeitraum: | X7: ==IF(OR(X5="",X6=""),"",DATEDIF(X5,X6,"m")+1) -> 158 | AD7: Zeitraum: | AE7: ==IF(OR(AE5="",AE6=""),"",DATEDIF(AE5,AE6,"m")+1) -> 158 | AK7: Zeitraum: | AL7: ==IF(OR(AL5="",AL6=""),"",DATEDIF(AL5,AL6,"m")+1) -> 158 | AR7: Zeitraum: | AS7: ==IF(OR(AS5="",AS6=""),"",DATEDIF(AS5,AS6,"m")+1) -> 158 | AY7: Zeitraum: | AZ7: ==IF(OR(AZ5="",AZ6=""),"",DATEDIF(AZ5,AZ6,"m")+1) -> 158 | BF7: Zeitraum: | BG7: ==IF(OR(BG5="",BG6=""),"",DATEDIF(BG5,BG6,"m")+1) -> 158 | BM7: Zeitraum: | BN7: ==IF(OR(BN5="",BN6=""),"",DATEDIF(BN5,BN6,"m")+1) -> 158 | BT7: Zeitraum: | BU7: ==IF(OR(BU5="",BU6=""),"",DATEDIF(BU5,BU6,"m")+1) -> 158 | CA7: Zeitraum: | CB7: ==IF(OR(CB5="",CB6=""),"",DATEDIF(CB5,CB6,"m")+1) -> 158 | CH7: Zeitraum: | CI7: ==IF(OR(CI5="",CI6=""),"",DATEDIF(CI5,CI6,"m")+1) -> 158 | CO7: Zeitraum: | CP7: ==IF(OR(CP5="",CP6=""),"",DATEDIF(CP5,CP6,"m")+1) -> 158 | CV7: Zeitraum: | CW7: ==IF(OR(CW5="",CW6=""),"",DATEDIF(CW5,CW6,"m")+1) -> 158 | DC7: Zeitraum: | DD7: ==IF(OR(DD5="",DD6=""),"",DATEDIF(DD5,DD6,"m")+1) -> 158 | DJ7: Zeitraum: | DK7: ==IF(OR(DK5="",DK6=""),"",DATEDIF(DK5,DK6,"m")+1) -> 158 | DQ7: Zeitraum: | DR7: ==IF(OR(DR5="",DR6=""),"",DATEDIF(DR5,DR6,"m")+1) -> 158
B8: Durchschnittskurs: | C8: ==ROUND(IFERROR(F161,0),6) -> 158 | I8: Durchschnittskurs: | J8: ==ROUND(IFERROR(M161,0),6) -> 158 | P8: Durchschnittskurs: | Q8: ==ROUND(IFERROR(T161,0),6) -> 158 | W8: Durchschnittskurs: | X8: ==ROUND(IFERROR(AA161,0),6) -> 158 | AD8: Durchschnittskurs: | AE8: ==ROUND(IFERROR(AH161,0),6) -> 158 | AK8: Durchschnittskurs: | AL8: ==ROUND(IFERROR(AO161,0),6) -> 158 | AR8: Durchschnittskurs: | AS8: ==ROUND(IFERROR(AV161,0),6) -> 158 | AY8: Durchschnittskurs: | AZ8: ==ROUND(IFERROR(BC161,0),6) -> 158 | BF8: Durchschnittskurs: | BG8: ==ROUND(IFERROR(BJ161,0),6) -> 158 | BM8: Durchschnittskurs: | BN8: ==ROUND(IFERROR(BQ161,0),6) -> 158 | BT8: Durchschnittskurs: | BU8: ==ROUND(IFERROR(BX161,0),6) -> 158 | CA8: Durchschnittskurs: | CB8: ==ROUND(IFERROR(CE161,0),6) -> 158 | CH8: Durchschnittskurs: | CI8: ==ROUND(IFERROR(CL161,0),6) -> 158 | CO8: Durchschnittskurs: | CP8: ==ROUND(IFERROR(CS161,0),6) -> 158 | CV8: Durchschnittskurs: | CW8: ==ROUND(IFERROR(CZ161,0),6) -> 158 | DC8: Durchschnittskurs: | DD8: ==ROUND(IFERROR(DG161,0),6) -> 158 | DJ8: Durchschnittskurs: | DK8: ==ROUND(IFERROR(DN161,0),6) -> 158 | DQ8: Durchschnittskurs: | DR8: ==ROUND(IFERROR(DU161,0),6) -> 158
B9: Einnahmen | I9: Einnahmen | P9: Einnahmen | W9: Einnahmen | AD9: Einnahmen | AK9: Einnahmen | AR9: Einnahmen | AY9: Einnahmen | BF9: Einnahmen | BM9: Einnahmen | BT9: Einnahmen | CA9: Einnahmen | CH9: Einnahmen | CO9: Einnahmen | CV9: Einnahmen | DC9: Einnahmen | DJ9: Einnahmen | DQ9: Einnahmen
B10: Typ / ID | C10: Einnahmen (LC) | D10: Einnahmen (EUR) | E10: Kum. Einnahmen (LC) | F10: Kum. Einnahmen (EUR) | I10: Typ / ID | J10: Einnahmen (LC) | K10: Einnahmen (EUR) | L10: Kum. Einnahmen (LC) | M10: Kum. Einnahmen (EUR) | P10: Typ / ID | Q10: Einnahmen (LC) | R10: Einnahmen (EUR) | S10: Kum. Einnahmen (LC) | T10: Kum. Einnahmen (EUR) | W10: Typ / ID | X10: Einnahmen (LC) | Y10: Einnahmen (EUR) | Z10: Kum. Einnahmen (LC) | AA10: Kum. Einnahmen (EUR) | AD10: Typ / ID | AE10: Einnahmen (LC) | AF10: Einnahmen (EUR) | AG10: Kum. Einnahmen (LC) | AH10: Kum. Einnahmen (EUR) | AK10: Typ / ID | AL10: Einnahmen (LC) | AM10: Einnahmen (EUR) | AN10: Kum. Einnahmen (LC) | AO10: Kum. Einnahmen (EUR) | AR10: Typ / ID | AS10: Einnahmen (LC) | AT10: Einnahmen (EUR) | AU10: Kum. Einnahmen (LC) | AV10: Kum. Einnahmen (EUR) | AY10: Typ / ID | AZ10: Einnahmen (LC) | BA10: Einnahmen (EUR) | BB10: Kum. Einnahmen (LC) | BC10: Kum. Einnahmen (EUR) | BF10: Typ / ID | BG10: Einnahmen (LC) | BH10: Einnahmen (EUR) | BI10: Kum. Einnahmen (LC) | BJ10: Kum. Einnahmen (EUR) | BM10: Typ / ID | BN10: Einnahmen (LC) | BO10: Einnahmen (EUR) | BP10: Kum. Einnahmen (LC) | BQ10: Kum. Einnahmen (EUR) | BT10: Typ / ID | BU10: Einnahmen (LC) | BV10: Einnahmen (EUR) | BW10: Kum. Einnahmen (LC) | BX10: Kum. Einnahmen (EUR) | CA10: Typ / ID | CB10: Einnahmen (LC) | CC10: Einnahmen (EUR) | CD10: Kum. Einnahmen (LC) | CE10: Kum. Einnahmen (EUR) | CH10: Typ / ID | CI10: Einnahmen (LC) | CJ10: Einnahmen (EUR) | CK10: Kum. Einnahmen (LC) | CL10: Kum. Einnahmen (EUR) | CO10: Typ / ID | CP10: Einnahmen (LC) | CQ10: Einnahmen (EUR) | CR10: Kum. Einnahmen (LC) | CS10: Kum. Einnahmen (EUR) | CV10: Typ / ID | CW10: Einnahmen (LC) | CX10: Einnahmen (EUR) | CY10: Kum. Einnahmen (LC) | CZ10: Kum. Einnahmen (EUR) | DC10: Typ / ID | DD10: Einnahmen (LC) | DE10: Einnahmen (EUR) | DF10: Kum. Einnahmen (LC) | DG10: Kum. Einnahmen (EUR) | DJ10: Typ / ID | DK10: Einnahmen (LC) | DL10: Einnahmen (EUR) | DM10: Kum. Einnahmen (LC) | DN10: Kum. Einnahmen (EUR) | DQ10: Typ / ID | DR10: Einnahmen (LC) | DS10: Einnahmen (EUR) | DT10: Kum. Einnahmen (LC) | DU10: Kum. Einnahmen (EUR)
B11: Vorprojektsaldo | C11: ==ROUND(IF(Saldovortrag_LW="",0,Saldovortrag_LW),2) | D11: ==ROUND(IF(Saldovortrag_EUR="",0,Saldovortrag_EUR),2) | E11: ==ROUND(IF(Saldovortrag_LW="",0,Saldovortrag_LW),2) | F11: ==ROUND(IF(Saldovortrag_EUR="",0,Saldovortrag_EUR),2) | I11: Vorperiodensaldo | J11: ==ROUND(FB_SaldoLC_1,2) | K11: ==ROUND(FB_SaldoEUR_1,2) | L11: ==ROUND(FB_SaldoLC_1,2) | M11: ==ROUND(FB_SaldoEUR_1,2) | P11: Vorperiodensaldo | Q11: ==ROUND(FB_SaldoLC_2,2) | R11: ==ROUND(FB_SaldoEUR_2,2) | S11: ==ROUND(FB_SaldoLC_2,2) | T11: ==ROUND(FB_SaldoEUR_2,2) | W11: Vorperiodensaldo | X11: ==ROUND(FB_SaldoLC_3,2) | Y11: ==ROUND(FB_SaldoEUR_3,2) | Z11: ==ROUND(FB_SaldoLC_3,2) | AA11: ==ROUND(FB_SaldoEUR_3,2) | AD11: Vorperiodensaldo | AE11: ==ROUND(FB_SaldoLC_4,2) | AF11: ==ROUND(FB_SaldoEUR_4,2) | AG11: ==ROUND(FB_SaldoLC_4,2) | AH11: ==ROUND(FB_SaldoEUR_4,2) | AK11: Vorperiodensaldo | AL11: ==ROUND(FB_SaldoLC_5,2) | AM11: ==ROUND(FB_SaldoEUR_5,2) | AN11: ==ROUND(FB_SaldoLC_5,2) | AO11: ==ROUND(FB_SaldoEUR_5,2) | AR11: Vorperiodensaldo | AS11: ==ROUND(FB_SaldoLC_6,2) | AT11: ==ROUND(FB_SaldoEUR_6,2) | AU11: ==ROUND(FB_SaldoLC_6,2) | AV11: ==ROUND(FB_SaldoEUR_6,2) | AY11: Vorperiodensaldo | AZ11: ==ROUND(FB_SaldoLC_7,2) | BA11: ==ROUND(FB_SaldoEUR_7,2) | BB11: ==ROUND(FB_SaldoLC_7,2) | BC11: ==ROUND(FB_SaldoEUR_7,2) | BF11: Vorperiodensaldo | BG11: ==ROUND(FB_SaldoLC_8,2) | BH11: ==ROUND(FB_SaldoEUR_8,2) | BI11: ==ROUND(FB_SaldoLC_8,2) | BJ11: ==ROUND(FB_SaldoEUR_8,2) | BM11: Vorperiodensaldo | BN11: ==ROUND(FB_SaldoLC_9,2) | BO11: ==ROUND(FB_SaldoEUR_9,2) | BP11: ==ROUND(FB_SaldoLC_9,2) | BQ11: ==ROUND(FB_SaldoEUR_9,2) | BT11: Vorperiodensaldo | BU11: ==ROUND(FB_SaldoLC_10,2) | BV11: ==ROUND(FB_SaldoEUR_10,2) | BW11: ==ROUND(FB_SaldoLC_10,2) | BX11: ==ROUND(FB_SaldoEUR_10,2) | CA11: Vorperiodensaldo | CB11: ==ROUND(FB_SaldoLC_11,2) | CC11: ==ROUND(FB_SaldoEUR_11,2) | CD11: ==ROUND(FB_SaldoLC_11,2) | CE11: ==ROUND(FB_SaldoEUR_11,2) | CH11: Vorperiodensaldo | CI11: ==ROUND(FB_SaldoLC_12,2) | CJ11: ==ROUND(FB_SaldoEUR_12,2) | CK11: ==ROUND(FB_SaldoLC_12,2) | CL11: ==ROUND(FB_SaldoEUR_12,2) | CO11: Vorperiodensaldo | CP11: ==ROUND(FB_SaldoLC_13,2) | CQ11: ==ROUND(FB_SaldoEUR_13,2) | CR11: ==ROUND(FB_SaldoLC_13,2) | CS11: ==ROUND(FB_SaldoEUR_13,2) | CV11: Vorperiodensaldo | CW11: ==ROUND(FB_SaldoLC_14,2) | CX11: ==ROUND(FB_SaldoEUR_14,2) | CY11: ==ROUND(FB_SaldoLC_14,2) | CZ11: ==ROUND(FB_SaldoEUR_14,2) | DC11: Vorperiodensaldo | DD11: ==ROUND(FB_SaldoLC_15,2) | DE11: ==ROUND(FB_SaldoEUR_15,2) | DF11: ==ROUND(FB_SaldoLC_15,2) | DG11: ==ROUND(FB_SaldoEUR_15,2) | DJ11: Vorperiodensaldo | DK11: ==ROUND(FB_SaldoLC_16,2) | DL11: ==ROUND(FB_SaldoEUR_16,2) | DM11: ==ROUND(FB_SaldoLC_16,2) | DN11: ==ROUND(FB_SaldoEUR_16,2) | DQ11: Vorperiodensaldo | DR11: ==ROUND(FB_SaldoLC_17,2) | DS11: ==ROUND(FB_SaldoEUR_17,2) | DT11: ==ROUND(FB_SaldoLC_17,2) | DU11: ==ROUND(FB_SaldoEUR_17,2)
B12: Eigenmittel | C12: ==ROUND(SUMIF($B$156:$B$160,"Eigenmittel",$D$156:$D$160)+SUMIF($B$165:$B$170,"Eigenmittel",$D$165:$D$170),2) | D12: ==ROUND(SUMIF($B$156:$B$160,"Eigenmittel",$E$156:$E$160)+SUMIF($B$165:$B$170,"Eigenmittel",$E$165:$E$170),2) | E12: ==ROUND(SUMIF($B$156:$B$160,"Eigenmittel",$D$156:$D$160)+SUMIF($B$165:$B$170,"Eigenmittel",$D$165:$D$170),2) | F12: ==ROUND(SUMIF($B$156:$B$160,"Eigenmittel",$E$156:$E$160)+SUMIF($B$165:$B$170,"Eigenmittel",$E$165:$E$170),2) | I12: Eigenmittel | J12: ==ROUND(SUMIF($I$156:$I$160,"Eigenmittel",$K$156:$K$160)+SUMIF($I$165:$I$170,"Eigenmittel",$K$165:$K$170),2) | K12: ==ROUND(SUMIF($I$156:$I$160,"Eigenmittel",$L$156:$L$160)+SUMIF($I$165:$I$170,"Eigenmittel",$L$165:$L$170),2) | L12: ==IFERROR(ROUND(E12 + J12, 2), J12) | M12: ==IFERROR(ROUND(F12 + K12, 2), K12) | P12: Eigenmittel | Q12: ==ROUND(SUMIF($P$156:$P$160,"Eigenmittel",$R$156:$R$160)+SUMIF($P$165:$P$170,"Eigenmittel",$R$165:$R$170),2) | R12: ==ROUND(SUMIF($P$156:$P$160,"Eigenmittel",$S$156:$S$160)+SUMIF($P$165:$P$170,"Eigenmittel",$S$165:$S$170),2) | S12: ==IFERROR(ROUND(L12 + Q12, 2), Q12) | T12: ==IFERROR(ROUND(M12 + R12, 2), R12) | W12: Eigenmittel | X12: ==ROUND(SUMIF($W$156:$W$160,"Eigenmittel",$Y$156:$Y$160)+SUMIF($W$165:$W$170,"Eigenmittel",$Y$165:$Y$170),2) | Y12: ==ROUND(SUMIF($W$156:$W$160,"Eigenmittel",$Z$156:$Z$160)+SUMIF($W$165:$W$170,"Eigenmittel",$Z$165:$Z$170),2) | Z12: ==IFERROR(ROUND(S12 + X12, 2), X12) | AA12: ==IFERROR(ROUND(T12 + Y12, 2), Y12) | AD12: Eigenmittel | AE12: ==ROUND(SUMIF($AD$156:$AD$160,"Eigenmittel",$AF$156:$AF$160)+SUMIF($AD$165:$AD$170,"Eigenmittel",$AF$165:$AF$170),2) | AF12: ==ROUND(SUMIF($AD$156:$AD$160,"Eigenmittel",$AG$156:$AG$160)+SUMIF($AD$165:$AD$170,"Eigenmittel",$AG$165:$AG$170),2) | AG12: ==IFERROR(ROUND(Z12 + AE12, 2), AE12) | AH12: ==IFERROR(ROUND(AA12 + AF12, 2), AF12) | AK12: Eigenmittel | AL12: ==ROUND(SUMIF($AK$156:$AK$160,"Eigenmittel",$AM$156:$AM$160)+SUMIF($AK$165:$AK$170,"Eigenmittel",$AM$165:$AM$170),2) | AM12: ==ROUND(SUMIF($AK$156:$AK$160,"Eigenmittel",$AN$156:$AN$160)+SUMIF($AK$165:$AK$170,"Eigenmittel",$AN$165:$AN$170),2) | AN12: ==IFERROR(ROUND(AG12 + AL12, 2), AL12) | AO12: ==IFERROR(ROUND(AH12 + AM12, 2), AM12) | AR12: Eigenmittel | AS12: ==ROUND(SUMIF($AR$156:$AR$160,"Eigenmittel",$AT$156:$AT$160)+SUMIF($AR$165:$AR$170,"Eigenmittel",$AT$165:$AT$170),2) | AT12: ==ROUND(SUMIF($AR$156:$AR$160,"Eigenmittel",$AU$156:$AU$160)+SUMIF($AR$165:$AR$170,"Eigenmittel",$AU$165:$AU$170),2) | AU12: ==IFERROR(ROUND(AN12 + AS12, 2), AS12) | AV12: ==IFERROR(ROUND(AO12 + AT12, 2), AT12) | AY12: Eigenmittel | AZ12: ==ROUND(SUMIF($AY$156:$AY$160,"Eigenmittel",$BA$156:$BA$160)+SUMIF($AY$165:$AY$170,"Eigenmittel",$BA$165:$BA$170),2) | BA12: ==ROUND(SUMIF($AY$156:$AY$160,"Eigenmittel",$BB$156:$BB$160)+SUMIF($AY$165:$AY$170,"Eigenmittel",$BB$165:$BB$170),2) | BB12: ==IFERROR(ROUND(AU12 + AZ12, 2), AZ12) | BC12: ==IFERROR(ROUND(AV12 + BA12, 2), BA12) | BF12: Eigenmittel | BG12: ==ROUND(SUMIF($BF$156:$BF$160,"Eigenmittel",$BH$156:$BH$160)+SUMIF($BF$165:$BF$170,"Eigenmittel",$BH$165:$BH$170),2) | BH12: ==ROUND(SUMIF($BF$156:$BF$160,"Eigenmittel",$BI$156:$BI$160)+SUMIF($BF$165:$BF$170,"Eigenmittel",$BI$165:$BI$170),2) | BI12: ==IFERROR(ROUND(BB12 + BG12, 2), BG12) | BJ12: ==IFERROR(ROUND(BC12 + BH12, 2), BH12) | BM12: Eigenmittel | BN12: ==ROUND(SUMIF($BM$156:$BM$160,"Eigenmittel",$BO$156:$BO$160)+SUMIF($BM$165:$BM$170,"Eigenmittel",$BO$165:$BO$170),2) | BO12: ==ROUND(SUMIF($BM$156:$BM$160,"Eigenmittel",$BP$156:$BP$160)+SUMIF($BM$165:$BM$170,"Eigenmittel",$BP$165:$BP$170),2) | BP12: ==IFERROR(ROUND(BI12 + BN12, 2), BN12) | BQ12: ==IFERROR(ROUND(BJ12 + BO12, 2), BO12) | BT12: Eigenmittel | BU12: ==ROUND(SUMIF($BT$156:$BT$160,"Eigenmittel",$BV$156:$BV$160)+SUMIF($BT$165:$BT$170,"Eigenmittel",$BV$165:$BV$170),2) | BV12: ==ROUND(SUMIF($BT$156:$BT$160,"Eigenmittel",$BW$156:$BW$160)+SUMIF($BT$165:$BT$170,"Eigenmittel",$BW$165:$BW$170),2) | BW12: ==IFERROR(ROUND(BP12 + BU12, 2), BU12) | BX12: ==IFERROR(ROUND(BQ12 + BV12, 2), BV12) | CA12: Eigenmittel | CB12: ==ROUND(SUMIF($CA$156:$CA$160,"Eigenmittel",$CC$156:$CC$160)+SUMIF($CA$165:$CA$170,"Eigenmittel",$CC$165:$CC$170),2) | CC12: ==ROUND(SUMIF($CA$156:$CA$160,"Eigenmittel",$CD$156:$CD$160)+SUMIF($CA$165:$CA$170,"Eigenmittel",$CD$165:$CD$170),2) | CD12: ==IFERROR(ROUND(BW12 + CB12, 2), CB12) | CE12: ==IFERROR(ROUND(BX12 + CC12, 2), CC12) | CH12: Eigenmittel | CI12: ==ROUND(SUMIF($CH$156:$CH$160,"Eigenmittel",$CJ$156:$CJ$160)+SUMIF($CH$165:$CH$170,"Eigenmittel",$CJ$165:$CJ$170),2) | CJ12: ==ROUND(SUMIF($CH$156:$CH$160,"Eigenmittel",$CK$156:$CK$160)+SUMIF($CH$165:$CH$170,"Eigenmittel",$CK$165:$CK$170),2) | CK12: ==IFERROR(ROUND(CD12 + CI12, 2), CI12) | CL12: ==IFERROR(ROUND(CE12 + CJ12, 2), CJ12) | CO12: Eigenmittel | CP12: ==ROUND(SUMIF($CO$156:$CO$160,"Eigenmittel",$CQ$156:$CQ$160)+SUMIF($CO$165:$CO$170,"Eigenmittel",$CQ$165:$CQ$170),2) | CQ12: ==ROUND(SUMIF($CO$156:$CO$160,"Eigenmittel",$CR$156:$CR$160)+SUMIF($CO$165:$CO$170,"Eigenmittel",$CR$165:$CR$170),2) | CR12: ==IFERROR(ROUND(CK12 + CP12, 2), CP12) | CS12: ==IFERROR(ROUND(CL12 + CQ12, 2), CQ12) | CV12: Eigenmittel | CW12: ==ROUND(SUMIF($CV$156:$CV$160,"Eigenmittel",$CX$156:$CX$160)+SUMIF($CV$165:$CV$170,"Eigenmittel",$CX$165:$CX$170),2) | CX12: ==ROUND(SUMIF($CV$156:$CV$160,"Eigenmittel",$CY$156:$CY$160)+SUMIF($CV$165:$CV$170,"Eigenmittel",$CY$165:$CY$170),2) | CY12: ==IFERROR(ROUND(CR12 + CW12, 2), CW12) | CZ12: ==IFERROR(ROUND(CS12 + CX12, 2), CX12) | DC12: Eigenmittel | DD12: ==ROUND(SUMIF($DC$156:$DC$160,"Eigenmittel",$DE$156:$DE$160)+SUMIF($DC$165:$DC$170,"Eigenmittel",$DE$165:$DE$170),2) | DE12: ==ROUND(SUMIF($DC$156:$DC$160,"Eigenmittel",$DF$156:$DF$160)+SUMIF($DC$165:$DC$170,"Eigenmittel",$DF$165:$DF$170),2) | DF12: ==IFERROR(ROUND(CY12 + DD12, 2), DD12) | DG12: ==IFERROR(ROUND(CZ12 + DE12, 2), DE12) | DJ12: Eigenmittel | DK12: ==ROUND(SUMIF($DJ$156:$DJ$160,"Eigenmittel",$DL$156:$DL$160)+SUMIF($DJ$165:$DJ$170,"Eigenmittel",$DL$165:$DL$170),2) | DL12: ==ROUND(SUMIF($DJ$156:$DJ$160,"Eigenmittel",$DM$156:$DM$160)+SUMIF($DJ$165:$DJ$170,"Eigenmittel",$DM$165:$DM$170),2) | DM12: ==IFERROR(ROUND(DF12 + DK12, 2), DK12) | DN12: ==IFERROR(ROUND(DG12 + DL12, 2), DL12) | DQ12: Eigenmittel | DR12: ==ROUND(SUMIF($DQ$156:$DQ$160,"Eigenmittel",$DS$156:$DS$160)+SUMIF($DQ$165:$DQ$170,"Eigenmittel",$DS$165:$DS$170),2) | DS12: ==ROUND(SUMIF($DQ$156:$DQ$160,"Eigenmittel",$DT$156:$DT$160)+SUMIF($DQ$165:$DQ$170,"Eigenmittel",$DT$165:$DT$170),2) | DT12: ==IFERROR(ROUND(DM12 + DR12, 2), DR12) | DU12: ==IFERROR(ROUND(DN12 + DS12, 2), DS12)
B13: Drittmittel | C13: ==ROUND(SUMIF($B$156:$B$160,"Drittmittel",$D$156:$D$160)+SUMIF($B$165:$B$170,"Drittmittel",$D$165:$D$170),2) | D13: ==ROUND(SUMIF($B$156:$B$160,"Drittmittel",$E$156:$E$160)+SUMIF($B$165:$B$170,"Drittmittel",$E$165:$E$170),2) | E13: ==ROUND(SUMIF($B$156:$B$160,"Drittmittel",$D$156:$D$160)+SUMIF($B$165:$B$170,"Drittmittel",$D$165:$D$170),2) | F13: ==ROUND(SUMIF($B$156:$B$160,"Drittmittel",$E$156:$E$160)+SUMIF($B$165:$B$170,"Drittmittel",$E$165:$E$170),2) | I13: Drittmittel | J13: ==ROUND(SUMIF($I$156:$I$160,"Drittmittel",$K$156:$K$160)+SUMIF($I$165:$I$170,"Drittmittel",$K$165:$K$170),2) | K13: ==ROUND(SUMIF($I$156:$I$160,"Drittmittel",$L$156:$L$160)+SUMIF($I$165:$I$170,"Drittmittel",$L$165:$L$170),2) | L13: ==IFERROR(ROUND(E13 + J13, 2), J13) | M13: ==IFERROR(ROUND(F13 + K13, 2), K13) | P13: Drittmittel | Q13: ==ROUND(SUMIF($P$156:$P$160,"Drittmittel",$R$156:$R$160)+SUMIF($P$165:$P$170,"Drittmittel",$R$165:$R$170),2) | R13: ==ROUND(SUMIF($P$156:$P$160,"Drittmittel",$S$156:$S$160)+SUMIF($P$165:$P$170,"Drittmittel",$S$165:$S$170),2) | S13: ==IFERROR(ROUND(L13 + Q13, 2), Q13) | T13: ==IFERROR(ROUND(M13 + R13, 2), R13) | W13: Drittmittel | X13: ==ROUND(SUMIF($W$156:$W$160,"Drittmittel",$Y$156:$Y$160)+SUMIF($W$165:$W$170,"Drittmittel",$Y$165:$Y$170),2) | Y13: ==ROUND(SUMIF($W$156:$W$160,"Drittmittel",$Z$156:$Z$160)+SUMIF($W$165:$W$170,"Drittmittel",$Z$165:$Z$170),2) | Z13: ==IFERROR(ROUND(S13 + X13, 2), X13) | AA13: ==IFERROR(ROUND(T13 + Y13, 2), Y13) | AD13: Drittmittel | AE13: ==ROUND(SUMIF($AD$156:$AD$160,"Drittmittel",$AF$156:$AF$160)+SUMIF($AD$165:$AD$170,"Drittmittel",$AF$165:$AF$170),2) | AF13: ==ROUND(SUMIF($AD$156:$AD$160,"Drittmittel",$AG$156:$AG$160)+SUMIF($AD$165:$AD$170,"Drittmittel",$AG$165:$AG$170),2) | AG13: ==IFERROR(ROUND(Z13 + AE13, 2), AE13) | AH13: ==IFERROR(ROUND(AA13 + AF13, 2), AF13) | AK13: Drittmittel | AL13: ==ROUND(SUMIF($AK$156:$AK$160,"Drittmittel",$AM$156:$AM$160)+SUMIF($AK$165:$AK$170,"Drittmittel",$AM$165:$AM$170),2) | AM13: ==ROUND(SUMIF($AK$156:$AK$160,"Drittmittel",$AN$156:$AN$160)+SUMIF($AK$165:$AK$170,"Drittmittel",$AN$165:$AN$170),2) | AN13: ==IFERROR(ROUND(AG13 + AL13, 2), AL13) | AO13: ==IFERROR(ROUND(AH13 + AM13, 2), AM13) | AR13: Drittmittel | AS13: ==ROUND(SUMIF($AR$156:$AR$160,"Drittmittel",$AT$156:$AT$160)+SUMIF($AR$165:$AR$170,"Drittmittel",$AT$165:$AT$170),2) | AT13: ==ROUND(SUMIF($AR$156:$AR$160,"Drittmittel",$AU$156:$AU$160)+SUMIF($AR$165:$AR$170,"Drittmittel",$AU$165:$AU$170),2) | AU13: ==IFERROR(ROUND(AN13 + AS13, 2), AS13) | AV13: ==IFERROR(ROUND(AO13 + AT13, 2), AT13) | AY13: Drittmittel | AZ13: ==ROUND(SUMIF($AY$156:$AY$160,"Drittmittel",$BA$156:$BA$160)+SUMIF($AY$165:$AY$170,"Drittmittel",$BA$165:$BA$170),2) | BA13: ==ROUND(SUMIF($AY$156:$AY$160,"Drittmittel",$BB$156:$BB$160)+SUMIF($AY$165:$AY$170,"Drittmittel",$BB$165:$BB$170),2) | BB13: ==IFERROR(ROUND(AU13 + AZ13, 2), AZ13) | BC13: ==IFERROR(ROUND(AV13 + BA13, 2), BA13) | BF13: Drittmittel | BG13: ==ROUND(SUMIF($BF$156:$BF$160,"Drittmittel",$BH$156:$BH$160)+SUMIF($BF$165:$BF$170,"Drittmittel",$BH$165:$BH$170),2) | BH13: ==ROUND(SUMIF($BF$156:$BF$160,"Drittmittel",$BI$156:$BI$160)+SUMIF($BF$165:$BF$170,"Drittmittel",$BI$165:$BI$170),2) | BI13: ==IFERROR(ROUND(BB13 + BG13, 2), BG13) | BJ13: ==IFERROR(ROUND(BC13 + BH13, 2), BH13) | BM13: Drittmittel | BN13: ==ROUND(SUMIF($BM$156:$BM$160,"Drittmittel",$BO$156:$BO$160)+SUMIF($BM$165:$BM$170,"Drittmittel",$BO$165:$BO$170),2) | BO13: ==ROUND(SUMIF($BM$156:$BM$160,"Drittmittel",$BP$156:$BP$160)+SUMIF($BM$165:$BM$170,"Drittmittel",$BP$165:$BP$170),2) | BP13: ==IFERROR(ROUND(BI13 + BN13, 2), BN13) | BQ13: ==IFERROR(ROUND(BJ13 + BO13, 2), BO13) | BT13: Drittmittel | BU13: ==ROUND(SUMIF($BT$156:$BT$160,"Drittmittel",$BV$156:$BV$160)+SUMIF($BT$165:$BT$170,"Drittmittel",$BV$165:$BV$170),2) | BV13: ==ROUND(SUMIF($BT$156:$BT$160,"Drittmittel",$BW$156:$BW$160)+SUMIF($BT$165:$BT$170,"Drittmittel",$BW$165:$BW$170),2) | BW13: ==IFERROR(ROUND(BP13 + BU13, 2), BU13) | BX13: ==IFERROR(ROUND(BQ13 + BV13, 2), BV13) | CA13: Drittmittel | CB13: ==ROUND(SUMIF($CA$156:$CA$160,"Drittmittel",$CC$156:$CC$160)+SUMIF($CA$165:$CA$170,"Drittmittel",$CC$165:$CC$170),2) | CC13: ==ROUND(SUMIF($CA$156:$CA$160,"Drittmittel",$CD$156:$CD$160)+SUMIF($CA$165:$CA$170,"Drittmittel",$CD$165:$CD$170),2) | CD13: ==IFERROR(ROUND(BW13 + CB13, 2), CB13) | CE13: ==IFERROR(ROUND(BX13 + CC13, 2), CC13) | CH13: Drittmittel | CI13: ==ROUND(SUMIF($CH$156:$CH$160,"Drittmittel",$CJ$156:$CJ$160)+SUMIF($CH$165:$CH$170,"Drittmittel",$CJ$165:$CJ$170),2) | CJ13: ==ROUND(SUMIF($CH$156:$CH$160,"Drittmittel",$CK$156:$CK$160)+SUMIF($CH$165:$CH$170,"Drittmittel",$CK$165:$CK$170),2) | CK13: ==IFERROR(ROUND(CD13 + CI13, 2), CI13) | CL13: ==IFERROR(ROUND(CE13 + CJ13, 2), CJ13) | CO13: Drittmittel | CP13: ==ROUND(SUMIF($CO$156:$CO$160,"Drittmittel",$CQ$156:$CQ$160)+SUMIF($CO$165:$CO$170,"Drittmittel",$CQ$165:$CQ$170),2) | CQ13: ==ROUND(SUMIF($CO$156:$CO$160,"Drittmittel",$CR$156:$CR$160)+SUMIF($CO$165:$CO$170,"Drittmittel",$CR$165:$CR$170),2) | CR13: ==IFERROR(ROUND(CK13 + CP13, 2), CP13) | CS13: ==IFERROR(ROUND(CL13 + CQ13, 2), CQ13) | CV13: Drittmittel | CW13: ==ROUND(SUMIF($CV$156:$CV$160,"Drittmittel",$CX$156:$CX$160)+SUMIF($CV$165:$CV$170,"Drittmittel",$CX$165:$CX$170),2) | CX13: ==ROUND(SUMIF($CV$156:$CV$160,"Drittmittel",$CY$156:$CY$160)+SUMIF($CV$165:$CV$170,"Drittmittel",$CY$165:$CY$170),2) | CY13: ==IFERROR(ROUND(CR13 + CW13, 2), CW13) | CZ13: ==IFERROR(ROUND(CS13 + CX13, 2), CX13) | DC13: Drittmittel | DD13: ==ROUND(SUMIF($DC$156:$DC$160,"Drittmittel",$DE$156:$DE$160)+SUMIF($DC$165:$DC$170,"Drittmittel",$DE$165:$DE$170),2) | DE13: ==ROUND(SUMIF($DC$156:$DC$160,"Drittmittel",$DF$156:$DF$160)+SUMIF($DC$165:$DC$170,"Drittmittel",$DF$165:$DF$170),2) | DF13: ==IFERROR(ROUND(CY13 + DD13, 2), DD13) | DG13: ==IFERROR(ROUND(CZ13 + DE13, 2), DE13) | DJ13: Drittmittel | DK13: ==ROUND(SUMIF($DJ$156:$DJ$160,"Drittmittel",$DL$156:$DL$160)+SUMIF($DJ$165:$DJ$170,"Drittmittel",$DL$165:$DL$170),2) | DL13: ==ROUND(SUMIF($DJ$156:$DJ$160,"Drittmittel",$DM$156:$DM$160)+SUMIF($DJ$165:$DJ$170,"Drittmittel",$DM$165:$DM$170),2) | DM13: ==IFERROR(ROUND(DF13 + DK13, 2), DK13) | DN13: ==IFERROR(ROUND(DG13 + DL13, 2), DL13) | DQ13: Drittmittel | DR13: ==ROUND(SUMIF($DQ$156:$DQ$160,"Drittmittel",$DS$156:$DS$160)+SUMIF($DQ$165:$DQ$170,"Drittmittel",$DS$165:$DS$170),2) | DS13: ==ROUND(SUMIF($DQ$156:$DQ$160,"Drittmittel",$DT$156:$DT$160)+SUMIF($DQ$165:$DQ$170,"Drittmittel",$DT$165:$DT$170),2) | DT13: ==IFERROR(ROUND(DM13 + DR13, 2), DR13) | DU13: ==IFERROR(ROUND(DN13 + DS13, 2), DS13)
B14: KMW-Mittel | C14: ==ROUND(SUMIF($B$156:$B$160,"KMW-Mittel",$D$156:$D$160)+SUMIF($B$165:$B$170,"KMW-Mittel",$D$165:$D$170),2) | D14: ==ROUND(SUMIF($B$156:$B$160,"KMW-Mittel",$E$156:$E$160)+SUMIF($B$165:$B$170,"KMW-Mittel",$E$165:$E$170),2) | E14: ==ROUND(SUMIF($B$156:$B$160,"KMW-Mittel",$D$156:$D$160)+SUMIF($B$165:$B$170,"KMW-Mittel",$D$165:$D$170),2) | F14: ==ROUND(SUMIF($B$156:$B$160,"KMW-Mittel",$E$156:$E$160)+SUMIF($B$165:$B$170,"KMW-Mittel",$E$165:$E$170),2) | I14: KMW-Mittel | J14: ==ROUND(SUMIF($I$156:$I$160,"KMW-Mittel",$K$156:$K$160)+SUMIF($I$165:$I$170,"KMW-Mittel",$K$165:$K$170),2) | K14: ==ROUND(SUMIF($I$156:$I$160,"KMW-Mittel",$L$156:$L$160)+SUMIF($I$165:$I$170,"KMW-Mittel",$L$165:$L$170),2) | L14: ==IFERROR(ROUND(E14 + J14, 2), J14) | M14: ==IFERROR(ROUND(F14 + K14, 2), K14) | P14: KMW-Mittel | Q14: ==ROUND(SUMIF($P$156:$P$160,"KMW-Mittel",$R$156:$R$160)+SUMIF($P$165:$P$170,"KMW-Mittel",$R$165:$R$170),2) | R14: ==ROUND(SUMIF($P$156:$P$160,"KMW-Mittel",$S$156:$S$160)+SUMIF($P$165:$P$170,"KMW-Mittel",$S$165:$S$170),2) | S14: ==IFERROR(ROUND(L14 + Q14, 2), Q14) | T14: ==IFERROR(ROUND(M14 + R14, 2), R14) | W14: KMW-Mittel | X14: ==ROUND(SUMIF($W$156:$W$160,"KMW-Mittel",$Y$156:$Y$160)+SUMIF($W$165:$W$170,"KMW-Mittel",$Y$165:$Y$170),2) | Y14: ==ROUND(SUMIF($W$156:$W$160,"KMW-Mittel",$Z$156:$Z$160)+SUMIF($W$165:$W$170,"KMW-Mittel",$Z$165:$Z$170),2) | Z14: ==IFERROR(ROUND(S14 + X14, 2), X14) | AA14: ==IFERROR(ROUND(T14 + Y14, 2), Y14) | AD14: KMW-Mittel | AE14: ==ROUND(SUMIF($AD$156:$AD$160,"KMW-Mittel",$AF$156:$AF$160)+SUMIF($AD$165:$AD$170,"KMW-Mittel",$AF$165:$AF$170),2) | AF14: ==ROUND(SUMIF($AD$156:$AD$160,"KMW-Mittel",$AG$156:$AG$160)+SUMIF($AD$165:$AD$170,"KMW-Mittel",$AG$165:$AG$170),2) | AG14: ==IFERROR(ROUND(Z14 + AE14, 2), AE14) | AH14: ==IFERROR(ROUND(AA14 + AF14, 2), AF14) | AK14: KMW-Mittel | AL14: ==ROUND(SUMIF($AK$156:$AK$160,"KMW-Mittel",$AM$156:$AM$160)+SUMIF($AK$165:$AK$170,"KMW-Mittel",$AM$165:$AM$170),2) | AM14: ==ROUND(SUMIF($AK$156:$AK$160,"KMW-Mittel",$AN$156:$AN$160)+SUMIF($AK$165:$AK$170,"KMW-Mittel",$AN$165:$AN$170),2) | AN14: ==IFERROR(ROUND(AG14 + AL14, 2), AL14) | AO14: ==IFERROR(ROUND(AH14 + AM14, 2), AM14) | AR14: KMW-Mittel | AS14: ==ROUND(SUMIF($AR$156:$AR$160,"KMW-Mittel",$AT$156:$AT$160)+SUMIF($AR$165:$AR$170,"KMW-Mittel",$AT$165:$AT$170),2) | AT14: ==ROUND(SUMIF($AR$156:$AR$160,"KMW-Mittel",$AU$156:$AU$160)+SUMIF($AR$165:$AR$170,"KMW-Mittel",$AU$165:$AU$170),2) | AU14: ==IFERROR(ROUND(AN14 + AS14, 2), AS14) | AV14: ==IFERROR(ROUND(AO14 + AT14, 2), AT14) | AY14: KMW-Mittel | AZ14: ==ROUND(SUMIF($AY$156:$AY$160,"KMW-Mittel",$BA$156:$BA$160)+SUMIF($AY$165:$AY$170,"KMW-Mittel",$BA$165:$BA$170),2) | BA14: ==ROUND(SUMIF($AY$156:$AY$160,"KMW-Mittel",$BB$156:$BB$160)+SUMIF($AY$165:$AY$170,"KMW-Mittel",$BB$165:$BB$170),2) | BB14: ==IFERROR(ROUND(AU14 + AZ14, 2), AZ14) | BC14: ==IFERROR(ROUND(AV14 + BA14, 2), BA14) | BF14: KMW-Mittel | BG14: ==ROUND(SUMIF($BF$156:$BF$160,"KMW-Mittel",$BH$156:$BH$160)+SUMIF($BF$165:$BF$170,"KMW-Mittel",$BH$165:$BH$170),2) | BH14: ==ROUND(SUMIF($BF$156:$BF$160,"KMW-Mittel",$BI$156:$BI$160)+SUMIF($BF$165:$BF$170,"KMW-Mittel",$BI$165:$BI$170),2) | BI14: ==IFERROR(ROUND(BB14 + BG14, 2), BG14) | BJ14: ==IFERROR(ROUND(BC14 + BH14, 2), BH14) | BM14: KMW-Mittel | BN14: ==ROUND(SUMIF($BM$156:$BM$160,"KMW-Mittel",$BO$156:$BO$160)+SUMIF($BM$165:$BM$170,"KMW-Mittel",$BO$165:$BO$170),2) | BO14: ==ROUND(SUMIF($BM$156:$BM$160,"KMW-Mittel",$BP$156:$BP$160)+SUMIF($BM$165:$BM$170,"KMW-Mittel",$BP$165:$BP$170),2) | BP14: ==IFERROR(ROUND(BI14 + BN14, 2), BN14) | BQ14: ==IFERROR(ROUND(BJ14 + BO14, 2), BO14) | BT14: KMW-Mittel | BU14: ==ROUND(SUMIF($BT$156:$BT$160,"KMW-Mittel",$BV$156:$BV$160)+SUMIF($BT$165:$BT$170,"KMW-Mittel",$BV$165:$BV$170),2) | BV14: ==ROUND(SUMIF($BT$156:$BT$160,"KMW-Mittel",$BW$156:$BW$160)+SUMIF($BT$165:$BT$170,"KMW-Mittel",$BW$165:$BW$170),2) | BW14: ==IFERROR(ROUND(BP14 + BU14, 2), BU14) | BX14: ==IFERROR(ROUND(BQ14 + BV14, 2), BV14) | CA14: KMW-Mittel | CB14: ==ROUND(SUMIF($CA$156:$CA$160,"KMW-Mittel",$CC$156:$CC$160)+SUMIF($CA$165:$CA$170,"KMW-Mittel",$CC$165:$CC$170),2) | CC14: ==ROUND(SUMIF($CA$156:$CA$160,"KMW-Mittel",$CD$156:$CD$160)+SUMIF($CA$165:$CA$170,"KMW-Mittel",$CD$165:$CD$170),2) | CD14: ==IFERROR(ROUND(BW14 + CB14, 2), CB14) | CE14: ==IFERROR(ROUND(BX14 + CC14, 2), CC14) | CH14: KMW-Mittel | CI14: ==ROUND(SUMIF($CH$156:$CH$160,"KMW-Mittel",$CJ$156:$CJ$160)+SUMIF($CH$165:$CH$170,"KMW-Mittel",$CJ$165:$CJ$170),2) | CJ14: ==ROUND(SUMIF($CH$156:$CH$160,"KMW-Mittel",$CK$156:$CK$160)+SUMIF($CH$165:$CH$170,"KMW-Mittel",$CK$165:$CK$170),2) | CK14: ==IFERROR(ROUND(CD14 + CI14, 2), CI14) | CL14: ==IFERROR(ROUND(CE14 + CJ14, 2), CJ14) | CO14: KMW-Mittel | CP14: ==ROUND(SUMIF($CO$156:$CO$160,"KMW-Mittel",$CQ$156:$CQ$160)+SUMIF($CO$165:$CO$170,"KMW-Mittel",$CQ$165:$CQ$170),2) | CQ14: ==ROUND(SUMIF($CO$156:$CO$160,"KMW-Mittel",$CR$156:$CR$160)+SUMIF($CO$165:$CO$170,"KMW-Mittel",$CR$165:$CR$170),2) | CR14: ==IFERROR(ROUND(CK14 + CP14, 2), CP14) | CS14: ==IFERROR(ROUND(CL14 + CQ14, 2), CQ14) | CV14: KMW-Mittel | CW14: ==ROUND(SUMIF($CV$156:$CV$160,"KMW-Mittel",$CX$156:$CX$160)+SUMIF($CV$165:$CV$170,"KMW-Mittel",$CX$165:$CX$170),2) | CX14: ==ROUND(SUMIF($CV$156:$CV$160,"KMW-Mittel",$CY$156:$CY$160)+SUMIF($CV$165:$CV$170,"KMW-Mittel",$CY$165:$CY$170),2) | CY14: ==IFERROR(ROUND(CR14 + CW14, 2), CW14) | CZ14: ==IFERROR(ROUND(CS14 + CX14, 2), CX14) | DC14: KMW-Mittel | DD14: ==ROUND(SUMIF($DC$156:$DC$160,"KMW-Mittel",$DE$156:$DE$160)+SUMIF($DC$165:$DC$170,"KMW-Mittel",$DE$165:$DE$170),2) | DE14: ==ROUND(SUMIF($DC$156:$DC$160,"KMW-Mittel",$DF$156:$DF$160)+SUMIF($DC$165:$DC$170,"KMW-Mittel",$DF$165:$DF$170),2) | DF14: ==IFERROR(ROUND(CY14 + DD14, 2), DD14) | DG14: ==IFERROR(ROUND(CZ14 + DE14, 2), DE14) | DJ14: KMW-Mittel | DK14: ==ROUND(SUMIF($DJ$156:$DJ$160,"KMW-Mittel",$DL$156:$DL$160)+SUMIF($DJ$165:$DJ$170,"KMW-Mittel",$DL$165:$DL$170),2) | DL14: ==ROUND(SUMIF($DJ$156:$DJ$160,"KMW-Mittel",$DM$156:$DM$160)+SUMIF($DJ$165:$DJ$170,"KMW-Mittel",$DM$165:$DM$170),2) | DM14: ==IFERROR(ROUND(DF14 + DK14, 2), DK14) | DN14: ==IFERROR(ROUND(DG14 + DL14, 2), DL14) | DQ14: KMW-Mittel | DR14: ==ROUND(SUMIF($DQ$156:$DQ$160,"KMW-Mittel",$DS$156:$DS$160)+SUMIF($DQ$165:$DQ$170,"KMW-Mittel",$DS$165:$DS$170),2) | DS14: ==ROUND(SUMIF($DQ$156:$DQ$160,"KMW-Mittel",$DT$156:$DT$160)+SUMIF($DQ$165:$DQ$170,"KMW-Mittel",$DT$165:$DT$170),2) | DT14: ==IFERROR(ROUND(DM14 + DR14, 2), DR14) | DU14: ==IFERROR(ROUND(DN14 + DS14, 2), DS14)
B15: Zinsertraege | C15: ==ROUND(SUMIF($B$156:$B$160,"Zinsertraege",$D$156:$D$160)+SUMIF($B$165:$B$170,"Zinsertraege",$D$165:$D$170),2) | D15: ==ROUND(SUMIF($B$156:$B$160,"Zinsertraege",$E$156:$E$160)+SUMIF($B$165:$B$170,"Zinsertraege",$E$165:$E$170),2) | E15: ==ROUND(SUMIF($B$156:$B$160,"Zinsertraege",$D$156:$D$160)+SUMIF($B$165:$B$170,"Zinsertraege",$D$165:$D$170),2) | F15: ==ROUND(SUMIF($B$156:$B$160,"Zinsertraege",$E$156:$E$160)+SUMIF($B$165:$B$170,"Zinsertraege",$E$165:$E$170),2) | I15: Zinsertraege | J15: ==ROUND(SUMIF($I$156:$I$160,"Zinsertraege",$K$156:$K$160)+SUMIF($I$165:$I$170,"Zinsertraege",$K$165:$K$170),2) | K15: ==ROUND(SUMIF($I$156:$I$160,"Zinsertraege",$L$156:$L$160)+SUMIF($I$165:$I$170,"Zinsertraege",$L$165:$L$170),2) | L15: ==IFERROR(ROUND(E15 + J15, 2), J15) | M15: ==IFERROR(ROUND(F15 + K15, 2), K15) | P15: Zinsertraege | Q15: ==ROUND(SUMIF($P$156:$P$160,"Zinsertraege",$R$156:$R$160)+SUMIF($P$165:$P$170,"Zinsertraege",$R$165:$R$170),2) | R15: ==ROUND(SUMIF($P$156:$P$160,"Zinsertraege",$S$156:$S$160)+SUMIF($P$165:$P$170,"Zinsertraege",$S$165:$S$170),2) | S15: ==IFERROR(ROUND(L15 + Q15, 2), Q15) | T15: ==IFERROR(ROUND(M15 + R15, 2), R15) | W15: Zinsertraege | X15: ==ROUND(SUMIF($W$156:$W$160,"Zinsertraege",$Y$156:$Y$160)+SUMIF($W$165:$W$170,"Zinsertraege",$Y$165:$Y$170),2) | Y15: ==ROUND(SUMIF($W$156:$W$160,"Zinsertraege",$Z$156:$Z$160)+SUMIF($W$165:$W$170,"Zinsertraege",$Z$165:$Z$170),2) | Z15: ==IFERROR(ROUND(S15 + X15, 2), X15) | AA15: ==IFERROR(ROUND(T15 + Y15, 2), Y15) | AD15: Zinsertraege | AE15: ==ROUND(SUMIF($AD$156:$AD$160,"Zinsertraege",$AF$156:$AF$160)+SUMIF($AD$165:$AD$170,"Zinsertraege",$AF$165:$AF$170),2) | AF15: ==ROUND(SUMIF($AD$156:$AD$160,"Zinsertraege",$AG$156:$AG$160)+SUMIF($AD$165:$AD$170,"Zinsertraege",$AG$165:$AG$170),2) | AG15: ==IFERROR(ROUND(Z15 + AE15, 2), AE15) | AH15: ==IFERROR(ROUND(AA15 + AF15, 2), AF15) | AK15: Zinsertraege | AL15: ==ROUND(SUMIF($AK$156:$AK$160,"Zinsertraege",$AM$156:$AM$160)+SUMIF($AK$165:$AK$170,"Zinsertraege",$AM$165:$AM$170),2) | AM15: ==ROUND(SUMIF($AK$156:$AK$160,"Zinsertraege",$AN$156:$AN$160)+SUMIF($AK$165:$AK$170,"Zinsertraege",$AN$165:$AN$170),2) | AN15: ==IFERROR(ROUND(AG15 + AL15, 2), AL15) | AO15: ==IFERROR(ROUND(AH15 + AM15, 2), AM15) | AR15: Zinsertraege | AS15: ==ROUND(SUMIF($AR$156:$AR$160,"Zinsertraege",$AT$156:$AT$160)+SUMIF($AR$165:$AR$170,"Zinsertraege",$AT$165:$AT$170),2) | AT15: ==ROUND(SUMIF($AR$156:$AR$160,"Zinsertraege",$AU$156:$AU$160)+SUMIF($AR$165:$AR$170,"Zinsertraege",$AU$165:$AU$170),2) | AU15: ==IFERROR(ROUND(AN15 + AS15, 2), AS15) | AV15: ==IFERROR(ROUND(AO15 + AT15, 2), AT15) | AY15: Zinsertraege | AZ15: ==ROUND(SUMIF($AY$156:$AY$160,"Zinsertraege",$BA$156:$BA$160)+SUMIF($AY$165:$AY$170,"Zinsertraege",$BA$165:$BA$170),2) | BA15: ==ROUND(SUMIF($AY$156:$AY$160,"Zinsertraege",$BB$156:$BB$160)+SUMIF($AY$165:$AY$170,"Zinsertraege",$BB$165:$BB$170),2) | BB15: ==IFERROR(ROUND(AU15 + AZ15, 2), AZ15) | BC15: ==IFERROR(ROUND(AV15 + BA15, 2), BA15) | BF15: Zinsertraege | BG15: ==ROUND(SUMIF($BF$156:$BF$160,"Zinsertraege",$BH$156:$BH$160)+SUMIF($BF$165:$BF$170,"Zinsertraege",$BH$165:$BH$170),2) | BH15: ==ROUND(SUMIF($BF$156:$BF$160,"Zinsertraege",$BI$156:$BI$160)+SUMIF($BF$165:$BF$170,"Zinsertraege",$BI$165:$BI$170),2) | BI15: ==IFERROR(ROUND(BB15 + BG15, 2), BG15) | BJ15: ==IFERROR(ROUND(BC15 + BH15, 2), BH15) | BM15: Zinsertraege | BN15: ==ROUND(SUMIF($BM$156:$BM$160,"Zinsertraege",$BO$156:$BO$160)+SUMIF($BM$165:$BM$170,"Zinsertraege",$BO$165:$BO$170),2) | BO15: ==ROUND(SUMIF($BM$156:$BM$160,"Zinsertraege",$BP$156:$BP$160)+SUMIF($BM$165:$BM$170,"Zinsertraege",$BP$165:$BP$170),2) | BP15: ==IFERROR(ROUND(BI15 + BN15, 2), BN15) | BQ15: ==IFERROR(ROUND(BJ15 + BO15, 2), BO15) | BT15: Zinsertraege | BU15: ==ROUND(SUMIF($BT$156:$BT$160,"Zinsertraege",$BV$156:$BV$160)+SUMIF($BT$165:$BT$170,"Zinsertraege",$BV$165:$BV$170),2) | BV15: ==ROUND(SUMIF($BT$156:$BT$160,"Zinsertraege",$BW$156:$BW$160)+SUMIF($BT$165:$BT$170,"Zinsertraege",$BW$165:$BW$170),2) | BW15: ==IFERROR(ROUND(BP15 + BU15, 2), BU15) | BX15: ==IFERROR(ROUND(BQ15 + BV15, 2), BV15) | CA15: Zinsertraege | CB15: ==ROUND(SUMIF($CA$156:$CA$160,"Zinsertraege",$CC$156:$CC$160)+SUMIF($CA$165:$CA$170,"Zinsertraege",$CC$165:$CC$170),2) | CC15: ==ROUND(SUMIF($CA$156:$CA$160,"Zinsertraege",$CD$156:$CD$160)+SUMIF($CA$165:$CA$170,"Zinsertraege",$CD$165:$CD$170),2) | CD15: ==IFERROR(ROUND(BW15 + CB15, 2), CB15) | CE15: ==IFERROR(ROUND(BX15 + CC15, 2), CC15) | CH15: Zinsertraege | CI15: ==ROUND(SUMIF($CH$156:$CH$160,"Zinsertraege",$CJ$156:$CJ$160)+SUMIF($CH$165:$CH$170,"Zinsertraege",$CJ$165:$CJ$170),2) | CJ15: ==ROUND(SUMIF($CH$156:$CH$160,"Zinsertraege",$CK$156:$CK$160)+SUMIF($CH$165:$CH$170,"Zinsertraege",$CK$165:$CK$170),2) | CK15: ==IFERROR(ROUND(CD15 + CI15, 2), CI15) | CL15: ==IFERROR(ROUND(CE15 + CJ15, 2), CJ15) | CO15: Zinsertraege | CP15: ==ROUND(SUMIF($CO$156:$CO$160,"Zinsertraege",$CQ$156:$CQ$160)+SUMIF($CO$165:$CO$170,"Zinsertraege",$CQ$165:$CQ$170),2) | CQ15: ==ROUND(SUMIF($CO$156:$CO$160,"Zinsertraege",$CR$156:$CR$160)+SUMIF($CO$165:$CO$170,"Zinsertraege",$CR$165:$CR$170),2) | CR15: ==IFERROR(ROUND(CK15 + CP15, 2), CP15) | CS15: ==IFERROR(ROUND(CL15 + CQ15, 2), CQ15) | CV15: Zinsertraege | CW15: ==ROUND(SUMIF($CV$156:$CV$160,"Zinsertraege",$CX$156:$CX$160)+SUMIF($CV$165:$CV$170,"Zinsertraege",$CX$165:$CX$170),2) | CX15: ==ROUND(SUMIF($CV$156:$CV$160,"Zinsertraege",$CY$156:$CY$160)+SUMIF($CV$165:$CV$170,"Zinsertraege",$CY$165:$CY$170),2) | CY15: ==IFERROR(ROUND(CR15 + CW15, 2), CW15) | CZ15: ==IFERROR(ROUND(CS15 + CX15, 2), CX15) | DC15: Zinsertraege | DD15: ==ROUND(SUMIF($DC$156:$DC$160,"Zinsertraege",$DE$156:$DE$160)+SUMIF($DC$165:$DC$170,"Zinsertraege",$DE$165:$DE$170),2) | DE15: ==ROUND(SUMIF($DC$156:$DC$160,"Zinsertraege",$DF$156:$DF$160)+SUMIF($DC$165:$DC$170,"Zinsertraege",$DF$165:$DF$170),2) | DF15: ==IFERROR(ROUND(CY15 + DD15, 2), DD15) | DG15: ==IFERROR(ROUND(CZ15 + DE15, 2), DE15) | DJ15: Zinsertraege | DK15: ==ROUND(SUMIF($DJ$156:$DJ$160,"Zinsertraege",$DL$156:$DL$160)+SUMIF($DJ$165:$DJ$170,"Zinsertraege",$DL$165:$DL$170),2) | DL15: ==ROUND(SUMIF($DJ$156:$DJ$160,"Zinsertraege",$DM$156:$DM$160)+SUMIF($DJ$165:$DJ$170,"Zinsertraege",$DM$165:$DM$170),2) | DM15: ==IFERROR(ROUND(DF15 + DK15, 2), DK15) | DN15: ==IFERROR(ROUND(DG15 + DL15, 2), DL15) | DQ15: Zinsertraege | DR15: ==ROUND(SUMIF($DQ$156:$DQ$160,"Zinsertraege",$DS$156:$DS$160)+SUMIF($DQ$165:$DQ$170,"Zinsertraege",$DS$165:$DS$170),2) | DS15: ==ROUND(SUMIF($DQ$156:$DQ$160,"Zinsertraege",$DT$156:$DT$160)+SUMIF($DQ$165:$DQ$170,"Zinsertraege",$DT$165:$DT$170),2) | DT15: ==IFERROR(ROUND(DM15 + DR15, 2), DR15) | DU15: ==IFERROR(ROUND(DN15 + DS15, 2), DS15)
B16: Gesamteinnahmen | C16: ==ROUND(SUM(C11:C15),2) | D16: ==ROUND(SUM(D11:D15),2) | E16: ==ROUND(SUM(E11:E15),2) | F16: ==ROUND(SUM(F11:F15),2) | I16: Gesamteinnahmen | J16: ==ROUND(SUM(J11:J15),2) | K16: ==ROUND(SUM(K11:K15),2) | L16: ==ROUND(SUM(L11:L15),2) | M16: ==ROUND(SUM(M11:M15),2) | P16: Gesamteinnahmen | Q16: ==ROUND(SUM(Q11:Q15),2) | R16: ==ROUND(SUM(R11:R15),2) | S16: ==ROUND(SUM(S11:S15),2) | T16: ==ROUND(SUM(T11:T15),2) | W16: Gesamteinnahmen | X16: ==ROUND(SUM(X11:X15),2) | Y16: ==ROUND(SUM(Y11:Y15),2) | Z16: ==ROUND(SUM(Z11:Z15),2) | AA16: ==ROUND(SUM(AA11:AA15),2) | AD16: Gesamteinnahmen | AE16: ==ROUND(SUM(AE11:AE15),2) | AF16: ==ROUND(SUM(AF11:AF15),2) | AG16: ==ROUND(SUM(AG11:AG15),2) | AH16: ==ROUND(SUM(AH11:AH15),2) | AK16: Gesamteinnahmen | AL16: ==ROUND(SUM(AL11:AL15),2) | AM16: ==ROUND(SUM(AM11:AM15),2) | AN16: ==ROUND(SUM(AN11:AN15),2) | AO16: ==ROUND(SUM(AO11:AO15),2) | AR16: Gesamteinnahmen | AS16: ==ROUND(SUM(AS11:AS15),2) | AT16: ==ROUND(SUM(AT11:AT15),2) | AU16: ==ROUND(SUM(AU11:AU15),2) | AV16: ==ROUND(SUM(AV11:AV15),2) | AY16: Gesamteinnahmen | AZ16: ==ROUND(SUM(AZ11:AZ15),2) | BA16: ==ROUND(SUM(BA11:BA15),2) | BB16: ==ROUND(SUM(BB11:BB15),2) | BC16: ==ROUND(SUM(BC11:BC15),2) | BF16: Gesamteinnahmen | BG16: ==ROUND(SUM(BG11:BG15),2) | BH16: ==ROUND(SUM(BH11:BH15),2) | BI16: ==ROUND(SUM(BI11:BI15),2) | BJ16: ==ROUND(SUM(BJ11:BJ15),2) | BM16: Gesamteinnahmen | BN16: ==ROUND(SUM(BN11:BN15),2) | BO16: ==ROUND(SUM(BO11:BO15),2) | BP16: ==ROUND(SUM(BP11:BP15),2) | BQ16: ==ROUND(SUM(BQ11:BQ15),2) | BT16: Gesamteinnahmen | BU16: ==ROUND(SUM(BU11:BU15),2) | BV16: ==ROUND(SUM(BV11:BV15),2) | BW16: ==ROUND(SUM(BW11:BW15),2) | BX16: ==ROUND(SUM(BX11:BX15),2) | CA16: Gesamteinnahmen | CB16: ==ROUND(SUM(CB11:CB15),2) | CC16: ==ROUND(SUM(CC11:CC15),2) | CD16: ==ROUND(SUM(CD11:CD15),2) | CE16: ==ROUND(SUM(CE11:CE15),2) | CH16: Gesamteinnahmen | CI16: ==ROUND(SUM(CI11:CI15),2) | CJ16: ==ROUND(SUM(CJ11:CJ15),2) | CK16: ==ROUND(SUM(CK11:CK15),2) | CL16: ==ROUND(SUM(CL11:CL15),2) | CO16: Gesamteinnahmen | CP16: ==ROUND(SUM(CP11:CP15),2) | CQ16: ==ROUND(SUM(CQ11:CQ15),2) | CR16: ==ROUND(SUM(CR11:CR15),2) | CS16: ==ROUND(SUM(CS11:CS15),2) | CV16: Gesamteinnahmen | CW16: ==ROUND(SUM(CW11:CW15),2) | CX16: ==ROUND(SUM(CX11:CX15),2) | CY16: ==ROUND(SUM(CY11:CY15),2) | CZ16: ==ROUND(SUM(CZ11:CZ15),2) | DC16: Gesamteinnahmen | DD16: ==ROUND(SUM(DD11:DD15),2) | DE16: ==ROUND(SUM(DE11:DE15),2) | DF16: ==ROUND(SUM(DF11:DF15),2) | DG16: ==ROUND(SUM(DG11:DG15),2) | DJ16: Gesamteinnahmen | DK16: ==ROUND(SUM(DK11:DK15),2) | DL16: ==ROUND(SUM(DL11:DL15),2) | DM16: ==ROUND(SUM(DM11:DM15),2) | DN16: ==ROUND(SUM(DN11:DN15),2) | DQ16: Gesamteinnahmen | DR16: ==ROUND(SUM(DR11:DR15),2) | DS16: ==ROUND(SUM(DS11:DS15),2) | DT16: ==ROUND(SUM(DT11:DT15),2) | DU16: ==ROUND(SUM(DU11:DU15),2)
B17: Ausgaben | I17: Ausgaben | P17: Ausgaben | W17: Ausgaben | AD17: Ausgaben | AK17: Ausgaben | AR17: Ausgaben | AY17: Ausgaben | BF17: Ausgaben | BM17: Ausgaben | BT17: Ausgaben | CA17: Ausgaben | CH17: Ausgaben | CO17: Ausgaben | CV17: Ausgaben | DC17: Ausgaben | DJ17: Ausgaben | DQ17: Ausgaben
B18: ID | C18: Ausgaben (LC) | D18: Ausgaben (EUR) | E18: Kum. Ausgaben (LC) | F18: Kum. Ausgaben (EUR) | I18: ID | J18: Ausgaben (LC) | K18: Ausgaben (EUR) | L18: Kum. Ausgaben (LC) | M18: Kum. Ausgaben (EUR) | P18: ID | Q18: Ausgaben (LC) | R18: Ausgaben (EUR) | S18: Kum. Ausgaben (LC) | T18: Kum. Ausgaben (EUR) | W18: ID | X18: Ausgaben (LC) | Y18: Ausgaben (EUR) | Z18: Kum. Ausgaben (LC) | AA18: Kum. Ausgaben (EUR) | AD18: ID | AE18: Ausgaben (LC) | AF18: Ausgaben (EUR) | AG18: Kum. Ausgaben (LC) | AH18: Kum. Ausgaben (EUR) | AK18: ID | AL18: Ausgaben (LC) | AM18: Ausgaben (EUR) | AN18: Kum. Ausgaben (LC) | AO18: Kum. Ausgaben (EUR) | AR18: ID | AS18: Ausgaben (LC) | AT18: Ausgaben (EUR) | AU18: Kum. Ausgaben (LC) | AV18: Kum. Ausgaben (EUR) | AY18: ID | AZ18: Ausgaben (LC) | BA18: Ausgaben (EUR) | BB18: Kum. Ausgaben (LC) | BC18: Kum. Ausgaben (EUR) | BF18: ID | BG18: Ausgaben (LC) | BH18: Ausgaben (EUR) | BI18: Kum. Ausgaben (LC) | BJ18: Kum. Ausgaben (EUR) | BM18: ID | BN18: Ausgaben (LC) | BO18: Ausgaben (EUR) | BP18: Kum. Ausgaben (LC) | BQ18: Kum. Ausgaben (EUR) | BT18: ID | BU18: Ausgaben (LC) | BV18: Ausgaben (EUR) | BW18: Kum. Ausgaben (LC) | BX18: Kum. Ausgaben (EUR) | CA18: ID | CB18: Ausgaben (LC) | CC18: Ausgaben (EUR) | CD18: Kum. Ausgaben (LC) | CE18: Kum. Ausgaben (EUR) | CH18: ID | CI18: Ausgaben (LC) | CJ18: Ausgaben (EUR) | CK18: Kum. Ausgaben (LC) | CL18: Kum. Ausgaben (EUR) | CO18: ID | CP18: Ausgaben (LC) | CQ18: Ausgaben (EUR) | CR18: Kum. Ausgaben (LC) | CS18: Kum. Ausgaben (EUR) | CV18: ID | CW18: Ausgaben (LC) | CX18: Ausgaben (EUR) | CY18: Kum. Ausgaben (LC) | CZ18: Kum. Ausgaben (EUR) | DC18: ID | DD18: Ausgaben (LC) | DE18: Ausgaben (EUR) | DF18: Kum. Ausgaben (LC) | DG18: Kum. Ausgaben (EUR) | DJ18: ID | DK18: Ausgaben (LC) | DL18: Ausgaben (EUR) | DM18: Kum. Ausgaben (LC) | DN18: Kum. Ausgaben (EUR) | DQ18: ID | DR18: Ausgaben (LC) | DS18: Ausgaben (EUR) | DT18: Kum. Ausgaben (LC) | DU18: Kum. Ausgaben (EUR)
B19: 1.1 | D19: ==IFERROR(ROUND(C19/FB_Kurs_1,2),0) | E19: ==ROUND(C19,2) | F19: ==ROUND(D19,2) | I19: 1.1 | K19: ==IFERROR(ROUND(J19/FB_Kurs_2,2),0) | L19: ==ROUND(J19+E19,2) | M19: ==ROUND(K19+F19,2) | P19: 1.1 | R19: ==IFERROR(ROUND(Q19/FB_Kurs_3,2),0) | S19: ==ROUND(Q19+L19,2) | T19: ==ROUND(R19+M19,2) | W19: 1.1 | Y19: ==IFERROR(ROUND(X19/FB_Kurs_4,2),0) | Z19: ==ROUND(X19+S19,2) | AA19: ==ROUND(Y19+T19,2) | AD19: 1.1 | AF19: ==IFERROR(ROUND(AE19/FB_Kurs_5,2),0) | AG19: ==ROUND(AE19+Z19,2) | AH19: ==ROUND(AF19+AA19,2) | AK19: 1.1 | AM19: ==IFERROR(ROUND(AL19/FB_Kurs_6,2),0) | AN19: ==ROUND(AL19+AG19,2) | AO19: ==ROUND(AM19+AH19,2) | AR19: 1.1 | AT19: ==IFERROR(ROUND(AS19/FB_Kurs_7,2),0) | AU19: ==ROUND(AS19+AN19,2) | AV19: ==ROUND(AT19+AO19,2) | AY19: 1.1 | BA19: ==IFERROR(ROUND(AZ19/FB_Kurs_8,2),0) | BB19: ==ROUND(AZ19+AU19,2) | BC19: ==ROUND(BA19+AV19,2) | BF19: 1.1 | BH19: ==IFERROR(ROUND(BG19/FB_Kurs_9,2),0) | BI19: ==ROUND(BG19+BB19,2) | BJ19: ==ROUND(BH19+BC19,2) | BM19: 1.1 | BO19: ==IFERROR(ROUND(BN19/FB_Kurs_10,2),0) | BP19: ==ROUND(BN19+BI19,2) | BQ19: ==ROUND(BO19+BJ19,2) | BT19: 1.1 | BV19: ==IFERROR(ROUND(BU19/FB_Kurs_11,2),0) | BW19: ==ROUND(BU19+BP19,2) | BX19: ==ROUND(BV19+BQ19,2) | CA19: 1.1 | CC19: ==IFERROR(ROUND(CB19/FB_Kurs_12,2),0) | CD19: ==ROUND(CB19+BW19,2) | CE19: ==ROUND(CC19+BX19,2) | CH19: 1.1 | CJ19: ==IFERROR(ROUND(CI19/FB_Kurs_13,2),0) | CK19: ==ROUND(CI19+CD19,2) | CL19: ==ROUND(CJ19+CE19,2) | CO19: 1.1 | CQ19: ==IFERROR(ROUND(CP19/FB_Kurs_14,2),0) | CR19: ==ROUND(CP19+CK19,2) | CS19: ==ROUND(CQ19+CL19,2) | CV19: 1.1 | CX19: ==IFERROR(ROUND(CW19/FB_Kurs_15,2),0) | CY19: ==ROUND(CW19+CR19,2) | CZ19: ==ROUND(CX19+CS19,2) | DC19: 1.1 | DE19: ==IFERROR(ROUND(DD19/FB_Kurs_16,2),0) | DF19: ==ROUND(DD19+CY19,2) | DG19: ==ROUND(DE19+CZ19,2) | DJ19: 1.1 | DL19: ==IFERROR(ROUND(DK19/FB_Kurs_17,2),0) | DM19: ==ROUND(DK19+DF19,2) | DN19: ==ROUND(DL19+DG19,2) | DQ19: 1.1 | DS19: ==IFERROR(ROUND(DR19/FB_Kurs_18,2),0) | DT19: ==ROUND(DR19+DM19,2) | DU19: ==ROUND(DS19+DN19,2)
B20: 1.2 | D20: ==IFERROR(ROUND(C20/FB_Kurs_1,2),0) | E20: ==ROUND(C20,2) | F20: ==ROUND(D20,2) | I20: 1.2 | K20: ==IFERROR(ROUND(J20/FB_Kurs_2,2),0) | L20: ==ROUND(J20+E20,2) | M20: ==ROUND(K20+F20,2) | P20: 1.2 | R20: ==IFERROR(ROUND(Q20/FB_Kurs_3,2),0) | S20: ==ROUND(Q20+L20,2) | T20: ==ROUND(R20+M20,2) | W20: 1.2 | Y20: ==IFERROR(ROUND(X20/FB_Kurs_4,2),0) | Z20: ==ROUND(X20+S20,2) | AA20: ==ROUND(Y20+T20,2) | AD20: 1.2 | AF20: ==IFERROR(ROUND(AE20/FB_Kurs_5,2),0) | AG20: ==ROUND(AE20+Z20,2) | AH20: ==ROUND(AF20+AA20,2) | AK20: 1.2 | AM20: ==IFERROR(ROUND(AL20/FB_Kurs_6,2),0) | AN20: ==ROUND(AL20+AG20,2) | AO20: ==ROUND(AM20+AH20,2) | AR20: 1.2 | AT20: ==IFERROR(ROUND(AS20/FB_Kurs_7,2),0) | AU20: ==ROUND(AS20+AN20,2) | AV20: ==ROUND(AT20+AO20,2) | AY20: 1.2 | BA20: ==IFERROR(ROUND(AZ20/FB_Kurs_8,2),0) | BB20: ==ROUND(AZ20+AU20,2) | BC20: ==ROUND(BA20+AV20,2) | BF20: 1.2 | BH20: ==IFERROR(ROUND(BG20/FB_Kurs_9,2),0) | BI20: ==ROUND(BG20+BB20,2) | BJ20: ==ROUND(BH20+BC20,2) | BM20: 1.2 | BO20: ==IFERROR(ROUND(BN20/FB_Kurs_10,2),0) | BP20: ==ROUND(BN20+BI20,2) | BQ20: ==ROUND(BO20+BJ20,2) | BT20: 1.2 | BV20: ==IFERROR(ROUND(BU20/FB_Kurs_11,2),0) | BW20: ==ROUND(BU20+BP20,2) | BX20: ==ROUND(BV20+BQ20,2) | CA20: 1.2 | CC20: ==IFERROR(ROUND(CB20/FB_Kurs_12,2),0) | CD20: ==ROUND(CB20+BW20,2) | CE20: ==ROUND(CC20+BX20,2) | CH20: 1.2 | CJ20: ==IFERROR(ROUND(CI20/FB_Kurs_13,2),0) | CK20: ==ROUND(CI20+CD20,2) | CL20: ==ROUND(CJ20+CE20,2) | CO20: 1.2 | CQ20: ==IFERROR(ROUND(CP20/FB_Kurs_14,2),0) | CR20: ==ROUND(CP20+CK20,2) | CS20: ==ROUND(CQ20+CL20,2) | CV20: 1.2 | CX20: ==IFERROR(ROUND(CW20/FB_Kurs_15,2),0) | CY20: ==ROUND(CW20+CR20,2) | CZ20: ==ROUND(CX20+CS20,2) | DC20: 1.2 | DE20: ==IFERROR(ROUND(DD20/FB_Kurs_16,2),0) | DF20: ==ROUND(DD20+CY20,2) | DG20: ==ROUND(DE20+CZ20,2) | DJ20: 1.2 | DL20: ==IFERROR(ROUND(DK20/FB_Kurs_17,2),0) | DM20: ==ROUND(DK20+DF20,2) | DN20: ==ROUND(DL20+DG20,2) | DQ20: 1.2 | DS20: ==IFERROR(ROUND(DR20/FB_Kurs_18,2),0) | DT20: ==ROUND(DR20+DM20,2) | DU20: ==ROUND(DS20+DN20,2)
B21: 1.3 | D21: ==IFERROR(ROUND(C21/FB_Kurs_1,2),0) | E21: ==ROUND(C21,2) | F21: ==ROUND(D21,2) | I21: 1.3 | K21: ==IFERROR(ROUND(J21/FB_Kurs_2,2),0) | L21: ==ROUND(J21+E21,2) | M21: ==ROUND(K21+F21,2) | P21: 1.3 | R21: ==IFERROR(ROUND(Q21/FB_Kurs_3,2),0) | S21: ==ROUND(Q21+L21,2) | T21: ==ROUND(R21+M21,2) | W21: 1.3 | Y21: ==IFERROR(ROUND(X21/FB_Kurs_4,2),0) | Z21: ==ROUND(X21+S21,2) | AA21: ==ROUND(Y21+T21,2) | AD21: 1.3 | AF21: ==IFERROR(ROUND(AE21/FB_Kurs_5,2),0) | AG21: ==ROUND(AE21+Z21,2) | AH21: ==ROUND(AF21+AA21,2) | AK21: 1.3 | AM21: ==IFERROR(ROUND(AL21/FB_Kurs_6,2),0) | AN21: ==ROUND(AL21+AG21,2) | AO21: ==ROUND(AM21+AH21,2) | AR21: 1.3 | AT21: ==IFERROR(ROUND(AS21/FB_Kurs_7,2),0) | AU21: ==ROUND(AS21+AN21,2) | AV21: ==ROUND(AT21+AO21,2) | AY21: 1.3 | BA21: ==IFERROR(ROUND(AZ21/FB_Kurs_8,2),0) | BB21: ==ROUND(AZ21+AU21,2) | BC21: ==ROUND(BA21+AV21,2) | BF21: 1.3 | BH21: ==IFERROR(ROUND(BG21/FB_Kurs_9,2),0) | BI21: ==ROUND(BG21+BB21,2) | BJ21: ==ROUND(BH21+BC21,2) | BM21: 1.3 | BO21: ==IFERROR(ROUND(BN21/FB_Kurs_10,2),0) | BP21: ==ROUND(BN21+BI21,2) | BQ21: ==ROUND(BO21+BJ21,2) | BT21: 1.3 | BV21: ==IFERROR(ROUND(BU21/FB_Kurs_11,2),0) | BW21: ==ROUND(BU21+BP21,2) | BX21: ==ROUND(BV21+BQ21,2) | CA21: 1.3 | CC21: ==IFERROR(ROUND(CB21/FB_Kurs_12,2),0) | CD21: ==ROUND(CB21+BW21,2) | CE21: ==ROUND(CC21+BX21,2) | CH21: 1.3 | CJ21: ==IFERROR(ROUND(CI21/FB_Kurs_13,2),0) | CK21: ==ROUND(CI21+CD21,2) | CL21: ==ROUND(CJ21+CE21,2) | CO21: 1.3 | CQ21: ==IFERROR(ROUND(CP21/FB_Kurs_14,2),0) | CR21: ==ROUND(CP21+CK21,2) | CS21: ==ROUND(CQ21+CL21,2) | CV21: 1.3 | CX21: ==IFERROR(ROUND(CW21/FB_Kurs_15,2),0) | CY21: ==ROUND(CW21+CR21,2) | CZ21: ==ROUND(CX21+CS21,2) | DC21: 1.3 | DE21: ==IFERROR(ROUND(DD21/FB_Kurs_16,2),0) | DF21: ==ROUND(DD21+CY21,2) | DG21: ==ROUND(DE21+CZ21,2) | DJ21: 1.3 | DL21: ==IFERROR(ROUND(DK21/FB_Kurs_17,2),0) | DM21: ==ROUND(DK21+DF21,2) | DN21: ==ROUND(DL21+DG21,2) | DQ21: 1.3 | DS21: ==IFERROR(ROUND(DR21/FB_Kurs_18,2),0) | DT21: ==ROUND(DR21+DM21,2) | DU21: ==ROUND(DS21+DN21,2)
B22: 1.4 | D22: ==IFERROR(ROUND(C22/FB_Kurs_1,2),0) | E22: ==ROUND(C22,2) | F22: ==ROUND(D22,2) | I22: 1.4 | K22: ==IFERROR(ROUND(J22/FB_Kurs_2,2),0) | L22: ==ROUND(J22+E22,2) | M22: ==ROUND(K22+F22,2) | P22: 1.4 | R22: ==IFERROR(ROUND(Q22/FB_Kurs_3,2),0) | S22: ==ROUND(Q22+L22,2) | T22: ==ROUND(R22+M22,2) | W22: 1.4 | Y22: ==IFERROR(ROUND(X22/FB_Kurs_4,2),0) | Z22: ==ROUND(X22+S22,2) | AA22: ==ROUND(Y22+T22,2) | AD22: 1.4 | AF22: ==IFERROR(ROUND(AE22/FB_Kurs_5,2),0) | AG22: ==ROUND(AE22+Z22,2) | AH22: ==ROUND(AF22+AA22,2) | AK22: 1.4 | AM22: ==IFERROR(ROUND(AL22/FB_Kurs_6,2),0) | AN22: ==ROUND(AL22+AG22,2) | AO22: ==ROUND(AM22+AH22,2) | AR22: 1.4 | AT22: ==IFERROR(ROUND(AS22/FB_Kurs_7,2),0) | AU22: ==ROUND(AS22+AN22,2) | AV22: ==ROUND(AT22+AO22,2) | AY22: 1.4 | BA22: ==IFERROR(ROUND(AZ22/FB_Kurs_8,2),0) | BB22: ==ROUND(AZ22+AU22,2) | BC22: ==ROUND(BA22+AV22,2) | BF22: 1.4 | BH22: ==IFERROR(ROUND(BG22/FB_Kurs_9,2),0) | BI22: ==ROUND(BG22+BB22,2) | BJ22: ==ROUND(BH22+BC22,2) | BM22: 1.4 | BO22: ==IFERROR(ROUND(BN22/FB_Kurs_10,2),0) | BP22: ==ROUND(BN22+BI22,2) | BQ22: ==ROUND(BO22+BJ22,2) | BT22: 1.4 | BV22: ==IFERROR(ROUND(BU22/FB_Kurs_11,2),0) | BW22: ==ROUND(BU22+BP22,2) | BX22: ==ROUND(BV22+BQ22,2) | CA22: 1.4 | CC22: ==IFERROR(ROUND(CB22/FB_Kurs_12,2),0) | CD22: ==ROUND(CB22+BW22,2) | CE22: ==ROUND(CC22+BX22,2) | CH22: 1.4 | CJ22: ==IFERROR(ROUND(CI22/FB_Kurs_13,2),0) | CK22: ==ROUND(CI22+CD22,2) | CL22: ==ROUND(CJ22+CE22,2) | CO22: 1.4 | CQ22: ==IFERROR(ROUND(CP22/FB_Kurs_14,2),0) | CR22: ==ROUND(CP22+CK22,2) | CS22: ==ROUND(CQ22+CL22,2) | CV22: 1.4 | CX22: ==IFERROR(ROUND(CW22/FB_Kurs_15,2),0) | CY22: ==ROUND(CW22+CR22,2) | CZ22: ==ROUND(CX22+CS22,2) | DC22: 1.4 | DE22: ==IFERROR(ROUND(DD22/FB_Kurs_16,2),0) | DF22: ==ROUND(DD22+CY22,2) | DG22: ==ROUND(DE22+CZ22,2) | DJ22: 1.4 | DL22: ==IFERROR(ROUND(DK22/FB_Kurs_17,2),0) | DM22: ==ROUND(DK22+DF22,2) | DN22: ==ROUND(DL22+DG22,2) | DQ22: 1.4 | DS22: ==IFERROR(ROUND(DR22/FB_Kurs_18,2),0) | DT22: ==ROUND(DR22+DM22,2) | DU22: ==ROUND(DS22+DN22,2)
