Workbook
Name Saldovortrag_LW: Dashboard!$C$14
Name Saldovortrag_EUR: Dashboard!$E$14
Name Budget_Kurs: 'I. Budget'!$H$4
Name Eigenmittel_LW: 'I. Budget'!$E$7
Name Eigenmittel_EUR: 'I. Budget'!$I$7
Name Drittmittel_LW: 'I. Budget'!$E$10
Name Drittmittel_EUR: 'I. Budget'!$I$10
Name KMW_Mittel_LW: 'I. Budget'!$E$13
Name KMW_Mittel_EUR: 'I. Budget'!$I$13
Name Gesamtprojektmittel_LW: 'I. Budget'!$E$15
Name Gesamtprojektmittel_EUR: 'I. Budget'!$I$15
Name Kosten_Bauausgaben_LW: 'I. Budget'!$O$4
Name Kosten_Bauausgaben_EUR: 'I. Budget'!$P$4
Name Kosten_Investitionen_LW: 'I. Budget'!$O$5
Name Kosten_Investitionen_EUR: 'I. Budget'!$P$5
Name Kosten_Personalkosten_LW: 'I. Budget'!$O$6
Name Kosten_Personalkosten_EUR: 'I. Budget'!$P$6
Name Kosten_Projektaktivitaeten_LW: 'I. Budget'!$O$7
Name Kosten_Projektaktivitaeten_EUR: 'I. Budget'!$P$7
Name Kosten_Projektverwaltung_LW: 'I. Budget'!$O$8
Name Kosten_Projektverwaltung_EUR: 'I. Budget'!$P$8
Name Kosten_Evaluierung_LW: 'I. Budget'!$O$9
Name Kosten_Evaluierung_EUR: 'I. Budget'!$P$9
Name Kosten_Audit_LW: 'I. Budget'!$O$10
Name Kosten_Audit_EUR: 'I. Budget'!$P$10
Name Kosten_Reserve_LW: 'I. Budget'!$O$11
Name Kosten_Reserve_EUR: 'I. Budget'!$P$11
Name Gesamtausgaben_LW: 'I. Budget'!$O$12
Name Gesamtausgaben_EUR: 'I. Budget'!$P$12
Name Budget_ID_Liste: OFFSET('I. Budget'!$S$1,0,0,COUNTA('I. Budget'!S:S),1)
Name Geber_Liste: OFFSET('I. Budget'!$K$19,0,0,MAX(1,COUNTA('I. Budget'!$K$19:$K$19)),1)
Name Reserve_Freigabe: 'I. Budget'!$K$5
Name FB_Kurs_1: 'III. Finanzberichte'!$C$8
Name FB_SaldoLC_1: 'III. Finanzberichte'!$C$104
Name FB_SaldoEUR_1: 'III. Finanzberichte'!$D$104
Name FB_Kurs_2: 'III. Finanzberichte'!$J$8
Name FB_SaldoLC_2: 'III. Finanzberichte'!$J$104
Name FB_SaldoEUR_2: 'III. Finanzberichte'!$K$104
Name FB_Kurs_3: 'III. Finanzberichte'!$Q$8
Name FB_SaldoLC_3: 'III. Finanzberichte'!$Q$104
Name FB_SaldoEUR_3: 'III. Finanzberichte'!$R$104
Name FB_Kurs_4: 'III. Finanzberichte'!$X$8
Name FB_SaldoLC_4: 'III. Finanzberichte'!$X$104
Name FB_SaldoEUR_4: 'III. Finanzberichte'!$Y$104
Name FB_Kurs_5: 'III. Finanzberichte'!$AE$8
Name FB_SaldoLC_5: 'III. Finanzberichte'!$AE$104
Name FB_SaldoEUR_5: 'III. Finanzberichte'!$AF$104
Name FB_Kurs_6: 'III. Finanzberichte'!$AL$8
Name FB_SaldoLC_6: 'III. Finanzberichte'!$AL$104
Name FB_SaldoEUR_6: 'III. Finanzberichte'!$AM$104
Name FB_Kurs_7: 'III. Finanzberichte'!$AS$8
Name FB_SaldoLC_7: 'III. Finanzberichte'!$AS$104
Name FB_SaldoEUR_7: 'III. Finanzberichte'!$AT$104
Name FB_Kurs_8: 'III. Finanzberichte'!$AZ$8
Name FB_SaldoLC_8: 'III. Finanzberichte'!$AZ$104
Name FB_SaldoEUR_8: 'III. Finanzberichte'!$BA$104
Name FB_Kurs_9: 'III. Finanzberichte'!$BG$8
Name FB_SaldoLC_9: 'III. Finanzberichte'!$BG$104
Name FB_SaldoEUR_9: 'III. Finanzberichte'!$BH$104
Name FB_Kurs_10: 'III. Finanzberichte'!$BN$8

Sheet Dashboard
AA1: AED
B2: DASHBOARD (v1.0) | AA2: AFN
AA3: ALL
B4: Statische Projektinformationen | AA4: AMD
B5: Projektnummer | D5: Vorprojekt vorhanden | E5: Ja | AA5: AOA
B6: Projekttitel | AA6: ARS
B7: Projekttraeger | D7: Berichtswaehrung | AA7: AUD
B8: Projektstart | D8: Projektende | AA8: AWG
B9: Projektlaufzeit (geplant) | C9: =IF(AND(ISNUMBER($C$8),ISNUMBER($E$8)),TEXT(DAY($C$8),"00")&"."&TEXT(MONTH($C$8),"00")&"."&TEXT(YEAR($C$8),"0000")&" - "&TEXT(DAY($E$8),"00")&"."&TEXT(MONTH($E$8),"00")&"."&TEXT(YEAR($E$8),"0000"),"") | D9: In Monate | E9: =IF(AND(ISNUMBER($C$8),ISNUMBER($E$8)),DATEDIF($C$8,$E$8+1,"M"),"") | AA9: AZN
B10: Vorprojektnummer | D10: VP-Berichtswaehrung | AA10: BAM
B11: Vorprojektende | D11: Wechselkurs | AA11: BBD
B12: Saldo (LW) | D12: Saldo (EUR) | E12: =IFERROR(ROUND($C$12/$E$11,2),0) -> 0 | AA12: BDT
B13: Folgeprojektstart | D13: Wechselkurs | AA13: BHD
B14: Saldovortrag (LW) | D14: Saldovortrag (EUR) | E14: =IFERROR(ROUND($C$14/$E$13,2),0) -> 0 | AA14: BIF
AA15: BMD
B16: Folgende Dokumente liegen vor: | D16: Nein | E16: Vorprojektsaldo (Nachweis) | AA16: BND
D17: Nein | E17: Vertrag | AA17: BOB
D18: Nein | E18: Budget | AA18: BRL
D19: Nein | E19: Bankbelege | AA19: BSD
D20: Nein | E20: Finanzbericht(e) | AA20: BTN
D21: Nein | E21: Einzelbelege und Beleglisten | AA21: BWP
D22: Nein | E22: Narrativer Bericht | AA22: BYN
AA23: BZD
AA24: CAD
AA25: CDF
AA26: CHF
AA27: CLP
AA28: CNY
AA29: COP
AA30: CRC
AA31: CUP
AA32: CVE
AA33: CZK
AA34: DJF
... AA155: ZWG

Sheet I. Budget
S1: {=IFERROR(_xlfn._xlws.FILTER(TblBudgetAusgaben[ID],TblBudgetAusgaben[ID]<>""),"")} -> 0
B2: I. KERNDATEN BUDGET | K2: Reserve Freigabe
K3: =$P$11 -> 39500
B4: 1. GEPLANTE EINNAHMEN / FINANZIERUNG | G4: € Budget-Kurs: | H4: =IFERROR($E$15/$I$15,0) -> 2 | K4: Reserve freigeben: | O4: =SUMIFS(TblBudgetAusgaben[Betrag (LC)],TblBudgetAusgaben[Kostenkategorie],"Bauausgaben") -> 390000 | P4: =SUMIFS(TblBudgetAusgaben[Betrag (EUR)],TblBudgetAusgaben[Kostenkategorie],"Bauausgaben") -> 195000
B5: Finanzierungsquelle | E5: Betrag (LC) | F5: Jahr 1 | G5: Jahr 2 | H5: Jahr 3 | I5: Betrag (EUR) | K5: Nein | O5: =SUMIFS(TblBudgetAusgaben[Betrag (LC)],TblBudgetAusgaben[Kostenkategorie],"Investitionen") -> 390000 | P5: =SUMIFS(TblBudgetAusgaben[Betrag (EUR)],TblBudgetAusgaben[Kostenkategorie],"Investitionen") -> 195000
B6: 1.1 Eigenmittel | K6: =IF($K$5="Ja","FREIGEGEBEN","NICHT FREIGEGEBEN") -> NICHT FREIGEGEBEN | O6: =SUMIFS(TblBudgetAusgaben[Betrag (LC)],TblBudgetAusgaben[Kostenkategorie],"Personalkosten") -> 0 | P6: =SUMIFS(TblBudgetAusgaben[Betrag (EUR)],TblBudgetAusgaben[Kostenkategorie],"Personalkosten") -> 0
B7: Eigenmittel | E7: 40000 | F7: 40000 | I7: 20000 | O7: =SUMIFS(TblBudgetAusgaben[Betrag (LC)],TblBudgetAusgaben[Kostenkategorie],"Projektaktivitaeten") -> 390000 | P7: =SUMIFS(TblBudgetAusgaben[Betrag (EUR)],TblBudgetAusgaben[Kostenkategorie],"Projektaktivitaeten") -> 195000
K8: Begruendung | O8: =SUMIFS(TblBudgetAusgaben[Betrag (LC)],TblBudgetAusgaben[Kostenkategorie],"Projektverwaltung") -> 390000 | P8: =SUMIFS(TblBudgetAusgaben[Betrag (EUR)],TblBudgetAusgaben[Kostenkategorie],"Projektverwaltung") -> 195000
B9: 1.2 Drittmittel | O9: =SUMIFS(TblBudgetAusgaben[Betrag (LC)],TblBudgetAusgaben[Kostenkategorie],"Evaluierung") -> 10000 | P9: =SUMIFS(TblBudgetAusgaben[Betrag (EUR)],TblBudgetAusgaben[Kostenkategorie],"Evaluierung") -> 5000
B10: Drittmittel (Summe): | D10: Aufstellung je Geber → Tabelle rechts | E10: =SUM(TblDrittmittel[Betrag (LC)]) -> 30000 | F10: 30000 | I10: =SUM(TblDrittmittel[Betrag (EUR)]) -> 15000 | O10: =SUMIFS(TblBudgetAusgaben[Betrag (LC)],TblBudgetAusgaben[Kostenkategorie],"Audit") -> 10000 | P10: =SUMIFS(TblBudgetAusgaben[Betrag (EUR)],TblBudgetAusgaben[Kostenkategorie],"Audit") -> 5000
O11: =SUMIFS(TblBudgetAusgaben[Betrag (LC)],TblBudgetAusgaben[Kostenkategorie],"Reserve") -> 79000 | P11: =SUMIFS(TblBudgetAusgaben[Betrag (EUR)],TblBudgetAusgaben[Kostenkategorie],"Reserve") -> 39500
B12: 1.3 KMW-Mittel | O12: =SUBTOTAL(109,TblBudgetAusgaben[Betrag (LC)]) -> 1659000 | P12: =SUBTOTAL(109,TblBudgetAusgaben[Betrag (EUR)]) -> 829500
B13: KMW-Mittel | E13: 1589000 | F13: 1589000 | G13: 0 | H13: 0 | I13: 794500
B15: GESAMTPROJEKTMITTEL | E15: =E7+E10+E13 -> 1659000 | F15: =F7+F10+F13 -> 1659000 | G15: =G7+G10+G13 -> 0 | H15: =H7+H10+H13 -> 0 | I15: =I7+I10+I13 -> 829500
B17: 2. GEPLANTE AUSGABEN | K17: Drittmittel – Aufstellung je Geber
B18: Kostenkategorie | C18: ID | D18: Kostenposition | E18: Betrag (LC) | F18: Jahr 1 | G18: Jahr 2 | H18: Jahr 3 | I18: Betrag (EUR) | K18: Name des Gebers | L18: Betrag (LC) | M18: Betrag (EUR)
B19: Bauausgaben | C19: 1.1 | D19: Hallo1 | E19: 10000 | F19: 10000 | I19: 5000 | K19: Sonstige | L19: 30000 | M19: 15000
B20: Bauausgaben | C20: 1.2 | D20: Hallo2 | E20: 11000 | F20: 11000 | I20: 5500
B21: Bauausgaben | C21: 1.3 | D21: Hallo3 | E21: 12000 | F21: 12000 | I21: 6000
B22: Bauausgaben | C22: 1.4 | D22: Hallo4 | E22: 13000 | F22: 13000 | I22: 6500
B23: Bauausgaben | C23: 1.5 | D23: Hallo5 | E23: 14000 | F23: 14000 | I23: 7000
B24: Bauausgaben | C24: 1.6 | D24: Hallo6 | E24: 15000 | F24: 15000 | I24: 7500
B25: Bauausgaben | C25: 1.7 | D25: Hallo7 | E25: 16000 | F25: 16000 | I25: 8000
B26: Bauausgaben | C26: 1.8 | D26: Hallo8 | E26: 17000 | F26: 17000 | I26: 8500
B27: Bauausgaben | C27: 1.9 | D27: Hallo9 | E27: 18000 | F27: 18000 | I27: 9000
B28: Bauausgaben | C28: 1.10 | D28: Hallo10 | E28: 19000 | F28: 19000 | I28: 9500
B29: Bauausgaben | C29: 1.11 | D29: Hallo11 | E29: 20000 | F29: 20000 | I29: 10000
B30: Bauausgaben | C30: 1.12 | D30: Hallo12 | E30: 21000 | F30: 21000 | I30: 10500
B31: Bauausgaben | C31: 1.13 | D31: Hallo13 | E31: 22000 | F31: 22000 | I31: 11000
... B100: Audit | C100: 7. | D100: Audit | E100: 10000 | F100: 10000 | I100: 5000
B101: Reserve | C101: 8. | D101: Reserve - nur nach Genehmigung | E101: 79000 | F101: 79000 | G101: 0 | H101: 0 | I101: 39500
B102: Geplante Gesamtausgaben | E102: =SUBTOTAL(109,TblBudgetAusgaben[Betrag (LC)]) -> 1659000 | F102: =SUBTOTAL(109,TblBudgetAusgaben[Jahr 1]) -> 1659000 | G102: =SUBTOTAL(109,TblBudgetAusgaben[Jahr 2]) -> 0 | H102: =SUBTOTAL(109,TblBudgetAusgaben[Jahr 3]) -> 0 | I102: =SUBTOTAL(109,TblBudgetAusgaben[Betrag (EUR)]) -> 829500
B104: Budgetpruefung
B105: Einnahmen = Ausgaben (LC) | E105: =IF(ROUND($E$15-$O$12,2)=0,"OK","Abweichung") -> OK
B106: Einnahmen = Ausgaben (EUR) | E106: =IF(ROUND($I$15-$P$12,2)=0,"OK","Abweichung") -> OK
B107: Gleicher Budget-Kurs | E107: =IF(ROUND($H$4,4)=ROUND(IFERROR($O$12/$P$12,0),4),"OK","Abweichung") -> OK
B108: Einnahmen: Jahre = Gesamt (LC) | E108: =IF(ROUND(($F$15+$G$15+$H$15)-$E$15,2)=0,"OK","Abweichung") -> OK
B109: Ausgaben: Jahre = Gesamt (LC) | E109: =IF(ROUND(($F$102+$G$102+$H$102)-$O$12,2)=0,"OK","Abweichung") -> OK

Sheet II. KMW-Mittel
Z1: Periode 1
B2: II. KMW-MITTEL BEREITGESTELLT | Z2: Periode 2
Z3: Periode 3
B4: Periode | C4: Waehrung | D4: Betrag | E4: Datum | Z4: Periode 4
Z5: Periode 5
Z6: Periode 6
Z7: Periode 7
Z8: Periode 8
Z9: Periode 9
Z10: Periode 10
Z11: Periode 11
Z12: Periode 12
Z13: Periode 13
Z14: Periode 14
Z15: Periode 15
Z16: Periode 16
... Z22: Periode 22
B23: GESAMT | D23: =SUBTOTAL(109,TblKMWMittel[Betrag]) -> 0 | Z23: Periode 23
Z24: Periode 24
Z25: Periode 25
Z26: Periode 26
Z27: Periode 27
Z28: Periode 28
Z29: Periode 29
Z30: Periode 30
Z31: Periode 31
Z32: Periode 32
Z33: Periode 33
Z34: Periode 34
Z35: Periode 35
Z36: Periode 36

Sheet III. Finanzberichte
H3: ➤ | O3: ➤ | V3: ➤ | AC3: ➤ | AJ3: ➤ | AQ3: ➤ | AX3: ➤ | BE3: ➤ | BL3: ➤ | BS3: ➤ | BZ3: ➤ | CG3: ➤ | CN3: ➤ | CU3: ➤ | DB3: ➤ | DI3: ➤ | DP3: ➤
B4: Periode: | C4: Periode 1 | I4: Periode: | J4: Periode 2 | P4: Periode: | Q4: Periode 3 | W4: Periode: | X4: Periode 4 | AD4: Periode: | AE4: Periode 5 | AK4: Periode: | AL4: Periode 6 | AR4: Periode: | AS4: Periode 7 | AY4: Periode: | AZ4: Periode 8 | BF4: Periode: | BG4: Periode 9 | BM4: Periode: | BN4: Periode 10 | BT4: Periode: | BU4: Periode 11 | CA4: Periode: | CB4: Periode 12 | CH4: Periode: | CI4: Periode 13 | CO4: Periode: | CP4: Periode 14 | CV4: Periode: | CW4: Periode 15 | DC4: Periode: | DD4: Periode 16 | DJ4: Periode: | DK4: Periode 17 | DQ4: Periode: | DR4: Periode 18
B5: Von: | I5: Von: | P5: Von: | W5: Von: | AD5: Von: | AK5: Von: | AR5: Von: | AY5: Von: | BF5: Von: | BM5: Von: | BT5: Von: | CA5: Von: | CH5: Von: | CO5: Von: | CV5: Von: | DC5: Von: | DJ5: Von: | DQ5: Von:
B6: Bis: | I6: Bis: | P6: Bis: | W6: Bis: | AD6: Bis: | AK6: Bis: | AR6: Bis: | AY6: Bis: | BF6: Bis: | BM6: Bis: | BT6: Bis: | CA6: Bis: | CH6: Bis: | CO6: Bis: | CV6: Bis: | DC6: Bis: | DJ6: Bis: | DQ6: Bis:
B7: Zeitraum: | C7: =IF(OR(C5="",C6=""),"",DATEDIF(C5,C6,"m")+1) -> 158 | I7: Zeitraum: | J7: =IF(OR(J5="",J6=""),"",DATEDIF(J5,J6,"m")+1) -> 158 | P7: Zeitraum: | Q7: =IF(OR(Q5="",Q6=""),"",DATEDIF(Q5,Q6,"m")+1) -> 158 | W7: Zeitraum: | X7: =IF(OR(X5="",X6=""),"",DATEDIF(X5,X6,"m")+1) -> 158 | AD7: Zeitraum: | AE7: =IF(OR(AE5="",AE6=""),"",DATEDIF(AE5,AE6,"m")+1) -> 158 | AK7: Zeitraum: | AL7: =IF(OR(AL5="",AL6=""),"",DATEDIF(AL5,AL6,"m")+1) -> 158 | AR7: Zeitraum: | AS7: =IF(OR(AS5="",AS6=""),"",DATEDIF(AS5,AS6,"m")+1) -> 158 | AY7: Zeitraum: | AZ7: =IF(OR(AZ5="",AZ6=""),"",DATEDIF(AZ5,AZ6,"m")+1) -> 158 | BF7: Zeitraum: | BG7: =IF(OR(BG5="",BG6=""),"",DATEDIF(BG5,BG6,"m")+1) -> 158 | BM7: Zeitraum: | BN7: =IF(OR(BN5="",BN6=""),"",DATEDIF(BN5,BN6,"m")+1) -> 158 | BT7: Zeitraum: | BU7: =IF(OR(BU5="",BU6=""),"",DATEDIF(BU5,BU6,"m")+1) -> 158 | CA7: Zeitraum: | CB7: =IF(OR(CB5="",CB6=""),"",DATEDIF(CB5,CB6,"m")+1) -> 158 | CH7: Zeitraum: | CI7: =IF(OR(CI5="",CI6=""),"",DATEDIF(CI5,CI6,"m")+1) -> 158 | CO7: Zeitraum: | CP7: =IF(OR(CP5="",CP6=""),"",DATEDIF(CP5,CP6,"m")+1) -> 158 | CV7: Zeitraum: | CW7: =IF(OR(CW5="",CW6=""),"",DATEDIF(CW5,CW6,"m")+1) -> 158 | DC7: Zeitraum: | DD7: =IF(OR(DD5="",DD6=""),"",DATEDIF(DD5,DD6,"m")+1) -> 158 | DJ7: Zeitraum: | DK7: =IF(OR(DK5="",DK6=""),"",DATEDIF(DK5,DK6,"m")+1) -> 158 | DQ7: Zeitraum: | DR7: =IF(OR(DR5="",DR6=""),"",DATEDIF(DR5,DR6,"m")+1) -> 158
B8: Durchschnittskurs: | C8: =ROUND(IFERROR(F121,0),6) -> 0 | I8: Durchschnittskurs: | J8: =ROUND(IFERROR(M121,0),6) -> 0 | P8: Durchschnittskurs: | Q8: =ROUND(IFERROR(T121,0),6) -> 0 | W8: Durchschnittskurs: | X8: =ROUND(IFERROR(AA121,0),6) -> 0 | AD8: Durchschnittskurs: | AE8: =ROUND(IFERROR(AH121,0),6) -> 0 | AK8: Durchschnittskurs: | AL8: =ROUND(IFERROR(AO121,0),6) -> 0 | AR8: Durchschnittskurs: | AS8: =ROUND(IFERROR(AV121,0),6) -> 0 | AY8: Durchschnittskurs: | AZ8: =ROUND(IFERROR(BC121,0),6) -> 0 | BF8: Durchschnittskurs: | BG8: =ROUND(IFERROR(BJ121,0),6) -> 0 | BM8: Durchschnittskurs: | BN8: =ROUND(IFERROR(BQ121,0),6) -> 0 | BT8: Durchschnittskurs: | BU8: =ROUND(IFERROR(BX121,0),6) -> 0 | CA8: Durchschnittskurs: | CB8: =ROUND(IFERROR(CE121,0),6) -> 0 | CH8: Durchschnittskurs: | CI8: =ROUND(IFERROR(CL121,0),6) -> 0 | CO8: Durchschnittskurs: | CP8: =ROUND(IFERROR(CS121,0),6) -> 0 | CV8: Durchschnittskurs: | CW8: =ROUND(IFERROR(CZ121,0),6) -> 0 | DC8: Durchschnittskurs: | DD8: =ROUND(IFERROR(DG121,0),6) -> 0 | DJ8: Durchschnittskurs: | DK8: =ROUND(IFERROR(DN121,0),6) -> 0 | DQ8: Durchschnittskurs: | DR8: =ROUND(IFERROR(DU121,0),6) -> 0
B9: Einnahmen | I9: Einnahmen | P9: Einnahmen | W9: Einnahmen | AD9: Einnahmen | AK9: Einnahmen | AR9: Einnahmen | AY9: Einnahmen | BF9: Einnahmen | BM9: Einnahmen | BT9: Einnahmen | CA9: Einnahmen | CH9: Einnahmen | CO9: Einnahmen | CV9: Einnahmen | DC9: Einnahmen | DJ9: Einnahmen | DQ9: Einnahmen
B10: Typ / ID | C10: Einnahmen (LC) | D10: Einnahmen (EUR) | E10: Kum. Einnahmen (LC) | F10: Kum. Einnahmen (EUR) | I10: Typ / ID | J10: Einnahmen (LC) | K10: Einnahmen (EUR) | L10: Kum. Einnahmen (LC) | M10: Kum. Einnahmen (EUR) | P10: Typ / ID | Q10: Einnahmen (LC) | R10: Einnahmen (EUR) | S10: Kum. Einnahmen (LC) | T10: Kum. Einnahmen (EUR) | W10: Typ / ID | X10: Einnahmen (LC) | Y10: Einnahmen (EUR) | Z10: Kum. Einnahmen (LC) | AA10: Kum. Einnahmen (EUR) | AD10: Typ / ID | AE10: Einnahmen (LC) | AF10: Einnahmen (EUR) | AG10: Kum. Einnahmen (LC) | AH10: Kum. Einnahmen (EUR) | AK10: Typ / ID | AL10: Einnahmen (LC) | AM10: Einnahmen (EUR) | AN10: Kum. Einnahmen (LC) | AO10: Kum. Einnahmen (EUR) | AR10: Typ / ID | AS10: Einnahmen (LC) | AT10: Einnahmen (EUR) | AU10: Kum. Einnahmen (LC) | AV10: Kum. Einnahmen (EUR) | AY10: Typ / ID | AZ10: Einnahmen (LC) | BA10: Einnahmen (EUR) | BB10: Kum. Einnahmen (LC) | BC10: Kum. Einnahmen (EUR) | BF10: Typ / ID | BG10: Einnahmen (LC) | BH10: Einnahmen (EUR) | BI10: Kum. Einnahmen (LC) | BJ10: Kum. Einnahmen (EUR) | BM10: Typ / ID | BN10: Einnahmen (LC) | BO10: Einnahmen (EUR) | BP10: Kum. Einnahmen (LC) | BQ10: Kum. Einnahmen (EUR) | BT10: Typ / ID | BU10: Einnahmen (LC) | BV10: Einnahmen (EUR) | BW10: Kum. Einnahmen (LC) | BX10: Kum. Einnahmen (EUR) | CA10: Typ / ID | CB10: Einnahmen (LC) | CC10: Einnahmen (EUR) | CD10: Kum. Einnahmen (LC) | CE10: Kum. Einnahmen (EUR) | CH10: Typ / ID | CI10: Einnahmen (LC) | CJ10: Einnahmen (EUR) | CK10: Kum. Einnahmen (LC) | CL10: Kum. Einnahmen (EUR) | CO10: Typ / ID | CP10: Einnahmen (LC) | CQ10: Einnahmen (EUR) | CR10: Kum. Einnahmen (LC) | CS10: Kum. Einnahmen (EUR) | CV10: Typ / ID | CW10: Einnahmen (LC) | CX10: Einnahmen (EUR) | CY10: Kum. Einnahmen (LC) | CZ10: Kum. Einnahmen (EUR) | DC10: Typ / ID | DD10: Einnahmen (LC) | DE10: Einnahmen (EUR) | DF10: Kum. Einnahmen (LC) | DG10: Kum. Einnahmen (EUR) | DJ10: Typ / ID | DK10: Einnahmen (LC) | DL10: Einnahmen (EUR) | DM10: Kum. Einnahmen (LC) | DN10: Kum. Einnahmen (EUR) | DQ10: Typ / ID | DR10: Einnahmen (LC) | DS10: Einnahmen (EUR) | DT10: Kum. Einnahmen (LC) | DU10: Kum. Einnahmen (EUR)
B11: Vorprojektsaldo | C11: =ROUND(IF(Saldovortrag_LW="",0,Saldovortrag_LW),2) -> 0 | D11: =ROUND(IF(Saldovortrag_EUR="",0,Saldovortrag_EUR),2) -> 0 | E11: =ROUND(IF(Saldovortrag_LW="",0,Saldovortrag_LW),2) -> 0 | F11: =ROUND(IF(Saldovortrag_EUR="",0,Saldovortrag_EUR),2) -> 0 | I11: Vorperiodensaldo | J11: =ROUND(FB_SaldoLC_1,2) -> 0 | K11: =ROUND(FB_SaldoEUR_1,2) -> 0 | L11: =ROUND(FB_SaldoLC_1,2) -> 0 | M11: =ROUND(FB_SaldoEUR_1,2) -> 0 | P11: Vorperiodensaldo | Q11: =ROUND(FB_SaldoLC_2,2) -> 0 | R11: =ROUND(FB_SaldoEUR_2,2) -> 0 | S11: =ROUND(FB_SaldoLC_2,2) -> 0 | T11: =ROUND(FB_SaldoEUR_2,2) -> 0 | W11: Vorperiodensaldo | X11: =ROUND(FB_SaldoLC_3,2) -> 0 | Y11: =ROUND(FB_SaldoEUR_3,2) -> 0 | Z11: =ROUND(FB_SaldoLC_3,2) -> 0 | AA11: =ROUND(FB_SaldoEUR_3,2) -> 0 | AD11: Vorperiodensaldo | AE11: =ROUND(FB_SaldoLC_4,2) -> 0 | AF11: =ROUND(FB_SaldoEUR_4,2) -> 0 | AG11: =ROUND(FB_SaldoLC_4,2) -> 0 | AH11: =ROUND(FB_SaldoEUR_4,2) -> 0 | AK11: Vorperiodensaldo | AL11: =ROUND(FB_SaldoLC_5,2) -> 0 | AM11: =ROUND(FB_SaldoEUR_5,2) -> 0 | AN11: =ROUND(FB_SaldoLC_5,2) -> 0 | AO11: =ROUND(FB_SaldoEUR_5,2) -> 0 | AR11: Vorperiodensaldo | AS11: =ROUND(FB_SaldoLC_6,2) -> 0 | AT11: =ROUND(FB_SaldoEUR_6,2) -> 0 | AU11: =ROUND(FB_SaldoLC_6,2) -> 0 | AV11: =ROUND(FB_SaldoEUR_6,2) -> 0 | AY11: Vorperiodensaldo | AZ11: =ROUND(FB_SaldoLC_7,2) -> 0 | BA11: =ROUND(FB_SaldoEUR_7,2) -> 0 | BB11: =ROUND(FB_SaldoLC_7,2) -> 0 | BC11: =ROUND(FB_SaldoEUR_7,2) -> 0 | BF11: Vorperiodensaldo | BG11: =ROUND(FB_SaldoLC_8,2) -> 0 | BH11: =ROUND(FB_SaldoEUR_8,2) -> 0 | BI11: =ROUND(FB_SaldoLC_8,2) -> 0 | BJ11: =ROUND(FB_SaldoEUR_8,2) -> 0 | BM11: Vorperiodensaldo | BN11: =ROUND(FB_SaldoLC_9,2) -> 0 | BO11: =ROUND(FB_SaldoEUR_9,2) -> 0 | BP11: =ROUND(FB_SaldoLC_9,2) -> 0 | BQ11: =ROUND(FB_SaldoEUR_9,2) -> 0 | BT11: Vorperiodensaldo | BU11: =ROUND(FB_SaldoLC_10,2) -> 0 | BV11: =ROUND(FB_SaldoEUR_10,2) -> 0 | BW11: =ROUND(FB_SaldoLC_10,2) -> 0 | BX11: =ROUND(FB_SaldoEUR_10,2) -> 0 | CA11: Vorperiodensaldo | CB11: =ROUND(FB_SaldoLC_11,2) -> 0 | CC11: =ROUND(FB_SaldoEUR_11,2) -> 0 | CD11: =ROUND(FB_SaldoLC_11,2) -> 0 | CE11: =ROUND(FB_SaldoEUR_11,2) -> 0 | CH11: Vorperiodensaldo | CI11: =ROUND(FB_SaldoLC_12,2) -> 0 | CJ11: =ROUND(FB_SaldoEUR_12,2) -> 0 | CK11: =ROUND(FB_SaldoLC_12,2) -> 0 | CL11: =ROUND(FB_SaldoEUR_12,2) -> 0 | CO11: Vorperiodensaldo | CP11: =ROUND(FB_SaldoLC_13,2) -> 0 | CQ11: =ROUND(FB_SaldoEUR_13,2) -> 0 | CR11: =ROUND(FB_SaldoLC_13,2) -> 0 | CS11: =ROUND(FB_SaldoEUR_13,2) -> 0 | CV11: Vorperiodensaldo | CW11: =ROUND(FB_SaldoLC_14,2) -> 0 | CX11: =ROUND(FB_SaldoEUR_14,2) -> 0 | CY11: =ROUND(FB_SaldoLC_14,2) -> 0 | CZ11: =ROUND(FB_SaldoEUR_14,2) -> 0 | DC11: Vorperiodensaldo | DD11: =ROUND(FB_SaldoLC_15,2) -> 0 | DE11: =ROUND(FB_SaldoEUR_15,2) -> 0 | DF11: =ROUND(FB_SaldoLC_15,2) -> 0 | DG11: =ROUND(FB_SaldoEUR_15,2) -> 0 | DJ11: Vorperiodensaldo | DK11: =ROUND(FB_SaldoLC_16,2) -> 0 | DL11: =ROUND(FB_SaldoEUR_16,2) -> 0 | DM11: =ROUND(FB_SaldoLC_16,2) -> 0 | DN11: =ROUND(FB_SaldoEUR_16,2) -> 0 | DQ11: Vorperiodensaldo | DR11: =ROUND(FB_SaldoLC_17,2) -> 0 | DS11: =ROUND(FB_SaldoEUR_17,2) -> 0 | DT11: =ROUND(FB_SaldoLC_17,2) -> 0 | DU11: =ROUND(FB_SaldoEUR_17,2) -> 0
B12: Eigenmittel | C12: =ROUND(SUMIF($B$116:$B$120,"Eigenmittel",$D$116:$D$120)+SUMIF($B$125:$B$130,"Eigenmittel",$D$125:$D$130),2) -> 0 | D12: =ROUND(SUMIF($B$116:$B$120,"Eigenmittel",$E$116:$E$120)+SUMIF($B$125:$B$130,"Eigenmittel",$E$125:$E$130),2) -> 0 | E12: =ROUND(SUMIF($B$116:$B$120,"Eigenmittel",$D$116:$D$120)+SUMIF($B$125:$B$130,"Eigenmittel",$D$125:$D$130),2) -> 0 | F12: =ROUND(SUMIF($B$116:$B$120,"Eigenmittel",$E$116:$E$120)+SUMIF($B$125:$B$130,"Eigenmittel",$E$125:$E$130),2) -> 0 | I12: Eigenmittel | J12: =ROUND(SUMIF($I$116:$I$120,"Eigenmittel",$K$116:$K$120)+SUMIF($I$125:$I$130,"Eigenmittel",$K$125:$K$130),2) -> 0 | K12: =ROUND(SUMIF($I$116:$I$120,"Eigenmittel",$L$116:$L$120)+SUMIF($I$125:$I$130,"Eigenmittel",$L$125:$L$130),2) -> 0 | L12: =IFERROR(ROUND(E12 + J12, 2), J12) -> 0 | M12: =IFERROR(ROUND(F12 + K12, 2), K12) -> 0 | P12: Eigenmittel | Q12: =ROUND(SUMIF($P$116:$P$120,"Eigenmittel",$R$116:$R$120)+SUMIF($P$125:$P$130,"Eigenmittel",$R$125:$R$130),2) -> 0 | R12: =ROUND(SUMIF($P$116:$P$120,"Eigenmittel",$S$116:$S$120)+SUMIF($P$125:$P$130,"Eigenmittel",$S$125:$S$130),2) -> 0 | S12: =IFERROR(ROUND(L12 + Q12, 2), Q12) -> 0 | T12: =IFERROR(ROUND(M12 + R12, 2), R12) -> 0 | W12: Eigenmittel | X12: =ROUND(SUMIF($W$116:$W$120,"Eigenmittel",$Y$116:$Y$120)+SUMIF($W$125:$W$130,"Eigenmittel",$Y$125:$Y$130),2) -> 0 | Y12: =ROUND(SUMIF($W$116:$W$120,"Eigenmittel",$Z$116:$Z$120)+SUMIF($W$125:$W$130,"Eigenmittel",$Z$125:$Z$130),2) -> 0 | Z12: =IFERROR(ROUND(S12 + X12, 2), X12) -> 0 | AA12: =IFERROR(ROUND(T12 + Y12, 2), Y12) -> 0 | AD12: Eigenmittel | AE12: =ROUND(SUMIF($AD$116:$AD$120,"Eigenmittel",$AF$116:$AF$120)+SUMIF($AD$125:$AD$130,"Eigenmittel",$AF$125:$AF$130),2) -> 0 | AF12: =ROUND(SUMIF($AD$116:$AD$120,"Eigenmittel",$AG$116:$AG$120)+SUMIF($AD$125:$AD$130,"Eigenmittel",$AG$125:$AG$130),2) -> 0 | AG12: =IFERROR(ROUND(Z12 + AE12, 2), AE12) -> 0 | AH12: =IFERROR(ROUND(AA12 + AF12, 2), AF12) -> 0 | AK12: Eigenmittel | AL12: =ROUND(SUMIF($AK$116:$AK$120,"Eigenmittel",$AM$116:$AM$120)+SUMIF($AK$125:$AK$130,"Eigenmittel",$AM$125:$AM$130),2) -> 0 | AM12: =ROUND(SUMIF($AK$116:$AK$120,"Eigenmittel",$AN$116:$AN$120)+SUMIF($AK$125:$AK$130,"Eigenmittel",$AN$125:$AN$130),2) -> 0 | AN12: =IFERROR(ROUND(AG12 + AL12, 2), AL12) -> 0 | AO12: =IFERROR(ROUND(AH12 + AM12, 2), AM12) -> 0 | AR12: Eigenmittel | AS12: =ROUND(SUMIF($AR$116:$AR$120,"Eigenmittel",$AT$116:$AT$120)+SUMIF($AR$125:$AR$130,"Eigenmittel",$AT$125:$AT$130),2) -> 0 | AT12: =ROUND(SUMIF($AR$116:$AR$120,"Eigenmittel",$AU$116:$AU$120)+SUMIF($AR$125:$AR$130,"Eigenmittel",$AU$125:$AU$130),2) -> 0 | AU12: =IFERROR(ROUND(AN12 + AS12, 2), AS12) -> 0 | AV12: =IFERROR(ROUND(AO12 + AT12, 2), AT12) -> 0 | AY12: Eigenmittel | AZ12: =ROUND(SUMIF($AY$116:$AY$120,"Eigenmittel",$BA$116:$BA$120)+SUMIF($AY$125:$AY$130,"Eigenmittel",$BA$125:$BA$130),2) -> 0 | BA12: =ROUND(SUMIF($AY$116:$AY$120,"Eigenmittel",$BB$116:$BB$120)+SUMIF($AY$125:$AY$130,"Eigenmittel",$BB$125:$BB$130),2) -> 0 | BB12: =IFERROR(ROUND(AU12 + AZ12, 2), AZ12) -> 0 | BC12: =IFERROR(ROUND(AV12 + BA12, 2), BA12) -> 0 | BF12: Eigenmittel | BG12: =ROUND(SUMIF($BF$116:$BF$120,"Eigenmittel",$BH$116:$BH$120)+SUMIF($BF$125:$BF$130,"Eigenmittel",$BH$125:$BH$130),2) -> 0 | BH12: =ROUND(SUMIF($BF$116:$BF$120,"Eigenmittel",$BI$116:$BI$120)+SUMIF($BF$125:$BF$130,"Eigenmittel",$BI$125:$BI$130),2) -> 0 | BI12: =IFERROR(ROUND(BB12 + BG12, 2), BG12) -> 0 | BJ12: =IFERROR(ROUND(BC12 + BH12, 2), BH12) -> 0 | BM12: Eigenmittel | BN12: =ROUND(SUMIF($BM$116:$BM$120,"Eigenmittel",$BO$116:$BO$120)+SUMIF($BM$125:$BM$130,"Eigenmittel",$BO$125:$BO$130),2) -> 0 | BO12: =ROUND(SUMIF($BM$116:$BM$120,"Eigenmittel",$BP$116:$BP$120)+SUMIF($BM$125:$BM$130,"Eigenmittel",$BP$125:$BP$130),2) -> 0 | BP12: =IFERROR(ROUND(BI12 + BN12, 2), BN12) -> 0 | BQ12: =IFERROR(ROUND(BJ12 + BO12, 2), BO12) -> 0 | BT12: Eigenmittel | BU12: =ROUND(SUMIF($BT$116:$BT$120,"Eigenmittel",$BV$116:$BV$120)+SUMIF($BT$125:$BT$130,"Eigenmittel",$BV$125:$BV$130),2) -> 0 | BV12: =ROUND(SUMIF($BT$116:$BT$120,"Eigenmittel",$BW$116:$BW$120)+SUMIF($BT$125:$BT$130,"Eigenmittel",$BW$125:$BW$130),2) -> 0 | BW12: =IFERROR(ROUND(BP12 + BU12, 2), BU12) -> 0 | BX12: =IFERROR(ROUND(BQ12 + BV12, 2), BV12) -> 0 | CA12: Eigenmittel | CB12: =ROUND(SUMIF($CA$116:$CA$120,"Eigenmittel",$CC$116:$CC$120)+SUMIF($CA$125:$CA$130,"Eigenmittel",$CC$125:$CC$130),2) -> 0 | CC12: =ROUND(SUMIF($CA$116:$CA$120,"Eigenmittel",$CD$116:$CD$120)+SUMIF($CA$125:$CA$130,"Eigenmittel",$CD$125:$CD$130),2) -> 0 | CD12: =IFERROR(ROUND(BW12 + CB12, 2), CB12) -> 0 | CE12: =IFERROR(ROUND(BX12 + CC12, 2), CC12) -> 0 | CH12: Eigenmittel | CI12: =ROUND(SUMIF($CH$116:$CH$120,"Eigenmittel",$CJ$116:$CJ$120)+SUMIF($CH$125:$CH$130,"Eigenmittel",$CJ$125:$CJ$130),2) -> 0 | CJ12: =ROUND(SUMIF($CH$116:$CH$120,"Eigenmittel",$CK$116:$CK$120)+SUMIF($CH$125:$CH$130,"Eigenmittel",$CK$125:$CK$130),2) -> 0 | CK12: =IFERROR(ROUND(CD12 + CI12, 2), CI12) -> 0 | CL12: =IFERROR(ROUND(CE12 + CJ12, 2), CJ12) -> 0 | CO12: Eigenmittel | CP12: =ROUND(SUMIF($CO$116:$CO$120,"Eigenmittel",$CQ$116:$CQ$120)+SUMIF($CO$125:$CO$130,"Eigenmittel",$CQ$125:$CQ$130),2) -> 0 | CQ12: =ROUND(SUMIF($CO$116:$CO$120,"Eigenmittel",$CR$116:$CR$120)+SUMIF($CO$125:$CO$130,"Eigenmittel",$CR$125:$CR$130),2) -> 0 | CR12: =IFERROR(ROUND(CK12 + CP12, 2), CP12) -> 0 | CS12: =IFERROR(ROUND(CL12 + CQ12, 2), CQ12) -> 0 | CV12: Eigenmittel | CW12: =ROUND(SUMIF($CV$116:$CV$120,"Eigenmittel",$CX$116:$CX$120)+SUMIF($CV$125:$CV$130,"Eigenmittel",$CX$125:$CX$130),2) -> 0 | CX12: =ROUND(SUMIF($CV$116:$CV$120,"Eigenmittel",$CY$116:$CY$120)+SUMIF($CV$125:$CV$130,"Eigenmittel",$CY$125:$CY$130),2) -> 0 | CY12: =IFERROR(ROUND(CR12 + CW12, 2), CW12) -> 0 | CZ12: =IFERROR(ROUND(CS12 + CX12, 2), CX12) -> 0 | DC12: Eigenmittel | DD12: =ROUND(SUMIF($DC$116:$DC$120,"Eigenmittel",$DE$116:$DE$120)+SUMIF($DC$125:$DC$130,"Eigenmittel",$DE$125:$DE$130),2) -> 0 | DE12: =ROUND(SUMIF($DC$116:$DC$120,"Eigenmittel",$DF$116:$DF$120)+SUMIF($DC$125:$DC$130,"Eigenmittel",$DF$125:$DF$130),2) -> 0 | DF12: =IFERROR(ROUND(CY12 + DD12, 2), DD12) -> 0 | DG12: =IFERROR(ROUND(CZ12 + DE12, 2), DE12) -> 0 | DJ12: Eigenmittel | DK12: =ROUND(SUMIF($DJ$116:$DJ$120,"Eigenmittel",$DL$116:$DL$120)+SUMIF($DJ$125:$DJ$130,"Eigenmittel",$DL$125:$DL$130),2) -> 0 | DL12: =ROUND(SUMIF($DJ$116:$DJ$120,"Eigenmittel",$DM$116:$DM$120)+SUMIF($DJ$125:$DJ$130,"Eigenmittel",$DM$125:$DM$130),2) -> 0 | DM12: =IFERROR(ROUND(DF12 + DK12, 2), DK12) -> 0 | DN12: =IFERROR(ROUND(DG12 + DL12, 2), DL12) -> 0 | DQ12: Eigenmittel | DR12: =ROUND(SUMIF($DQ$116:$DQ$120,"Eigenmittel",$DS$116:$DS$120)+SUMIF($DQ$125:$DQ$130,"Eigenmittel",$DS$125:$DS$130),2) -> 0 | DS12: =ROUND(SUMIF($DQ$116:$DQ$120,"Eigenmittel",$DT$116:$DT$120)+SUMIF($DQ$125:$DQ$130,"Eigenmittel",$DT$125:$DT$130),2) -> 0 | DT12: =IFERROR(ROUND(DM12 + DR12, 2), DR12) -> 0 | DU12: =IFERROR(ROUND(DN12 + DS12, 2), DS12) -> 0
B13: Drittmittel | C13: =ROUND(SUMIF($B$116:$B$120,"Drittmittel",$D$116:$D$120)+SUMIF($B$125:$B$130,"Drittmittel",$D$125:$D$130),2) -> 0 | D13: =ROUND(SUMIF($B$116:$B$120,"Drittmittel",$E$116:$E$120)+SUMIF($B$125:$B$130,"Drittmittel",$E$125:$E$130),2) -> 0 | E13: =ROUND(SUMIF($B$116:$B$120,"Drittmittel",$D$116:$D$120)+SUMIF($B$125:$B$130,"Drittmittel",$D$125:$D$130),2) -> 0 | F13: =ROUND(SUMIF($B$116:$B$120,"Drittmittel",$E$116:$E$120)+SUMIF($B$125:$B$130,"Drittmittel",$E$125:$E$130),2) -> 0 | I13: Drittmittel | J13: =ROUND(SUMIF($I$116:$I$120,"Drittmittel",$K$116:$K$120)+SUMIF($I$125:$I$130,"Drittmittel",$K$125:$K$130),2) -> 0 | K13: =ROUND(SUMIF($I$116:$I$120,"Drittmittel",$L$116:$L$120)+SUMIF($I$125:$I$130,"Drittmittel",$L$125:$L$130),2) -> 0 | L13: =IFERROR(ROUND(E13 + J13, 2), J13) -> 0 | M13: =IFERROR(ROUND(F13 + K13, 2), K13) -> 0 | P13: Drittmittel | Q13: =ROUND(SUMIF($P$116:$P$120,"Drittmittel",$R$116:$R$120)+SUMIF($P$125:$P$130,"Drittmittel",$R$125:$R$130),2) -> 0 | R13: =ROUND(SUMIF($P$116:$P$120,"Drittmittel",$S$116:$S$120)+SUMIF($P$125:$P$130,"Drittmittel",$S$125:$S$130),2) -> 0 | S13: =IFERROR(ROUND(L13 + Q13, 2), Q13) -> 0 | T13: =IFERROR(ROUND(M13 + R13, 2), R13) -> 0 | W13: Drittmittel | X13: =ROUND(SUMIF($W$116:$W$120,"Drittmittel",$Y$116:$Y$120)+SUMIF($W$125:$W$130,"Drittmittel",$Y$125:$Y$130),2) -> 0 | Y13: =ROUND(SUMIF($W$116:$W$120,"Drittmittel",$Z$116:$Z$120)+SUMIF($W$125:$W$130,"Drittmittel",$Z$125:$Z$130),2) -> 0 | Z13: =IFERROR(ROUND(S13 + X13, 2), X13) -> 0 | AA13: =IFERROR(ROUND(T13 + Y13, 2), Y13) -> 0 | AD13: Drittmittel | AE13: =ROUND(SUMIF($AD$116:$AD$120,"Drittmittel",$AF$116:$AF$120)+SUMIF($AD$125:$AD$130,"Drittmittel",$AF$125:$AF$130),2) -> 0 | AF13: =ROUND(SUMIF($AD$116:$AD$120,"Drittmittel",$AG$116:$AG$120)+SUMIF($AD$125:$AD$130,"Drittmittel",$AG$125:$AG$130),2) -> 0 | AG13: =IFERROR(ROUND(Z13 + AE13, 2), AE13) -> 0 | AH13: =IFERROR(ROUND(AA13 + AF13, 2), AF13) -> 0 | AK13: Drittmittel | AL13: =ROUND(SUMIF($AK$116:$AK$120,"Drittmittel",$AM$116:$AM$120)+SUMIF($AK$125:$AK$130,"Drittmittel",$AM$125:$AM$130),2) -> 0 | AM13: =ROUND(SUMIF($AK$116:$AK$120,"Drittmittel",$AN$116:$AN$120)+SUMIF($AK$125:$AK$130,"Drittmittel",$AN$125:$AN$130),2) -> 0 | AN13: =IFERROR(ROUND(AG13 + AL13, 2), AL13) -> 0 | AO13: =IFERROR(ROUND(AH13 + AM13, 2), AM13) -> 0 | AR13: Drittmittel | AS13: =ROUND(SUMIF($AR$116:$AR$120,"Drittmittel",$AT$116:$AT$120)+SUMIF($AR$125:$AR$130,"Drittmittel",$AT$125:$AT$130),2) -> 0 | AT13: =ROUND(SUMIF($AR$116:$AR$120,"Drittmittel",$AU$116:$AU$120)+SUMIF($AR$125:$AR$130,"Drittmittel",$AU$125:$AU$130),2) -> 0 | AU13: =IFERROR(ROUND(AN13 + AS13, 2), AS13) -> 0 | AV13: =IFERROR(ROUND(AO13 + AT13, 2), AT13) -> 0 | AY13: Drittmittel | AZ13: =ROUND(SUMIF($AY$116:$AY$120,"Drittmittel",$BA$116:$BA$120)+SUMIF($AY$125:$AY$130,"Drittmittel",$BA$125:$BA$130),2) -> 0 | BA13: =ROUND(SUMIF($AY$116:$AY$120,"Drittmittel",$BB$116:$BB$120)+SUMIF($AY$125:$AY$130,"Drittmittel",$BB$125:$BB$130),2) -> 0 | BB13: =IFERROR(ROUND(AU13 + AZ13, 2), AZ13) -> 0 | BC13: =IFERROR(ROUND(AV13 + BA13, 2), BA13) -> 0 | BF13: Drittmittel | BG13: =ROUND(SUMIF($BF$116:$BF$120,"Drittmittel",$BH$116:$BH$120)+SUMIF($BF$125:$BF$130,"Drittmittel",$BH$125:$BH$130),2) -> 0 | BH13: =ROUND(SUMIF($BF$116:$BF$120,"Drittmittel",$BI$116:$BI$120)+SUMIF($BF$125:$BF$130,"Drittmittel",$BI$125:$BI$130),2) -> 0 | BI13: =IFERROR(ROUND(BB13 + BG13, 2), BG13) -> 0 | BJ13: =IFERROR(ROUND(BC13 + BH13, 2), BH13) -> 0 | BM13: Drittmittel | BN13: =ROUND(SUMIF($BM$116:$BM$120,"Drittmittel",$BO$116:$BO$120)+SUMIF($BM$125:$BM$130,"Drittmittel",$BO$125:$BO$130),2) -> 0 | BO13: =ROUND(SUMIF($BM$116:$BM$120,"Drittmittel",$BP$116:$BP$120)+SUMIF($BM$125:$BM$130,"Drittmittel",$BP$125:$BP$130),2) -> 0 | BP13: =IFERROR(ROUND(BI13 + BN13, 2), BN13) -> 0 | BQ13: =IFERROR(ROUND(BJ13 + BO13, 2), BO13) -> 0 | BT13: Drittmittel | BU13: =ROUND(SUMIF($BT$116:$BT$120,"Drittmittel",$BV$116:$BV$120)+SUMIF($BT$125:$BT$130,"Drittmittel",$BV$125:$BV$130),2) -> 0 | BV13: =ROUND(SUMIF($BT$116:$BT$120,"Drittmittel",$BW$116:$BW$120)+SUMIF($BT$125:$BT$130,"Drittmittel",$BW$125:$BW$130),2) -> 0 | BW13: =IFERROR(ROUND(BP13 + BU13, 2), BU13) -> 0 | BX13: =IFERROR(ROUND(BQ13 + BV13, 2), BV13) -> 0 | CA13: Drittmittel | CB13: =ROUND(SUMIF($CA$116:$CA$120,"Drittmittel",$CC$116:$CC$120)+SUMIF($CA$125:$CA$130,"Drittmittel",$CC$125:$CC$130),2) -> 0 | CC13: =ROUND(SUMIF($CA$116:$CA$120,"Drittmittel",$CD$116:$CD$120)+SUMIF($CA$125:$CA$130,"Drittmittel",$CD$125:$CD$130),2) -> 0 | CD13: =IFERROR(ROUND(BW13 + CB13, 2), CB13) -> 0 | CE13: =IFERROR(ROUND(BX13 + CC13, 2), CC13) -> 0 | CH13: Drittmittel | CI13: =ROUND(SUMIF($CH$116:$CH$120,"Drittmittel",$CJ$116:$CJ$120)+SUMIF($CH$125:$CH$130,"Drittmittel",$CJ$125:$CJ$130),2) -> 0 | CJ13: =ROUND(SUMIF($CH$116:$CH$120,"Drittmittel",$CK$116:$CK$120)+SUMIF($CH$125:$CH$130,"Drittmittel",$CK$125:$CK$130),2) -> 0 | CK13: =IFERROR(ROUND(CD13 + CI13, 2), CI13) -> 0 | CL13: =IFERROR(ROUND(CE13 + CJ13, 2), CJ13) -> 0 | CO13: Drittmittel | CP13: =ROUND(SUMIF($CO$116:$CO$120,"Drittmittel",$CQ$116:$CQ$120)+SUMIF($CO$125:$CO$130,"Drittmittel",$CQ$125:$CQ$130),2) -> 0 | CQ13: =ROUND(SUMIF($CO$116:$CO$120,"Drittmittel",$CR$116:$CR$120)+SUMIF($CO$125:$CO$130,"Drittmittel",$CR$125:$CR$130),2) -> 0 | CR13: =IFERROR(ROUND(CK13 + CP13, 2), CP13) -> 0 | CS13: =IFERROR(ROUND(CL13 + CQ13, 2), CQ13) -> 0 | CV13: Drittmittel | CW13: =ROUND(SUMIF($CV$116:$CV$120,"Drittmittel",$CX$116:$CX$120)+SUMIF($CV$125:$CV$130,"Drittmittel",$CX$125:$CX$130),2) -> 0 | CX13: =ROUND(SUMIF($CV$116:$CV$120,"Drittmittel",$CY$116:$CY$120)+SUMIF($CV$125:$CV$130,"Drittmittel",$CY$125:$CY$130),2) -> 0 | CY13: =IFERROR(ROUND(CR13 + CW13, 2), CW13) -> 0 | CZ13: =IFERROR(ROUND(CS13 + CX13, 2), CX13) -> 0 | DC13: Drittmittel | DD13: =ROUND(SUMIF($DC$116:$DC$120,"Drittmittel",$DE$116:$DE$120)+SUMIF($DC$125:$DC$130,"Drittmittel",$DE$125:$DE$130),2) -> 0 | DE13: =ROUND(SUMIF($DC$116:$DC$120,"Drittmittel",$DF$116:$DF$120)+SUMIF($DC$125:$DC$130,"Drittmittel",$DF$125:$DF$130),2) -> 0 | DF13: =IFERROR(ROUND(CY13 + DD13, 2), DD13) -> 0 | DG13: =IFERROR(ROUND(CZ13 + DE13, 2), DE13) -> 0 | DJ13: Drittmittel | DK13: =ROUND(SUMIF($DJ$116:$DJ$120,"Drittmittel",$DL$116:$DL$120)+SUMIF($DJ$125:$DJ$130,"Drittmittel",$DL$125:$DL$130),2) -> 0 | DL13: =ROUND(SUMIF($DJ$116:$DJ$120,"Drittmittel",$DM$116:$DM$120)+SUMIF($DJ$125:$DJ$130,"Drittmittel",$DM$125:$DM$130),2) -> 0 | DM13: =IFERROR(ROUND(DF13 + DK13, 2), DK13) -> 0 | DN13: =IFERROR(ROUND(DG13 + DL13, 2), DL13) -> 0 | DQ13: Drittmittel | DR13: =ROUND(SUMIF($DQ$116:$DQ$120,"Drittmittel",$DS$116:$DS$120)+SUMIF($DQ$125:$DQ$130,"Drittmittel",$DS$125:$DS$130),2) -> 0 | DS13: =ROUND(SUMIF($DQ$116:$DQ$120,"Drittmittel",$DT$116:$DT$120)+SUMIF($DQ$125:$DQ$130,"Drittmittel",$DT$125:$DT$130),2) -> 0 | DT13: =IFERROR(ROUND(DM13 + DR13, 2), DR13) -> 0 | DU13: =IFERROR(ROUND(DN13 + DS13, 2), DS13) -> 0
B14: KMW-Mittel | C14: =ROUND(SUMIF($B$116:$B$120,"KMW-Mittel",$D$116:$D$120)+SUMIF($B$125:$B$130,"KMW-Mittel",$D$125:$D$130),2) -> 0 | D14: =ROUND(SUMIF($B$116:$B$120,"KMW-Mittel",$E$116:$E$120)+SUMIF($B$125:$B$130,"KMW-Mittel",$E$125:$E$130),2) -> 0 | E14: =ROUND(SUMIF($B$116:$B$120,"KMW-Mittel",$D$116:$D$120)+SUMIF($B$125:$B$130,"KMW-Mittel",$D$125:$D$130),2) -> 0 | F14: =ROUND(SUMIF($B$116:$B$120,"KMW-Mittel",$E$116:$E$120)+SUMIF($B$125:$B$130,"KMW-Mittel",$E$125:$E$130),2) -> 0 | I14: KMW-Mittel | J14: =ROUND(SUMIF($I$116:$I$120,"KMW-Mittel",$K$116:$K$120)+SUMIF($I$125:$I$130,"KMW-Mittel",$K$125:$K$130),2) -> 0 | K14: =ROUND(SUMIF($I$116:$I$120,"KMW-Mittel",$L$116:$L$120)+SUMIF($I$125:$I$130,"KMW-Mittel",$L$125:$L$130),2) -> 0 | L14: =IFERROR(ROUND(E14 + J14, 2), J14) -> 0 | M14: =IFERROR(ROUND(F14 + K14, 2), K14) -> 0 | P14: KMW-Mittel | Q14: =ROUND(SUMIF($P$116:$P$120,"KMW-Mittel",$R$116:$R$120)+SUMIF($P$125:$P$130,"KMW-Mittel",$R$125:$R$130),2) -> 0 | R14: =ROUND(SUMIF($P$116:$P$120,"KMW-Mittel",$S$116:$S$120)+SUMIF($P$125:$P$130,"KMW-Mittel",$S$125:$S$130),2) -> 0 | S14: =IFERROR(ROUND(L14 + Q14, 2), Q14) -> 0 | T14: =IFERROR(ROUND(M14 + R14, 2), R14) -> 0 | W14: KMW-Mittel | X14: =ROUND(SUMIF($W$116:$W$120,"KMW-Mittel",$Y$116:$Y$120)+SUMIF($W$125:$W$130,"KMW-Mittel",$Y$125:$Y$130),2) -> 0 | Y14: =ROUND(SUMIF($W$116:$W$120,"KMW-Mittel",$Z$116:$Z$120)+SUMIF($W$125:$W$130,"KMW-Mittel",$Z$125:$Z$130),2) -> 0 | Z14: =IFERROR(ROUND(S14 + X14, 2), X14) -> 0 | AA14: =IFERROR(ROUND(T14 + Y14, 2), Y14) -> 0 | AD14: KMW-Mittel | AE14: =ROUND(SUMIF($AD$116:$AD$120,"KMW-Mittel",$AF$116:$AF$120)+SUMIF($AD$125:$AD$130,"KMW-Mittel",$AF$125:$AF$130),2) -> 0 | AF14: =ROUND(SUMIF($AD$116:$AD$120,"KMW-Mittel",$AG$116:$AG$120)+SUMIF($AD$125:$AD$130,"KMW-Mittel",$AG$125:$AG$130),2) -> 0 | AG14: =IFERROR(ROUND(Z14 + AE14, 2), AE14) -> 0 | AH14: =IFERROR(ROUND(AA14 + AF14, 2), AF14) -> 0 | AK14: KMW-Mittel | AL14: =ROUND(SUMIF($AK$116:$AK$120,"KMW-Mittel",$AM$116:$AM$120)+SUMIF($AK$125:$AK$130,"KMW-Mittel",$AM$125:$AM$130),2) -> 0 | AM14: =ROUND(SUMIF($AK$116:$AK$120,"KMW-Mittel",$AN$116:$AN$120)+SUMIF($AK$125:$AK$130,"KMW-Mittel",$AN$125:$AN$130),2) -> 0 | AN14: =IFERROR(ROUND(AG14 + AL14, 2), AL14) -> 0 | AO14: =IFERROR(ROUND(AH14 + AM14, 2), AM14) -> 0 | AR14: KMW-Mittel | AS14: =ROUND(SUMIF($AR$116:$AR$120,"KMW-Mittel",$AT$116:$AT$120)+SUMIF($AR$125:$AR$130,"KMW-Mittel",$AT$125:$AT$130),2) -> 0 | AT14: =ROUND(SUMIF($AR$116:$AR$120,"KMW-Mittel",$AU$116:$AU$120)+SUMIF($AR$125:$AR$130,"KMW-Mittel",$AU$125:$AU$130),2) -> 0 | AU14: =IFERROR(ROUND(AN14 + AS14, 2), AS14) -> 0 | AV14: =IFERROR(ROUND(AO14 + AT14, 2), AT14) -> 0 | AY14: KMW-Mittel | AZ14: =ROUND(SUMIF($AY$116:$AY$120,"KMW-Mittel",$BA$116:$BA$120)+SUMIF($AY$125:$AY$130,"KMW-Mittel",$BA$125:$BA$130),2) -> 0 | BA14: =ROUND(SUMIF($AY$116:$AY$120,"KMW-Mittel",$BB$116:$BB$120)+SUMIF($AY$125:$AY$130,"KMW-Mittel",$BB$125:$BB$130),2) -> 0 | BB14: =IFERROR(ROUND(AU14 + AZ14, 2), AZ14) -> 0 | BC14: =IFERROR(ROUND(AV14 + BA14, 2), BA14) -> 0 | BF14: KMW-Mittel | BG14: =ROUND(SUMIF($BF$116:$BF$120,"KMW-Mittel",$BH$116:$BH$120)+SUMIF($BF$125:$BF$130,"KMW-Mittel",$BH$125:$BH$130),2) -> 0 | BH14: =ROUND(SUMIF($BF$116:$BF$120,"KMW-Mittel",$BI$116:$BI$120)+SUMIF($BF$125:$BF$130,"KMW-Mittel",$BI$125:$BI$130),2) -> 0 | BI14: =IFERROR(ROUND(BB14 + BG14, 2), BG14) -> 0 | BJ14: =IFERROR(ROUND(BC14 + BH14, 2), BH14) -> 0 | BM14: KMW-Mittel | BN14: =ROUND(SUMIF($BM$116:$BM$120,"KMW-Mittel",$BO$116:$BO$120)+SUMIF($BM$125:$BM$130,"KMW-Mittel",$BO$125:$BO$130),2) -> 0 | BO14: =ROUND(SUMIF($BM$116:$BM$120,"KMW-Mittel",$BP$116:$BP$120)+SUMIF($BM$125:$BM$130,"KMW-Mittel",$BP$125:$BP$130),2) -> 0 | BP14: =IFERROR(ROUND(BI14 + BN14, 2), BN14) -> 0 | BQ14: =IFERROR(ROUND(BJ14 + BO14, 2), BO14) -> 0 | BT14: KMW-Mittel | BU14: =ROUND(SUMIF($BT$116:$BT$120,"KMW-Mittel",$BV$116:$BV$120)+SUMIF($BT$125:$BT$130,"KMW-Mittel",$BV$125:$BV$130),2) -> 0 | BV14: =ROUND(SUMIF($BT$116:$BT$120,"KMW-Mittel",$BW$116:$BW$120)+SUMIF($BT$125:$BT$130,"KMW-Mittel",$BW$125:$BW$130),2) -> 0 | BW14: =IFERROR(ROUND(BP14 + BU14, 2), BU14) -> 0 | BX14: =IFERROR(ROUND(BQ14 + BV14, 2), BV14) -> 0 | CA14: KMW-Mittel | CB14: =ROUND(SUMIF($CA$116:$CA$120,"KMW-Mittel",$CC$116:$CC$120)+SUMIF($CA$125:$CA$130,"KMW-Mittel",$CC$125:$CC$130),2) -> 0 | CC14: =ROUND(SUMIF($CA$116:$CA$120,"KMW-Mittel",$CD$116:$CD$120)+SUMIF($CA$125:$CA$130,"KMW-Mittel",$CD$125:$CD$130),2) -> 0 | CD14: =IFERROR(ROUND(BW14 + CB14, 2), CB14) -> 0 | CE14: =IFERROR(ROUND(BX14 + CC14, 2), CC14) -> 0 | CH14: KMW-Mittel | CI14: =ROUND(SUMIF($CH$116:$CH$120,"KMW-Mittel",$CJ$116:$CJ$120)+SUMIF($CH$125:$CH$130,"KMW-Mittel",$CJ$125:$CJ$130),2) -> 0 | CJ14: =ROUND(SUMIF($CH$116:$CH$120,"KMW-Mittel",$CK$116:$CK$120)+SUMIF($CH$125:$CH$130,"KMW-Mittel",$CK$125:$CK$130),2) -> 0 | CK14: =IFERROR(ROUND(CD14 + CI14, 2), CI14) -> 0 | CL14: =IFERROR(ROUND(CE14 + CJ14, 2), CJ14) -> 0 | CO14: KMW-Mittel | CP14: =ROUND(SUMIF($CO$116:$CO$120,"KMW-Mittel",$CQ$116:$CQ$120)+SUMIF($CO$125:$CO$130,"KMW-Mittel",$CQ$125:$CQ$130),2) -> 0 | CQ14: =ROUND(SUMIF($CO$116:$CO$120,"KMW-Mittel",$CR$116:$CR$120)+SUMIF($CO$125:$CO$130,"KMW-Mittel",$CR$125:$CR$130),2) -> 0 | CR14: =IFERROR(ROUND(CK14 + CP14, 2), CP14) -> 0 | CS14: =IFERROR(ROUND(CL14 + CQ14, 2), CQ14) -> 0 | CV14: KMW-Mittel | CW14: =ROUND(SUMIF($CV$116:$CV$120,"KMW-Mittel",$CX$116:$CX$120)+SUMIF($CV$125:$CV$130,"KMW-Mittel",$CX$125:$CX$130),2) -> 0 | CX14: =ROUND(SUMIF($CV$116:$CV$120,"KMW-Mittel",$CY$116:$CY$120)+SUMIF($CV$125:$CV$130,"KMW-Mittel",$CY$125:$CY$130),2) -> 0 | CY14: =IFERROR(ROUND(CR14 + CW14, 2), CW14) -> 0 | CZ14: =IFERROR(ROUND(CS14 + CX14, 2), CX14) -> 0 | DC14: KMW-Mittel | DD14: =ROUND(SUMIF($DC$116:$DC$120,"KMW-Mittel",$DE$116:$DE$120)+SUMIF($DC$125:$DC$130,"KMW-Mittel",$DE$125:$DE$130),2) -> 0 | DE14: =ROUND(SUMIF($DC$116:$DC$120,"KMW-Mittel",$DF$116:$DF$120)+SUMIF($DC$125:$DC$130,"KMW-Mittel",$DF$125:$DF$130),2) -> 0 | DF14: =IFERROR(ROUND(CY14 + DD14, 2), DD14) -> 0 | DG14: =IFERROR(ROUND(CZ14 + DE14, 2), DE14) -> 0 | DJ14: KMW-Mittel | DK14: =ROUND(SUMIF($DJ$116:$DJ$120,"KMW-Mittel",$DL$116:$DL$120)+SUMIF($DJ$125:$DJ$130,"KMW-Mittel",$DL$125:$DL$130),2) -> 0 | DL14: =ROUND(SUMIF($DJ$116:$DJ$120,"KMW-Mittel",$DM$116:$DM$120)+SUMIF($DJ$125:$DJ$130,"KMW-Mittel",$DM$125:$DM$130),2) -> 0 | DM14: =IFERROR(ROUND(DF14 + DK14, 2), DK14) -> 0 | DN14: =IFERROR(ROUND(DG14 + DL14, 2), DL14) -> 0 | DQ14: KMW-Mittel | DR14: =ROUND(SUMIF($DQ$116:$DQ$120,"KMW-Mittel",$DS$116:$DS$120)+SUMIF($DQ$125:$DQ$130,"KMW-Mittel",$DS$125:$DS$130),2) -> 0 | DS14: =ROUND(SUMIF($DQ$116:$DQ$120,"KMW-Mittel",$DT$116:$DT$120)+SUMIF($DQ$125:$DQ$130,"KMW-Mittel",$DT$125:$DT$130),2) -> 0 | DT14: =IFERROR(ROUND(DM14 + DR14, 2), DR14) -> 0 | DU14: =IFERROR(ROUND(DN14 + DS14, 2), DS14) -> 0
B15: Zinsertraege | C15: =ROUND(SUMIF($B$116:$B$120,"Zinsertraege",$D$116:$D$120)+SUMIF($B$125:$B$130,"Zinsertraege",$D$125:$D$130),2) -> 0 | D15: =ROUND(SUMIF($B$116:$B$120,"Zinsertraege",$E$116:$E$120)+SUMIF($B$125:$B$130,"Zinsertraege",$E$125:$E$130),2) -> 0 | E15: =ROUND(SUMIF($B$116:$B$120,"Zinsertraege",$D$116:$D$120)+SUMIF($B$125:$B$130,"Zinsertraege",$D$125:$D$130),2) -> 0 | F15: =ROUND(SUMIF($B$116:$B$120,"Zinsertraege",$E$116:$E$120)+SUMIF($B$125:$B$130,"Zinsertraege",$E$125:$E$130),2) -> 0 | I15: Zinsertraege | J15: =ROUND(SUMIF($I$116:$I$120,"Zinsertraege",$K$116:$K$120)+SUMIF($I$125:$I$130,"Zinsertraege",$K$125:$K$130),2) -> 0 | K15: =ROUND(SUMIF($I$116:$I$120,"Zinsertraege",$L$116:$L$120)+SUMIF($I$125:$I$130,"Zinsertraege",$L$125:$L$130),2) -> 0 | L15: =IFERROR(ROUND(E15 + J15, 2), J15) -> 0 | M15: =IFERROR(ROUND(F15 + K15, 2), K15) -> 0 | P15: Zinsertraege | Q15: =ROUND(SUMIF($P$116:$P$120,"Zinsertraege",$R$116:$R$120)+SUMIF($P$125:$P$130,"Zinsertraege",$R$125:$R$130),2) -> 0 | R15: =ROUND(SUMIF($P$116:$P$120,"Zinsertraege",$S$116:$S$120)+SUMIF($P$125:$P$130,"Zinsertraege",$S$125:$S$130),2) -> 0 | S15: =IFERROR(ROUND(L15 + Q15, 2), Q15) -> 0 | T15: =IFERROR(ROUND(M15 + R15, 2), R15) -> 0 | W15: Zinsertraege | X15: =ROUND(SUMIF($W$116:$W$120,"Zinsertraege",$Y$116:$Y$120)+SUMIF($W$125:$W$130,"Zinsertraege",$Y$125:$Y$130),2) -> 0 | Y15: =ROUND(SUMIF($W$116:$W$120,"Zinsertraege",$Z$116:$Z$120)+SUMIF($W$125:$W$130,"Zinsertraege",$Z$125:$Z$130),2) -> 0 | Z15: =IFERROR(ROUND(S15 + X15, 2), X15) -> 0 | AA15: =IFERROR(ROUND(T15 + Y15, 2), Y15) -> 0 | AD15: Zinsertraege | AE15: =ROUND(SUMIF($AD$116:$AD$120,"Zinsertraege",$AF$116:$AF$120)+SUMIF($AD$125:$AD$130,"Zinsertraege",$AF$125:$AF$130),2) -> 0 | AF15: =ROUND(SUMIF($AD$116:$AD$120,"Zinsertraege",$AG$116:$AG$120)+SUMIF($AD$125:$AD$130,"Zinsertraege",$AG$125:$AG$130),2) -> 0 | AG15: =IFERROR(ROUND(Z15 + AE15, 2), AE15) -> 0 | AH15: =IFERROR(ROUND(AA15 + AF15, 2), AF15) -> 0 | AK15: Zinsertraege | AL15: =ROUND(SUMIF($AK$116:$AK$120,"Zinsertraege",$AM$116:$AM$120)+SUMIF($AK$125:$AK$130,"Zinsertraege",$AM$125:$AM$130),2) -> 0 | AM15: =ROUND(SUMIF($AK$116:$AK$120,"Zinsertraege",$AN$116:$AN$120)+SUMIF($AK$125:$AK$130,"Zinsertraege",$AN$125:$AN$130),2) -> 0 | AN15: =IFERROR(ROUND(AG15 + AL15, 2), AL15) -> 0 | AO15: =IFERROR(ROUND(AH15 + AM15, 2), AM15) -> 0 | AR15: Zinsertraege | AS15: =ROUND(SUMIF($AR$116:$AR$120,"Zinsertraege",$AT$116:$AT$120)+SUMIF($AR$125:$AR$130,"Zinsertraege",$AT$125:$AT$130),2) -> 0 | AT15: =ROUND(SUMIF($AR$116:$AR$120,"Zinsertraege",$AU$116:$AU$120)+SUMIF($AR$125:$AR$130,"Zinsertraege",$AU$125:$AU$130),2) -> 0 | AU15: =IFERROR(ROUND(AN15 + AS15, 2), AS15) -> 0 | AV15: =IFERROR(ROUND(AO15 + AT15, 2), AT15) -> 0 | AY15: Zinsertraege | AZ15: =ROUND(SUMIF($AY$116:$AY$120,"Zinsertraege",$BA$116:$BA$120)+SUMIF($AY$125:$AY$130,"Zinsertraege",$BA$125:$BA$130),2) -> 0 | BA15: =ROUND(SUMIF($AY$116:$AY$120,"Zinsertraege",$BB$116:$BB$120)+SUMIF($AY$125:$AY$130,"Zinsertraege",$BB$125:$BB$130),2) -> 0 | BB15: =IFERROR(ROUND(AU15 + AZ15, 2), AZ15) -> 0 | BC15: =IFERROR(ROUND(AV15 + BA15, 2), BA15) -> 0 | BF15: Zinsertraege | BG15: =ROUND(SUMIF($BF$116:$BF$120,"Zinsertraege",$BH$116:$BH$120)+SUMIF($BF$125:$BF$130,"Zinsertraege",$BH$125:$BH$130),2) -> 0 | BH15: =ROUND(SUMIF($BF$116:$BF$120,"Zinsertraege",$BI$116:$BI$120)+SUMIF($BF$125:$BF$130,"Zinsertraege",$BI$125:$BI$130),2) -> 0 | BI15: =IFERROR(ROUND(BB15 + BG15, 2), BG15) -> 0 | BJ15: =IFERROR(ROUND(BC15 + BH15, 2), BH15) -> 0 | BM15: Zinsertraege | BN15: =ROUND(SUMIF($BM$116:$BM$120,"Zinsertraege",$BO$116:$BO$120)+SUMIF($BM$125:$BM$130,"Zinsertraege",$BO$125:$BO$130),2) -> 0 | BO15: =ROUND(SUMIF($BM$116:$BM$120,"Zinsertraege",$BP$116:$BP$120)+SUMIF($BM$125:$BM$130,"Zinsertraege",$BP$125:$BP$130),2) -> 0 | BP15: =IFERROR(ROUND(BI15 + BN15, 2), BN15) -> 0 | BQ15: =IFERROR(ROUND(BJ15 + BO15, 2), BO15) -> 0 | BT15: Zinsertraege | BU15: =ROUND(SUMIF($BT$116:$BT$120,"Zinsertraege",$BV$116:$BV$120)+SUMIF($BT$125:$BT$130,"Zinsertraege",$BV$125:$BV$130),2) -> 0 | BV15: =ROUND(SUMIF($BT$116:$BT$120,"Zinsertraege",$BW$116:$BW$120)+SUMIF($BT$125:$BT$130,"Zinsertraege",$BW$125:$BW$130),2) -> 0 | BW15: =IFERROR(ROUND(BP15 + BU15, 2), BU15) -> 0 | BX15: =IFERROR(ROUND(BQ15 + BV15, 2), BV15) -> 0 | CA15: Zinsertraege | CB15: =ROUND(SUMIF($CA$116:$CA$120,"Zinsertraege",$CC$116:$CC$120)+SUMIF($CA$125:$CA$130,"Zinsertraege",$CC$125:$CC$130),2) -> 0 | CC15: =ROUND(SUMIF($CA$116:$CA$120,"Zinsertraege",$CD$116:$CD$120)+SUMIF($CA$125:$CA$130,"Zinsertraege",$CD$125:$CD$130),2) -> 0 | CD15: =IFERROR(ROUND(BW15 + CB15, 2), CB15) -> 0 | CE15: =IFERROR(ROUND(BX15 + CC15, 2), CC15) -> 0 | CH15: Zinsertraege | CI15: =ROUND(SUMIF($CH$116:$CH$120,"Zinsertraege",$CJ$116:$CJ$120)+SUMIF($CH$125:$CH$130,"Zinsertraege",$CJ$125:$CJ$130),2) -> 0 | CJ15: =ROUND(SUMIF($CH$116:$CH$120,"Zinsertraege",$CK$116:$CK$120)+SUMIF($CH$125:$CH$130,"Zinsertraege",$CK$125:$CK$130),2) -> 0 | CK15: =IFERROR(ROUND(CD15 + CI15, 2), CI15) -> 0 | CL15: =IFERROR(ROUND(CE15 + CJ15, 2), CJ15) -> 0 | CO15: Zinsertraege | CP15: =ROUND(SUMIF($CO$116:$CO$120,"Zinsertraege",$CQ$116:$CQ$120)+SUMIF($CO$125:$CO$130,"Zinsertraege",$CQ$125:$CQ$130),2) -> 0 | CQ15: =ROUND(SUMIF($CO$116:$CO$120,"Zinsertraege",$CR$116:$CR$120)+SUMIF($CO$125:$CO$130,"Zinsertraege",$CR$125:$CR$130),2) -> 0 | CR15: =IFERROR(ROUND(CK15 + CP15, 2), CP15) -> 0 | CS15: =IFERROR(ROUND(CL15 + CQ15, 2), CQ15) -> 0 | CV15: Zinsertraege | CW15: =ROUND(SUMIF($CV$116:$CV$120,"Zinsertraege",$CX$116:$CX$120)+SUMIF($CV$125:$CV$130,"Zinsertraege",$CX$125:$CX$130),2) -> 0 | CX15: =ROUND(SUMIF($CV$116:$CV$120,"Zinsertraege",$CY$116:$CY$120)+SUMIF($CV$125:$CV$130,"Zinsertraege",$CY$125:$CY$130),2) -> 0 | CY15: =IFERROR(ROUND(CR15 + CW15, 2), CW15) -> 0 | CZ15: =IFERROR(ROUND(CS15 + CX15, 2), CX15) -> 0 | DC15: Zinsertraege | DD15: =ROUND(SUMIF($DC$116:$DC$120,"Zinsertraege",$DE$116:$DE$120)+SUMIF($DC$125:$DC$130,"Zinsertraege",$DE$125:$DE$130),2) -> 0 | DE15: =ROUND(SUMIF($DC$116:$DC$120,"Zinsertraege",$DF$116:$DF$120)+SUMIF($DC$125:$DC$130,"Zinsertraege",$DF$125:$DF$130),2) -> 0 | DF15: =IFERROR(ROUND(CY15 + DD15, 2), DD15) -> 0 | DG15: =IFERROR(ROUND(CZ15 + DE15, 2), DE15) -> 0 | DJ15: Zinsertraege | DK15: =ROUND(SUMIF($DJ$116:$DJ$120,"Zinsertraege",$DL$116:$DL$120)+SUMIF($DJ$125:$DJ$130,"Zinsertraege",$DL$125:$DL$130),2) -> 0 | DL15: =ROUND(SUMIF($DJ$116:$DJ$120,"Zinsertraege",$DM$116:$DM$120)+SUMIF($DJ$125:$DJ$130,"Zinsertraege",$DM$125:$DM$130),2) -> 0 | DM15: =IFERROR(ROUND(DF15 + DK15, 2), DK15) -> 0 | DN15: =IFERROR(ROUND(DG15 + DL15, 2), DL15) -> 0 | DQ15: Zinsertraege | DR15: =ROUND(SUMIF($DQ$116:$DQ$120,"Zinsertraege",$DS$116:$DS$120)+SUMIF($DQ$125:$DQ$130,"Zinsertraege",$DS$125:$DS$130),2) -> 0 | DS15: =ROUND(SUMIF($DQ$116:$DQ$120,"Zinsertraege",$DT$116:$DT$120)+SUMIF($DQ$125:$DQ$130,"Zinsertraege",$DT$125:$DT$130),2) -> 0 | DT15: =IFERROR(ROUND(DM15 + DR15, 2), DR15) -> 0 | DU15: =IFERROR(ROUND(DN15 + DS15, 2), DS15) -> 0
B16: Gesamteinnahmen | C16: =ROUND(SUM(C11:C15),2) -> 0 | D16: =ROUND(SUM(D11:D15),2) -> 0 | E16: =ROUND(SUM(E11:E15),2) -> 0 | F16: =ROUND(SUM(F11:F15),2) -> 0 | I16: Gesamteinnahmen | J16: =ROUND(SUM(J11:J15),2) -> 0 | K16: =ROUND(SUM(K11:K15),2) -> 0 | L16: =ROUND(SUM(L11:L15),2) -> 0 | M16: =ROUND(SUM(M11:M15),2) -> 0 | P16: Gesamteinnahmen | Q16: =ROUND(SUM(Q11:Q15),2) -> 0 | R16: =ROUND(SUM(R11:R15),2) -> 0 | S16: =ROUND(SUM(S11:S15),2) -> 0 | T16: =ROUND(SUM(T11:T15),2) -> 0 | W16: Gesamteinnahmen | X16: =ROUND(SUM(X11:X15),2) -> 0 | Y16: =ROUND(SUM(Y11:Y15),2) -> 0 | Z16: =ROUND(SUM(Z11:Z15),2) -> 0 | AA16: =ROUND(SUM(AA11:AA15),2) -> 0 | AD16: Gesamteinnahmen | AE16: =ROUND(SUM(AE11:AE15),2) -> 0 | AF16: =ROUND(SUM(AF11:AF15),2) -> 0 | AG16: =ROUND(SUM(AG11:AG15),2) -> 0 | AH16: =ROUND(SUM(AH11:AH15),2) -> 0 | AK16: Gesamteinnahmen | AL16: =ROUND(SUM(AL11:AL15),2) -> 0 | AM16: =ROUND(SUM(AM11:AM15),2) -> 0 | AN16: =ROUND(SUM(AN11:AN15),2) -> 0 | AO16: =ROUND(SUM(AO11:AO15),2) -> 0 | AR16: Gesamteinnahmen | AS16: =ROUND(SUM(AS11:AS15),2) -> 0 | AT16: =ROUND(SUM(AT11:AT15),2) -> 0 | AU16: =ROUND(SUM(AU11:AU15),2) -> 0 | AV16: =ROUND(SUM(AV11:AV15),2) -> 0 | AY16: Gesamteinnahmen | AZ16: =ROUND(SUM(AZ11:AZ15),2) -> 0 | BA16: =ROUND(SUM(BA11:BA15),2) -> 0 | BB16: =ROUND(SUM(BB11:BB15),2) -> 0 | BC16: =ROUND(SUM(BC11:BC15),2) -> 0 | BF16: Gesamteinnahmen | BG16: =ROUND(SUM(BG11:BG15),2) -> 0 | BH16: =ROUND(SUM(BH11:BH15),2) -> 0 | BI16: =ROUND(SUM(BI11:BI15),2) -> 0 | BJ16: =ROUND(SUM(BJ11:BJ15),2) -> 0 | BM16: Gesamteinnahmen | BN16: =ROUND(SUM(BN11:BN15),2) -> 0 | BO16: =ROUND(SUM(BO11:BO15),2) -> 0 | BP16: =ROUND(SUM(BP11:BP15),2) -> 0 | BQ16: =ROUND(SUM(BQ11:BQ15),2) -> 0 | BT16: Gesamteinnahmen | BU16: =ROUND(SUM(BU11:BU15),2) -> 0 | BV16: =ROUND(SUM(BV11:BV15),2) -> 0 | BW16: =ROUND(SUM(BW11:BW15),2) -> 0 | BX16: =ROUND(SUM(BX11:BX15),2) -> 0 | CA16: Gesamteinnahmen | CB16: =ROUND(SUM(CB11:CB15),2) -> 0 | CC16: =ROUND(SUM(CC11:CC15),2) -> 0 | CD16: =ROUND(SUM(CD11:CD15),2) -> 0 | CE16: =ROUND(SUM(CE11:CE15),2) -> 0 | CH16: Gesamteinnahmen | CI16: =ROUND(SUM(CI11:CI15),2) -> 0 | CJ16: =ROUND(SUM(CJ11:CJ15),2) -> 0 | CK16: =ROUND(SUM(CK11:CK15),2) -> 0 | CL16: =ROUND(SUM(CL11:CL15),2) -> 0 | CO16: Gesamteinnahmen | CP16: =ROUND(SUM(CP11:CP15),2) -> 0 | CQ16: =ROUND(SUM(CQ11:CQ15),2) -> 0 | CR16: =ROUND(SUM(CR11:CR15),2) -> 0 | CS16: =ROUND(SUM(CS11:CS15),2) -> 0 | CV16: Gesamteinnahmen | CW16: =ROUND(SUM(CW11:CW15),2) -> 0 | CX16: =ROUND(SUM(CX11:CX15),2) -> 0 | CY16: =ROUND(SUM(CY11:CY15),2) -> 0 | CZ16: =ROUND(SUM(CZ11:CZ15),2) -> 0 | DC16: Gesamteinnahmen | DD16: =ROUND(SUM(DD11:DD15),2) -> 0 | DE16: =ROUND(SUM(DE11:DE15),2) -> 0 | DF16: =ROUND(SUM(DF11:DF15),2) -> 0 | DG16: =ROUND(SUM(DG11:DG15),2) -> 0 | DJ16: Gesamteinnahmen | DK16: =ROUND(SUM(DK11:DK15),2) -> 0 | DL16: =ROUND(SUM(DL11:DL15),2) -> 0 | DM16: =ROUND(SUM(DM11:DM15),2) -> 0 | DN16: =ROUND(SUM(DN11:DN15),2) -> 0 | DQ16: Gesamteinnahmen | DR16: =ROUND(SUM(DR11:DR15),2) -> 0 | DS16: =ROUND(SUM(DS11:DS15),2) -> 0 | DT16: =ROUND(SUM(DT11:DT15),2) -> 0 | DU16: =ROUND(SUM(DU11:DU15),2) -> 0
B17: Ausgaben | I17: Ausgaben | P17: Ausgaben | W17: Ausgaben | AD17: Ausgaben | AK17: Ausgaben | AR17: Ausgaben | AY17: Ausgaben | BF17: Ausgaben | BM17: Ausgaben | BT17: Ausgaben | CA17: Ausgaben | CH17: Ausgaben | CO17: Ausgaben | CV17: Ausgaben | DC17: Ausgaben | DJ17: Ausgaben | DQ17: Ausgaben
B18: ID | C18: Ausgaben (LC) | D18: Ausgaben (EUR) | E18: Kum. Ausgaben (LC) | F18: Kum. Ausgaben (EUR) | I18: ID | J18: Ausgaben (LC) | K18: Ausgaben (EUR) | L18: Kum. Ausgaben (LC) | M18: Kum. Ausgaben (EUR) | P18: ID | Q18: Ausgaben (LC) | R18: Ausgaben (EUR) | S18: Kum. Ausgaben (LC) | T18: Kum. Ausgaben (EUR) | W18: ID | X18: Ausgaben (LC) | Y18: Ausgaben (EUR) | Z18: Kum. Ausgaben (LC) | AA18: Kum. Ausgaben (EUR) | AD18: ID | AE18: Ausgaben (LC) | AF18: Ausgaben (EUR) | AG18: Kum. Ausgaben (LC) | AH18: Kum. Ausgaben (EUR) | AK18: ID | AL18: Ausgaben (LC) | AM18: Ausgaben (EUR) | AN18: Kum. Ausgaben (LC) | AO18: Kum. Ausgaben (EUR) | AR18: ID | AS18: Ausgaben (LC) | AT18: Ausgaben (EUR) | AU18: Kum. Ausgaben (LC) | AV18: Kum. Ausgaben (EUR) | AY18: ID | AZ18: Ausgaben (LC) | BA18: Ausgaben (EUR) | BB18: Kum. Ausgaben (LC) | BC18: Kum. Ausgaben (EUR) | BF18: ID | BG18: Ausgaben (LC) | BH18: Ausgaben (EUR) | BI18: Kum. Ausgaben (LC) | BJ18: Kum. Ausgaben (EUR) | BM18: ID | BN18: Ausgaben (LC) | BO18: Ausgaben (EUR) | BP18: Kum. Ausgaben (LC) | BQ18: Kum. Ausgaben (EUR) | BT18: ID | BU18: Ausgaben (LC) | BV18: Ausgaben (EUR) | BW18: Kum. Ausgaben (LC) | BX18: Kum. Ausgaben (EUR) | CA18: ID | CB18: Ausgaben (LC) | CC18: Ausgaben (EUR) | CD18: Kum. Ausgaben (LC) | CE18: Kum. Ausgaben (EUR) | CH18: ID | CI18: Ausgaben (LC) | CJ18: Ausgaben (EUR) | CK18: Kum. Ausgaben (LC) | CL18: Kum. Ausgaben (EUR) | CO18: ID | CP18: Ausgaben (LC) | CQ18: Ausgaben (EUR) | CR18: Kum. Ausgaben (LC) | CS18: Kum. Ausgaben (EUR) | CV18: ID | CW18: Ausgaben (LC) | CX18: Ausgaben (EUR) | CY18: Kum. Ausgaben (LC) | CZ18: Kum. Ausgaben (EUR) | DC18: ID | DD18: Ausgaben (LC) | DE18: Ausgaben (EUR) | DF18: Kum. Ausgaben (LC) | DG18: Kum. Ausgaben (EUR) | DJ18: ID | DK18: Ausgaben (LC) | DL18: Ausgaben (EUR) | DM18: Kum. Ausgaben (LC) | DN18: Kum. Ausgaben (EUR) | DQ18: ID | DR18: Ausgaben (LC) | DS18: Ausgaben (EUR) | DT18: Kum. Ausgaben (LC) | DU18: Kum. Ausgaben (EUR)
B19: 1.1 | D19: =IFERROR(ROUND(C19/FB_Kurs_1,2),0) -> 0 | E19: =ROUND(C19,2) -> 0 | F19: =ROUND(D19,2) -> 0 | I19: 1.1 | K19: =IFERROR(ROUND(J19/FB_Kurs_2,2),0) -> 0 | L19: =ROUND(J19+E19,2) -> 0 | M19: =ROUND(K19+F19,2) -> 0 | P19: 1.1 | R19: =IFERROR(ROUND(Q19/FB_Kurs_3,2),0) -> 0 | S19: =ROUND(Q19+L19,2) -> 0 | T19: =ROUND(R19+M19,2) -> 0 | W19: 1.1 | Y19: =IFERROR(ROUND(X19/FB_Kurs_4,2),0) -> 0 | Z19: =ROUND(X19+S19,2) -> 0 | AA19: =ROUND(Y19+T19,2) -> 0 | AD19: 1.1 | AF19: =IFERROR(ROUND(AE19/FB_Kurs_5,2),0) -> 0 | AG19: =ROUND(AE19+Z19,2) -> 0 | AH19: =ROUND(AF19+AA19,2) -> 0 | AK19: 1.1 | AM19: =IFERROR(ROUND(AL19/FB_Kurs_6,2),0) -> 0 | AN19: =ROUND(AL19+AG19,2) -> 0 | AO19: =ROUND(AM19+AH19,2) -> 0 | AR19: 1.1 | AT19: =IFERROR(ROUND(AS19/FB_Kurs_7,2),0) -> 0 | AU19: =ROUND(AS19+AN19,2) -> 0 | AV19: =ROUND(AT19+AO19,2) -> 0 | AY19: 1.1 | BA19: =IFERROR(ROUND(AZ19/FB_Kurs_8,2),0) -> 0 | BB19: =ROUND(AZ19+AU19,2) -> 0 | BC19: =ROUND(BA19+AV19,2) -> 0 | BF19: 1.1 | BH19: =IFERROR(ROUND(BG19/FB_Kurs_9,2),0) -> 0 | BI19: =ROUND(BG19+BB19,2) -> 0 | BJ19: =ROUND(BH19+BC19,2) -> 0 | BM19: 1.1 | BO19: =IFERROR(ROUND(BN19/FB_Kurs_10,2),0) -> 0 | BP19: =ROUND(BN19+BI19,2) -> 0 | BQ19: =ROUND(BO19+BJ19,2) -> 0 | BT19: 1.1 | BV19: =IFERROR(ROUND(BU19/FB_Kurs_11,2),0) -> 0 | BW19: =ROUND(BU19+BP19,2) -> 0 | BX19: =ROUND(BV19+BQ19,2) -> 0 | CA19: 1.1 | CC19: =IFERROR(ROUND(CB19/FB_Kurs_12,2),0) -> 0 | CD19: =ROUND(CB19+BW19,2) -> 0 | CE19: =ROUND(CC19+BX19,2) -> 0 | CH19: 1.1 | CJ19: =IFERROR(ROUND(CI19/FB_Kurs_13,2),0) -> 0 | CK19: =ROUND(CI19+CD19,2) -> 0 | CL19: =ROUND(CJ19+CE19,2) -> 0 | CO19: 1.1 | CQ19: =IFERROR(ROUND(CP19/FB_Kurs_14,2),0) -> 0 | CR19: =ROUND(CP19+CK19,2) -> 0 | CS19: =ROUND(CQ19+CL19,2) -> 0 | CV19: 1.1 | CX19: =IFERROR(ROUND(CW19/FB_Kurs_15,2),0) -> 0 | CY19: =ROUND(CW19+CR19,2) -> 0 | CZ19: =ROUND(CX19+CS19,2) -> 0 | DC19: 1.1 | DE19: =IFERROR(ROUND(DD19/FB_Kurs_16,2),0) -> 0 | DF19: =ROUND(DD19+CY19,2) -> 0 | DG19: =ROUND(DE19+CZ19,2) -> 0 | DJ19: 1.1 | DL19: =IFERROR(ROUND(DK19/FB_Kurs_17,2),0) -> 0 | DM19: =ROUND(DK19+DF19,2) -> 0 | DN19: =ROUND(DL19+DG19,2) -> 0 | DQ19: 1.1 | DS19: =IFERROR(ROUND(DR19/FB_Kurs_18,2),0) -> 0 | DT19: =ROUND(DR19+DM19,2) -> 0 | DU19: =ROUND(DS19+DN19,2) -> 0
B20: 1.2 | D20: =IFERROR(ROUND(C20/FB_Kurs_1,2),0) -> 0 | E20: =ROUND(C20,2) -> 0 | F20: =ROUND(D20,2) -> 0 | I20: 1.2 | K20: =IFERROR(ROUND(J20/FB_Kurs_2,2),0) -> 0 | L20: =ROUND(J20+E20,2) -> 0 | M20: =ROUND(K20+F20,2) -> 0 | P20: 1.2 | R20: =IFERROR(ROUND(Q20/FB_Kurs_3,2),0) -> 0 | S20: =ROUND(Q20+L20,2) -> 0 | T20: =ROUND(R20+M20,2) -> 0 | W20: 1.2 | Y20: =IFERROR(ROUND(X20/FB_Kurs_4,2),0) -> 0 | Z20: =ROUND(X20+S20,2) -> 0 | AA20: =ROUND(Y20+T20,2) -> 0 | AD20: 1.2 | AF20: =IFERROR(ROUND(AE20/FB_Kurs_5,2),0) -> 0 | AG20: =ROUND(AE20+Z20,2) -> 0 | AH20: =ROUND(AF20+AA20,2) -> 0 | AK20: 1.2 | AM20: =IFERROR(ROUND(AL20/FB_Kurs_6,2),0) -> 0 | AN20: =ROUND(AL20+AG20,2) -> 0 | AO20: =ROUND(AM20+AH20,2) -> 0 | AR20: 1.2 | AT20: =IFERROR(ROUND(AS20/FB_Kurs_7,2),0) -> 0 | AU20: =ROUND(AS20+AN20,2) -> 0 | AV20: =ROUND(AT20+AO20,2) -> 0 | AY20: 1.2 | BA20: =IFERROR(ROUND(AZ20/FB_Kurs_8,2),0) -> 0 | BB20: =ROUND(AZ20+AU20,2) -> 0 | BC20: =ROUND(BA20+AV20,2) -> 0 | BF20: 1.2 | BH20: =IFERROR(ROUND(BG20/FB_Kurs_9,2),0) -> 0 | BI20: =ROUND(BG20+BB20,2) -> 0 | BJ20: =ROUND(BH20+BC20,2) -> 0 | BM20: 1.2 | BO20: =IFERROR(ROUND(BN20/FB_Kurs_10,2),0) -> 0 | BP20: =ROUND(BN20+BI20,2) -> 0 | BQ20: =ROUND(BO20+BJ20,2) -> 0 | BT20: 1.2 | BV20: =IFERROR(ROUND(BU20/FB_Kurs_11,2),0) -> 0 | BW20: =ROUND(BU20+BP20,2) -> 0 | BX20: =ROUND(BV20+BQ20,2) -> 0 | CA20: 1.2 | CC20: =IFERROR(ROUND(CB20/FB_Kurs_12,2),0) -> 0 | CD20: =ROUND(CB20+BW20,2) -> 0 | CE20: =ROUND(CC20+BX20,2) -> 0 | CH20: 1.2 | CJ20: =IFERROR(ROUND(CI20/FB_Kurs_13,2),0) -> 0 | CK20: =ROUND(CI20+CD20,2) -> 0 | CL20: =ROUND(CJ20+CE20,2) -> 0 | CO20: 1.2 | CQ20: =IFERROR(ROUND(CP20/FB_Kurs_14,2),0) -> 0 | CR20: =ROUND(CP20+CK20,2) -> 0 | CS20: =ROUND(CQ20+CL20,2) -> 0 | CV20: 1.2 | CX20: =IFERROR(ROUND(CW20/FB_Kurs_15,2),0) -> 0 | CY20: =ROUND(CW20+CR20,2) -> 0 | CZ20: =ROUND(CX20+CS20,2) -> 0 | DC20: 1.2 | DE20: =IFERROR(ROUND(DD20/FB_Kurs_16,2),0) -> 0 | DF20: =ROUND(DD20+CY20,2) -> 0 | DG20: =ROUND(DE20+CZ20,2) -> 0 | DJ20: 1.2 | DL20: =IFERROR(ROUND(DK20/FB_Kurs_17,2),0) -> 0 | DM20: =ROUND(DK20+DF20,2) -> 0 | DN20: =ROUND(DL20+DG20,2) -> 0 | DQ20: 1.2 | DS20: =IFERROR(ROUND(DR20/FB_Kurs_18,2),0) -> 0 | DT20: =ROUND(DR20+DM20,2) -> 0 | DU20: =ROUND(DS20+DN20,2) -> 0
B21: 1.3 | D21: =IFERROR(ROUND(C21/FB_Kurs_1,2),0) -> 0 | E21: =ROUND(C21,2) -> 0 | F21: =ROUND(D21,2) -> 0 | I21: 1.3 | K21: =IFERROR(ROUND(J21/FB_Kurs_2,2),0) -> 0 | L21: =ROUND(J21+E21,2) -> 0 | M21: =ROUND(K21+F21,2) -> 0 | P21: 1.3 | R21: =IFERROR(ROUND(Q21/FB_Kurs_3,2),0) -> 0 | S21: =ROUND(Q21+L21,2) -> 0 | T21: =ROUND(R21+M21,2) -> 0 | W21: 1.3 | Y21: =IFERROR(ROUND(X21/FB_Kurs_4,2),0) -> 0 | Z21: =ROUND(X21+S21,2) -> 0 | AA21: =ROUND(Y21+T21,2) -> 0 | AD21: 1.3 | AF21: =IFERROR(ROUND(AE21/FB_Kurs_5,2),0) -> 0 | AG21: =ROUND(AE21+Z21,2) -> 0 | AH21: =ROUND(AF21+AA21,2) -> 0 | AK21: 1.3 | AM21: =IFERROR(ROUND(AL21/FB_Kurs_6,2),0) -> 0 | AN21: =ROUND(AL21+AG21,2) -> 0 | AO21: =ROUND(AM21+AH21,2) -> 0 | AR21: 1.3 | AT21: =IFERROR(ROUND(AS21/FB_Kurs_7,2),0) -> 0 | AU21: =ROUND(AS21+AN21,2) -> 0 | AV21: =ROUND(AT21+AO21,2) -> 0 | AY21: 1.3 | BA21: =IFERROR(ROUND(AZ21/FB_Kurs_8,2),0) -> 0 | BB21: =ROUND(AZ21+AU21,2) -> 0 | BC21: =ROUND(BA21+AV21,2) -> 0 | BF21: 1.3 | BH21: =IFERROR(ROUND(BG21/FB_Kurs_9,2),0) -> 0 | BI21: =ROUND(BG21+BB21,2) -> 0 | BJ21: =ROUND(BH21+BC21,2) -> 0 | BM21: 1.3 | BO21: =IFERROR(ROUND(BN21/FB_Kurs_10,2),0) -> 0 | BP21: =ROUND(BN21+BI21,2) -> 0 | BQ21: =ROUND(BO21+BJ21,2) -> 0 | BT21: 1.3 | BV21: =IFERROR(ROUND(BU21/FB_Kurs_11,2),0) -> 0 | BW21: =ROUND(BU21+BP21,2) -> 0 | BX21: =ROUND(BV21+BQ21,2) -> 0 | CA21: 1.3 | CC21: =IFERROR(ROUND(CB21/FB_Kurs_12,2),0) -> 0 | CD21: =ROUND(CB21+BW21,2) -> 0 | CE21: =ROUND(CC21+BX21,2) -> 0 | CH21: 1.3 | CJ21: =IFERROR(ROUND(CI21/FB_Kurs_13,2),0) -> 0 | CK21: =ROUND(CI21+CD21,2) -> 0 | CL21: =ROUND(CJ21+CE21,2) -> 0 | CO21: 1.3 | CQ21: =IFERROR(ROUND(CP21/FB_Kurs_14,2),0) -> 0 | CR21: =ROUND(CP21+CK21,2) -> 0 | CS21: =ROUND(CQ21+CL21,2) -> 0 | CV21: 1.3 | CX21: =IFERROR(ROUND(CW21/FB_Kurs_15,2),0) -> 0 | CY21: =ROUND(CW21+CR21,2) -> 0 | CZ21: =ROUND(CX21+CS21,2) -> 0 | DC21: 1.3 | DE21: =IFERROR(ROUND(DD21/FB_Kurs_16,2),0) -> 0 | DF21: =ROUND(DD21+CY21,2) -> 0 | DG21: =ROUND(DE21+CZ21,2) -> 0 | DJ21: 1.3 | DL21: =IFERROR(ROUND(DK21/FB_Kurs_17,2),0) -> 0 | DM21: =ROUND(DK21+DF21,2) -> 0 | DN21: =ROUND(DL21+DG21,2) -> 0 | DQ21: 1.3 | DS21: =IFERROR(ROUND(DR21/FB_Kurs_18,2),0) -> 0 | DT21: =ROUND(DR21+DM21,2) -> 0 | DU21: =ROUND(DS21+DN21,2) -> 0
